Workbook
Name UPDATE: 'Data Sheet'!$E$1

Sheet FINANCIALS
B2: ="HISTORICAL FINANCIAL STATEMENT - "&'Data Sheet'!B1 -> HISTORICAL FINANCIAL STATEMENT - CASTROL INDIA LTD
B3: YEARS | C3: ='Data Sheet'!B16 -> 42735 | D3: ='Data Sheet'!C16 -> 43100 | E3: ='Data Sheet'!D16 -> 43465 | F3: ='Data Sheet'!E16 -> 43830 | G3: ='Data Sheet'!F16 -> 44196 | H3: ='Data Sheet'!G16 -> 44561 | I3: ='Data Sheet'!H16 -> 44926 | J3: ='Data Sheet'!I16 -> 45291 | ... L3: ='Data Sheet'!K16 -> 46022 | M3: LTM
A4: # | B4: INCOME STATEMENT (IN CRORES)
B5: SALES | C5: =IFERROR('Data Sheet'!B17,0) -> 3370.33 | D5: =IFERROR('Data Sheet'!C17,0) -> 3584.32 | E5: =IFERROR('Data Sheet'!D17,0) -> 3904.55 | F5: =IFERROR('Data Sheet'!E17,0) -> 3876.82 | G5: =IFERROR('Data Sheet'!F17,0) -> 2996.92 | H5: =IFERROR('Data Sheet'!G17,0) -> 4192.06 | I5: =IFERROR('Data Sheet'!H17,0) -> 4774.49 | J5: =IFERROR('Data Sheet'!I17,0) -> 5074.61 | ... L5: =IFERROR('Data Sheet'!K17,0) -> 5721.5 | M5: =IFERROR(SUM('Data Sheet'!H42:K42),0) -> 6219.38
B6: SALES GROWTH | C6: - | D6: =D5/C5-1 -> 0.063492299 | E6: =E5/D5-1 -> 0.089341911 | F6: =F5/E5-1 -> -0.0071019708 | G6: =G5/F5-1 -> -0.22696437 | H6: =H5/G5-1 -> 0.39878942 | I6: =I5/H5-1 -> 0.13893647 | J6: =J5/I5-1 -> 0.06285907 | K6: =K5/J5-1 -> 0.057194543 | ... M6: =M5/L5-1 -> 0.087019138
B8: COGS | C8: =IFERROR(SUM('Data Sheet'!B18,'Data Sheet'!B20,'Data Sheet'!B21,'Data Sheet'!B22-1*'Data Sheet'!B19),0) -> 1889.87 | D8: =IFERROR(SUM('Data Sheet'!C18,'Data Sheet'!C20,'Data Sheet'!C21,'Data Sheet'!C22-1*'Data Sheet'!C19),0) -> 2054.32 | E8: =IFERROR(SUM('Data Sheet'!D18,'Data Sheet'!D20,'Data Sheet'!D21,'Data Sheet'!D22-1*'Data Sheet'!D19),0) -> 2334.63 | F8: =IFERROR(SUM('Data Sheet'!E18,'Data Sheet'!E20,'Data Sheet'!E21,'Data Sheet'!E22-1*'Data Sheet'!E19),0) -> 2189.88 | G8: =IFERROR(SUM('Data Sheet'!F18,'Data Sheet'!F20,'Data Sheet'!F21,'Data Sheet'!F22-1*'Data Sheet'!F19),0) -> 1685.45 | H8: =IFERROR(SUM('Data Sheet'!G18,'Data Sheet'!G20,'Data Sheet'!G21,'Data Sheet'!G22-1*'Data Sheet'!G19),0) -> 2522.66 | I8: =IFERROR(SUM('Data Sheet'!H18,'Data Sheet'!H20,'Data Sheet'!H21,'Data Sheet'!H22-1*'Data Sheet'!H19),0) -> 3015.69 | J8: =IFERROR(SUM('Data Sheet'!I18,'Data Sheet'!I20,'Data Sheet'!I21,'Data Sheet'!I22-1*'Data Sheet'!I19),0) -> 3181.76 | ... L8: =IFERROR(SUM('Data Sheet'!K18,'Data Sheet'!K20,'Data Sheet'!K21,'Data Sheet'!K22-1*'Data Sheet'!K19),0) -> 3517.6 | M8: =IFERROR(SUM('Data Sheet'!H43:K43),0) -> 4705.25
B9: COGS % SALES | C9: =C8/C5 -> 0.56073738 | D9: =D8/D5 -> 0.57314079 | E9: =E8/E5 -> 0.5979255 | F9: =F8/F5 -> 0.56486502 | G9: =G8/G5 -> 0.56239406 | H9: =H8/H5 -> 0.60177097 | I9: =I8/I5 -> 0.63162558 | J9: =J8/J5 -> 0.62699597 | ... M9: =M8/M5 -> 0.75654647 | O9: =AVERAGE(D6:M6) -> 0.073004554
B11: GROSS PROFIT | C11: =C5-C8 -> 1480.46 | D11: =D5-D8 -> 1530 | E11: =E5-E8 -> 1569.92 | F11: =F5-F8 -> 1686.94 | G11: =G5-G8 -> 1311.47 | H11: =H5-H8 -> 1669.4 | I11: =I5-I8 -> 1758.8 | J11: =J5-J8 -> 1892.85 | ... M11: =M5-M8 -> 1514.13
B12: GROSS PROFIT % SALES | C12: =C11/C5 -> 0.43926262 | D12: =D11/D5 -> 0.42685921 | E12: =E11/E5 -> 0.4020745 | F12: =F11/F5 -> 0.43513498 | G12: =G11/G5 -> 0.43760594 | H12: =H11/H5 -> 0.39822903 | I12: =I11/I5 -> 0.36837442 | J12: =J11/J5 -> 0.37300403 | ... M12: =M11/M5 -> 0.24345353
B14: SELLING &GENERAL EXPENSES | C14: =IFERROR(SUM('Data Sheet'!B23:B24),0) -> 479.46 | D14: =IFERROR(SUM('Data Sheet'!C23:C24),0) -> 496.88 | E14: =IFERROR(SUM('Data Sheet'!D23:D24),0) -> 499.15 | F14: =IFERROR(SUM('Data Sheet'!E23:E24),0) -> 533.24 | G14: =IFERROR(SUM('Data Sheet'!F23:F24),0) -> 497.21 | H14: =IFERROR(SUM('Data Sheet'!G23:G24),0) -> 602.5 | I14: =IFERROR(SUM('Data Sheet'!H23:H24),0) -> 647.38 | J14: =IFERROR(SUM('Data Sheet'!I23:I24),0) -> 694.94 | ... M14: =IFERROR(SUM('Data Sheet'!L23:L24),0) -> 0
B15: SG EXP % SALES | C15: =C14/C5 -> 0.14225907 | D15: =D14/D5 -> 0.13862602 | E15: =E14/E5 -> 0.12783804 | F15: =F14/F5 -> 0.13754572 | G15: =G14/G5 -> 0.165907 | H15: =H14/H5 -> 0.14372409 | I15: =I14/I5 -> 0.13559145 | J15: =J14/J5 -> 0.13694451 | ... L15: =L14/L5 -> 0.14967753
B17: EBITDA | C17: =C11-C14 -> 1001 | D17: =D11-D14 -> 1033.12 | E17: =E11-E14 -> 1070.77 | F17: =F11-F14 -> 1153.7 | G17: =G11-G14 -> 814.26 | H17: =H11-H14 -> 1066.9 | I17: =I11-I14 -> 1111.42 | J17: =J11-J14 -> 1197.91 | ... M17: =M11-M14 -> 1514.13
B18: EBITDA % SALES | C18: =C17/C5 -> 0.29700356 | D18: =D17/D5 -> 0.28823319 | E18: =E17/E5 -> 0.27423647 | F18: =F17/F5 -> 0.29758926 | G18: =G17/G5 -> 0.27169894 | H18: =H17/H5 -> 0.25450495 | I18: =I17/I5 -> 0.23278298 | J18: =J17/J5 -> 0.23605952 | ... M18: =M17/M5 -> 0.24345353
B20: INTEREST | C20: =IFERROR('Data Sheet'!B27,0) -> 1.48 | D20: =IFERROR('Data Sheet'!C27,0) -> 1.2 | E20: =IFERROR('Data Sheet'!D27,0) -> 1.09 | F20: =IFERROR('Data Sheet'!E27,0) -> 1.19 | G20: =IFERROR('Data Sheet'!F27,0) -> 4.16 | H20: =IFERROR('Data Sheet'!G27,0) -> 2.41 | I20: =IFERROR('Data Sheet'!H27,0) -> 4.01 | J20: =IFERROR('Data Sheet'!I27,0) -> 7.53 | ... L20: =IFERROR('Data Sheet'!K27,0) -> 9.29 | M20: =IFERROR(SUM('Data Sheet'!H46:K46),0) -> 7.91
B21: INTEREST % SALES | C21: =C20/C5 -> 0.00043912614 | D21: =D20/D5 -> 0.00033479154 | E21: =E20/E5 -> 0.00027916149 | F21: =F20/F5 -> 0.00030695261 | G21: =G20/G5 -> 0.0013880918 | H21: =H20/H5 -> 0.00057489635 | I21: =I20/I5 -> 0.00083988028 | J21: =J20/J5 -> 0.0014838579 | ... M21: =M20/M5 -> 0.001271831
B23: DEPRECIATION | C23: =IFERROR('Data Sheet'!B26,0) -> 44.96 | D23: =IFERROR('Data Sheet'!C26,0) -> 45.5 | E23: =IFERROR('Data Sheet'!D26,0) -> 55.57 | F23: =IFERROR('Data Sheet'!E26,0) -> 69.74 | G23: =IFERROR('Data Sheet'!F26,0) -> 86.62 | H23: =IFERROR('Data Sheet'!G26,0) -> 82.7 | I23: =IFERROR('Data Sheet'!H26,0) -> 81.39 | J23: =IFERROR('Data Sheet'!I26,0) -> 92.43 | ... L23: =IFERROR('Data Sheet'!K26,0) -> 100.82 | M23: =IFERROR(SUM('Data Sheet'!H45:K45),0) -> 107.77
B24: DEPRECIATION% SALES | C24: =C23/C8 -> 0.023789996 | D24: =D23/D8 -> 0.022148448 | E24: =E23/E8 -> 0.023802487 | F24: =F23/F8 -> 0.031846494 | G24: =G23/G8 -> 0.051392803 | H24: =H23/H8 -> 0.032782856 | I24: =I23/I8 -> 0.026988848 | J24: =J23/J8 -> 0.02904996 | ... M24: =M23/M8 -> 0.022904203
B26: EARNINGS BEFORE TAX | C26: =IFERROR(C17-SUM(C20,C23),0) -> 954.56 | D26: =IFERROR(D17-SUM(D20,D23),0) -> 986.42 | E26: =IFERROR(E17-SUM(E20,E23),0) -> 1014.11 | F26: =IFERROR(F17-SUM(F20,F23),0) -> 1082.77 | G26: =IFERROR(G17-SUM(G20,G23),0) -> 723.48 | H26: =IFERROR(H17-SUM(H20,H23),0) -> 981.79 | I26: =IFERROR(I17-SUM(I20,I23),0) -> 1026.02 | J26: =IFERROR(J17-SUM(J20,J23),0) -> 1097.95 | ... M26: =IFERROR(M17-SUM(M20,M23),0) -> 1398.45
B27: EBT % SALES | C27: =C26/C5 -> 0.28322449 | D27: =D26/D5 -> 0.27520422 | E27: =E26/E5 -> 0.25972519 | F27: =F26/F5 -> 0.27929334 | G27: =G26/G5 -> 0.24140785 | H27: =H26/H5 -> 0.23420228 | I27: =I26/I5 -> 0.21489625 | J27: =J26/J5 -> 0.21636145 | ... M27: =M26/M5 -> 0.2248536
B29: TAX | C29: =IFERROR('Data Sheet'!B29,0) -> 369.92 | D29: =IFERROR('Data Sheet'!C29,0) -> 378.26 | E29: =IFERROR('Data Sheet'!D29,0) -> 390.06 | F29: =IFERROR('Data Sheet'!E29,0) -> 319.54 | G29: =IFERROR('Data Sheet'!F29,0) -> 202.42 | H29: =IFERROR('Data Sheet'!G29,0) -> 271.19 | I29: =IFERROR('Data Sheet'!H29,0) -> 277.6 | J29: =IFERROR('Data Sheet'!I29,0) -> 316.97 | ... L29: =IFERROR('Data Sheet'!K29,0) -> 332.38 | M29: =IFERROR(SUM('Data Sheet'!H48:K48),0) -> 376.84
B30: EFFECTIVE TAX RATE | C30: =C29/C26 -> 0.38752933 | D30: =D29/D26 -> 0.38346749 | E30: =E29/E26 -> 0.38463283 | F30: =F29/F26 -> 0.29511346 | G30: =G29/G26 -> 0.27978659 | H30: =H29/H26 -> 0.27621997 | I30: =I29/I26 -> 0.27056003 | J30: =J29/J26 -> 0.28869256 | ... M30: =M29/M26 -> 0.26946977
B32: NET PROFIT | C32: =C26-C29 -> 584.64 | D32: =D26-D29 -> 608.16 | E32: =E26-E29 -> 624.05 | F32: =F26-F29 -> 763.23 | G32: =G26-G29 -> 521.06 | H32: =H26-H29 -> 710.6 | I32: =I26-I29 -> 748.42 | J32: =J26-J29 -> 780.98 | ... M32: =M26-M29 -> 1021.61
B33: NET PROFIT % SALES | C33: =IFERROR(C32/C5,0) -> 0.17346669 | D33: =IFERROR(D32/D5,0) -> 0.16967235 | E33: =IFERROR(E32/E5,0) -> 0.15982636 | F33: =IFERROR(F32/F5,0) -> 0.19687012 | G33: =IFERROR(G32/G5,0) -> 0.17386517 | H33: =IFERROR(H32/H5,0) -> 0.16951093 | I33: =IFERROR(I32/I5,0) -> 0.15675392 | J33: =IFERROR(J32/J5,0) -> 0.15389951 | ... M33: =IFERROR(M32/M5,0) -> 0.16426235
B35: NO OF EQUITY SHARES | C35: =IFERROR('Data Sheet'!B93,0) -> 98.91 | D35: =IFERROR('Data Sheet'!C93,0) -> 98.91 | E35: =IFERROR('Data Sheet'!D93,0) -> 98.91 | F35: =IFERROR('Data Sheet'!E93,0) -> 98.91 | G35: =IFERROR('Data Sheet'!F93,0) -> 98.91 | H35: =IFERROR('Data Sheet'!G93,0) -> 98.91 | I35: =IFERROR('Data Sheet'!H93,0) -> 98.91 | J35: =IFERROR('Data Sheet'!I93,0) -> 98.91 | ... M35: =IFERROR('Data Sheet'!L93,0) -> 0
B37: EPS | C37: =IFERROR(C32/C35,0) -> 5.910828 | D37: =IFERROR(D32/D35,0) -> 6.14862 | E37: =IFERROR(E32/E35,0) -> 6.3092711 | F37: =IFERROR(F32/F35,0) -> 7.7164089 | G37: =IFERROR(G32/G35,0) -> 5.2680214 | H37: =IFERROR(H32/H35,0) -> 7.184309 | I37: =IFERROR(I32/I35,0) -> 7.5666768 | J37: =IFERROR(J32/J35,0) -> 7.8958649 | ... M37: =IFERROR(M32/M35,0) -> 0
B38: EPS GROWTH % | D38: =IFERROR(D37/C37-1,0) -> 0.040229885 | E38: =E37/D37-1 -> 0.026127993 | F38: =F37/E37-1 -> 0.223027 | G38: =G37/F37-1 -> -0.31729623 | H38: =H37/G37-1 -> 0.36375849 | I38: =I37/H37-1 -> 0.053222629 | J38: =J37/I37-1 -> 0.043504984 | K38: =K37/J37-1 -> 0.074124818 | L38: =L37/K37-1 -> 0.078868001 | M38: =M37/L37-1 -> -1
B40: DIVIDEND PER SHARE | C40: =IFERROR('Data Sheet'!B31/FINANCIALS!C35,0) -> 5.5001517 | D40: =IFERROR('Data Sheet'!C31/FINANCIALS!D35,0) -> 7.0001011 | E40: =IFERROR('Data Sheet'!D31/FINANCIALS!E35,0) -> 5.0001011 | F40: =IFERROR('Data Sheet'!E31/FINANCIALS!F35,0) -> 5.5001517 | G40: =IFERROR('Data Sheet'!F31/FINANCIALS!G35,0) -> 5.5001517 | H40: =IFERROR('Data Sheet'!G31/FINANCIALS!H35,0) -> 5.5001517 | I40: =IFERROR('Data Sheet'!H31/FINANCIALS!I35,0) -> 6.5001517 | J40: =IFERROR('Data Sheet'!I31/FINANCIALS!J35,0) -> 7.5001517 | ... M40: =IFERROR('Data Sheet'!L31/FINANCIALS!M35,0) -> 0
B41: DIVIDEND PAYOUT RATIO | C41: =IFERROR(C40/C37,0) -> 0.93052135 | D41: =IFERROR(D40/D37,0) -> 1.1384833 | E41: =IFERROR(E40/E37,0) -> 0.7925006 | F41: =IFERROR(F40/F37,0) -> 0.71278645 | G41: =IFERROR(G40/G37,0) -> 1.044064 | H41: =IFERROR(H40/H37,0) -> 0.76557838 | I41: =IFERROR(I40/I37,0) -> 0.85904973 | J41: =IFERROR(J40/J37,0) -> 0.94988348 | ... M41: =IFERROR(M40/M37,0) -> 0
B43: RETAINED EARNINGS | C43: =IFERROR(IF(C37>C40,1-C41,0),0) -> 0.069478654 | D43: =IFERROR(IF(D37>D40,1-D41,0),0) -> 0 | E43: =IFERROR(IF(E37>E40,1-E41,0),0) -> 0.2074994 | F43: =IFERROR(IF(F37>F40,1-F41,0),0) -> 0.28721355 | G43: =IFERROR(IF(G37>G40,1-G41,0),0) -> 0 | H43: =IFERROR(IF(H37>H40,1-H41,0),0) -> 0.23442162 | I43: =IFERROR(IF(I37>I40,1-I41,0),0) -> 0.14095027 | J43: =IFERROR(IF(J37>J40,1-J41,0),0) -> 0.05011652 | ... M43: =IFERROR(IF(M37>M40,1-M41,0),0) -> 0
B48: YEARS | C48: 42825 | D48: 43190 | E48: 43555 | F48: 43921 | G48: 44286 | H48: 44651 | I48: 45016 | J48: 45382 | K48: 45747 | L48: 46112 | M48: LTM
A49: # | B49: BALANCE SHEET
B50: Equity Share Capital | C50: =IFERROR('Data Sheet'!B57,0) -> 247.28 | D50: =IFERROR('Data Sheet'!C57,0) -> 494.56 | E50: =IFERROR('Data Sheet'!D57,0) -> 494.56 | F50: =IFERROR('Data Sheet'!E57,0) -> 494.56 | G50: =IFERROR('Data Sheet'!F57,0) -> 494.56 | H50: =IFERROR('Data Sheet'!G57,0) -> 494.56 | I50: =IFERROR('Data Sheet'!H57,0) -> 494.56 | J50: =IFERROR('Data Sheet'!I57,0) -> 494.56 | ... L50: =IFERROR('Data Sheet'!K57,0) -> 494.56
B51: Reserves | C51: =IFERROR('Data Sheet'!B58,0) -> 734.26 | D51: =IFERROR('Data Sheet'!C58,0) -> 525.59 | E51: =IFERROR('Data Sheet'!D58,0) -> 671.1 | F51: =IFERROR('Data Sheet'!E58,0) -> 872.39 | G51: =IFERROR('Data Sheet'!F58,0) -> 919.67 | H51: =IFERROR('Data Sheet'!G58,0) -> 1150.95 | I51: =IFERROR('Data Sheet'!H58,0) -> 1391.47 | J51: =IFERROR('Data Sheet'!I58,0) -> 1627.13 | ... L51: =IFERROR('Data Sheet'!K58,0) -> 1405.74
B52: Borrowings | C52: =IFERROR('Data Sheet'!B59,0) -> 0 | D52: =IFERROR('Data Sheet'!C59,0) -> 0 | E52: =IFERROR('Data Sheet'!D59,0) -> 0 | F52: =IFERROR('Data Sheet'!E59,0) -> 0 | G52: =IFERROR('Data Sheet'!F59,0) -> 0 | H52: =IFERROR('Data Sheet'!G59,0) -> 6.72 | I52: =IFERROR('Data Sheet'!H59,0) -> 49.95 | J52: =IFERROR('Data Sheet'!I59,0) -> 76.95 | ... L52: =IFERROR('Data Sheet'!K59,0) -> 62.81
B53: Other Liabilities | C53: =IFERROR('Data Sheet'!B60,0) -> 906.79 | D53: =IFERROR('Data Sheet'!C60,0) -> 956.8 | E53: =IFERROR('Data Sheet'!D60,0) -> 941.11 | F53: =IFERROR('Data Sheet'!E60,0) -> 861.83 | G53: =IFERROR('Data Sheet'!F60,0) -> 979.27 | H53: =IFERROR('Data Sheet'!G60,0) -> 1051.79 | I53: =IFERROR('Data Sheet'!H60,0) -> 1133.03 | J53: =IFERROR('Data Sheet'!I60,0) -> 1221.29 | ... L53: =IFERROR('Data Sheet'!K60,0) -> 1431.74
B54: Total LIABILITY | C54: =IFERROR('Data Sheet'!B61,0) -> 1888.33 | D54: =IFERROR('Data Sheet'!C61,0) -> 1976.95 | E54: =IFERROR('Data Sheet'!D61,0) -> 2106.77 | F54: =IFERROR('Data Sheet'!E61,0) -> 2228.78 | G54: =IFERROR('Data Sheet'!F61,0) -> 2393.5 | H54: =IFERROR('Data Sheet'!G61,0) -> 2704.02 | I54: =IFERROR('Data Sheet'!H61,0) -> 3069.01 | J54: =IFERROR('Data Sheet'!I61,0) -> 3419.93 | ... L54: =IFERROR('Data Sheet'!K61,0) -> 3394.85
B56: FIXED ASSETS NET BLOCK | C56: =IFERROR('Data Sheet'!B62,0) -> 146.97 | D56: =IFERROR('Data Sheet'!C62,0) -> 138.97 | E56: =IFERROR('Data Sheet'!D62,0) -> 186.04 | F56: =IFERROR('Data Sheet'!E62,0) -> 199.7 | G56: =IFERROR('Data Sheet'!F62,0) -> 209.21 | H56: =IFERROR('Data Sheet'!G62,0) -> 201.18 | I56: =IFERROR('Data Sheet'!H62,0) -> 260.79 | J56: =IFERROR('Data Sheet'!I62,0) -> 258.85 | ... L56: =IFERROR('Data Sheet'!K62,0) -> 333.6
B57: Capital Work in Progress | C57: =IFERROR('Data Sheet'!B63,0) -> 37.26 | D57: =IFERROR('Data Sheet'!C63,0) -> 57.27 | E57: =IFERROR('Data Sheet'!D63,0) -> 35.04 | F57: =IFERROR('Data Sheet'!E63,0) -> 27.33 | G57: =IFERROR('Data Sheet'!F63,0) -> 43.54 | H57: =IFERROR('Data Sheet'!G63,0) -> 50.04 | I57: =IFERROR('Data Sheet'!H63,0) -> 60.76 | J57: =IFERROR('Data Sheet'!I63,0) -> 108.36 | ... L57: =IFERROR('Data Sheet'!K63,0) -> 72.07
B58: Investments | C58: =IFERROR('Data Sheet'!B64,0) -> 0 | D58: =IFERROR('Data Sheet'!C64,0) -> 0 | E58: =IFERROR('Data Sheet'!D64,0) -> 0 | F58: =IFERROR('Data Sheet'!E64,0) -> 0 | G58: =IFERROR('Data Sheet'!F64,0) -> 0 | H58: =IFERROR('Data Sheet'!G64,0) -> 0 | I58: =IFERROR('Data Sheet'!H64,0) -> 325 | J58: =IFERROR('Data Sheet'!I64,0) -> 487.5 | ... L58: =IFERROR('Data Sheet'!K64,0) -> 442.8
B59: Other Assets | C59: =IFERROR('Data Sheet'!B65-SUM('Data Sheet'!B67:B69),0) -> 283.12 | D59: =IFERROR('Data Sheet'!C65-SUM('Data Sheet'!C67:C69),0) -> 391.94 | E59: =IFERROR('Data Sheet'!D65-SUM('Data Sheet'!D67:D69),0) -> 293.25 | F59: =IFERROR('Data Sheet'!E65-SUM('Data Sheet'!E67:E69),0) -> 269 | G59: =IFERROR('Data Sheet'!F65-SUM('Data Sheet'!F67:F69),0) -> 319.2 | H59: =IFERROR('Data Sheet'!G65-SUM('Data Sheet'!G67:G69),0) -> 349.29 | I59: =IFERROR('Data Sheet'!H65-SUM('Data Sheet'!H67:H69),0) -> 319.95 | J59: =IFERROR('Data Sheet'!I65-SUM('Data Sheet'!I67:I69),0) -> 409.69 | ... L59: =IFERROR('Data Sheet'!K65-SUM('Data Sheet'!K67:K69),0) -> 385.84
...

Sheet Sheet1
B2: ="RATIO ANALYSIS - "&'Data Sheet'!B1 -> RATIO ANALYSIS - CASTROL INDIA LTD
B3: YEARS | C3: ='Data Sheet'!B16 -> 42735 | D3: ='Data Sheet'!C16 -> 43100 | E3: ='Data Sheet'!D16 -> 43465 | F3: ='Data Sheet'!E16 -> 43830 | G3: ='Data Sheet'!F16 -> 44196 | H3: ='Data Sheet'!G16 -> 44561 | I3: ='Data Sheet'!H16 -> 44926 | J3: ='Data Sheet'!I16 -> 45291 | ... L3: ='Data Sheet'!K16 -> 46022
B5: SALES GROWTH | D5: =IFERROR(FINANCIALS!D6,0) -> 0.063492299 | E5: =IFERROR(FINANCIALS!E6,0) -> 0.089341911 | F5: =IFERROR(FINANCIALS!F6,0) -> -0.0071019708 | G5: =IFERROR(FINANCIALS!G6,0) -> -0.22696437 | H5: =IFERROR(FINANCIALS!H6,0) -> 0.39878942 | I5: =IFERROR(FINANCIALS!I6,0) -> 0.13893647 | J5: =IFERROR(FINANCIALS!J6,0) -> 0.06285907 | K5: =IFERROR(FINANCIALS!K6,0) -> 0.057194543 | L5: =IFERROR(FINANCIALS!L6,0) -> 0.066479026
B6: EBITDA GROWTH | D6: =IFERROR(FINANCIALS!D17/FINANCIALS!C17-1,0) -> 0.032087912 | E6: =IFERROR(FINANCIALS!E17/FINANCIALS!D17-1,0) -> 0.036443008 | F6: =IFERROR(FINANCIALS!F17/FINANCIALS!E17-1,0) -> 0.077448939 | G6: =IFERROR(FINANCIALS!G17/FINANCIALS!F17-1,0) -> -0.2942186 | H6: =IFERROR(FINANCIALS!H17/FINANCIALS!G17-1,0) -> 0.31026945 | I6: =IFERROR(FINANCIALS!I17/FINANCIALS!H17-1,0) -> 0.041728372 | J6: =IFERROR(FINANCIALS!J17/FINANCIALS!I17-1,0) -> 0.077819366 | K6: =IFERROR(FINANCIALS!K17/FINANCIALS!J17-1,0) -> 0.067192026 | L6: =IFERROR(FINANCIALS!L17/FINANCIALS!K17-1,0) -> 0.054067584
B7: EBIT GROWTH | D7: =IFERROR(FINANCIALS!D26/FINANCIALS!C26-1,0) -> 0.033376634 | E7: =IFERROR(FINANCIALS!E26/FINANCIALS!D26-1,0) -> 0.028071207 | F7: =IFERROR(FINANCIALS!F26/FINANCIALS!E26-1,0) -> 0.067704687 | G7: =IFERROR(FINANCIALS!G26/FINANCIALS!F26-1,0) -> -0.33182486 | H7: =IFERROR(FINANCIALS!H26/FINANCIALS!G26-1,0) -> 0.3570382 | I7: =IFERROR(FINANCIALS!I26/FINANCIALS!H26-1,0) -> 0.045050367 | J7: =IFERROR(FINANCIALS!J26/FINANCIALS!I26-1,0) -> 0.070105846 | K7: =IFERROR(FINANCIALS!K26/FINANCIALS!J26-1,0) -> 0.064939205 | L7: =IFERROR(FINANCIALS!L26/FINANCIALS!K26-1,0) -> 0.058293778
B8: NET PROFIT GROWTH | D8: =IFERROR(FINANCIALS!D32/FINANCIALS!C32-1,0) -> 0.040229885 | E8: =IFERROR(FINANCIALS!E32/FINANCIALS!D32-1,0) -> 0.026127993 | F8: =IFERROR(FINANCIALS!F32/FINANCIALS!E32-1,0) -> 0.223027 | G8: =IFERROR(FINANCIALS!G32/FINANCIALS!F32-1,0) -> -0.31729623 | H8: =IFERROR(FINANCIALS!H32/FINANCIALS!G32-1,0) -> 0.36375849 | I8: =IFERROR(FINANCIALS!I32/FINANCIALS!H32-1,0) -> 0.053222629 | J8: =IFERROR(FINANCIALS!J32/FINANCIALS!I32-1,0) -> 0.043504984 | K8: =IFERROR(FINANCIALS!K32/FINANCIALS!J32-1,0) -> 0.074124818 | L8: =IFERROR(FINANCIALS!L32/FINANCIALS!K32-1,0) -> 0.078868001
B9: DIVIDENED GROWTH | D9: =IFERROR(FINANCIALS!D40/FINANCIALS!C40-1,0) -> 0.27271056 | E9: =IFERROR(FINANCIALS!E40/FINANCIALS!D40-1,0) -> -0.28571016 | F9: =IFERROR(FINANCIALS!F40/FINANCIALS!E40-1,0) -> 0.10000809 | G9: =IFERROR(FINANCIALS!G40/FINANCIALS!F40-1,0) -> 0 | H9: =IFERROR(FINANCIALS!H40/FINANCIALS!G40-1,0) -> 0 | I9: =IFERROR(FINANCIALS!I40/FINANCIALS!H40-1,0) -> 0.18181317 | J9: =IFERROR(FINANCIALS!J40/FINANCIALS!I40-1,0) -> 0.15384256 | K9: =IFERROR(FINANCIALS!K40/FINANCIALS!J40-1,0) -> 0.86666936 | L9: =IFERROR(FINANCIALS!L40/FINANCIALS!K40-1,0) -> -0.3750009
B11: GROSS MARGIN | C11: =IFERROR(FINANCIALS!C12,0) -> 0.43926262 | D11: =IFERROR(FINANCIALS!D12,0) -> 0.42685921 | E11: =IFERROR(FINANCIALS!E12,0) -> 0.4020745 | F11: =IFERROR(FINANCIALS!F12,0) -> 0.43513498 | G11: =IFERROR(FINANCIALS!G12,0) -> 0.43760594 | H11: =IFERROR(FINANCIALS!H12,0) -> 0.39822903 | I11: =IFERROR(FINANCIALS!I12,0) -> 0.36837442 | J11: =IFERROR(FINANCIALS!J12,0) -> 0.37300403 | ... L11: =IFERROR(FINANCIALS!L12,0) -> 0.38519619
B12: EDITDA MARGIN | C12: =IFERROR(FINANCIALS!C18,0) -> 0.29700356 | D12: =IFERROR(FINANCIALS!D18,0) -> 0.28823319 | E12: =IFERROR(FINANCIALS!E18,0) -> 0.27423647 | F12: =IFERROR(FINANCIALS!F18,0) -> 0.29758926 | G12: =IFERROR(FINANCIALS!G18,0) -> 0.27169894 | H12: =IFERROR(FINANCIALS!H18,0) -> 0.25450495 | I12: =IFERROR(FINANCIALS!I18,0) -> 0.23278298 | J12: =IFERROR(FINANCIALS!J18,0) -> 0.23605952 | ... L12: =IFERROR(FINANCIALS!L18,0) -> 0.23551866
B13: EBIT MARGIN | C13: =IFERROR((FINANCIALS!C17-FINANCIALS!C23)/FINANCIALS!C5,0) -> 0.28366362 | D13: =IFERROR((FINANCIALS!D17-FINANCIALS!D23)/FINANCIALS!D5,0) -> 0.27553901 | E13: =IFERROR((FINANCIALS!E17-FINANCIALS!E23)/FINANCIALS!E5,0) -> 0.26000435 | F13: =IFERROR((FINANCIALS!F17-FINANCIALS!F23)/FINANCIALS!F5,0) -> 0.27960029 | G13: =IFERROR((FINANCIALS!G17-FINANCIALS!G23)/FINANCIALS!G5,0) -> 0.24279594 | H13: =IFERROR((FINANCIALS!H17-FINANCIALS!H23)/FINANCIALS!H5,0) -> 0.23477717 | I13: =IFERROR((FINANCIALS!I17-FINANCIALS!I23)/FINANCIALS!I5,0) -> 0.21573613 | J13: =IFERROR((FINANCIALS!J17-FINANCIALS!J23)/FINANCIALS!J5,0) -> 0.21784531 | ... L13: =IFERROR((FINANCIALS!L17-FINANCIALS!L23)/FINANCIALS!L5,0) -> 0.2178974
B14: EBT MARGIN | C14: =IFERROR(FINANCIALS!C27,0) -> 0.28322449 | D14: =IFERROR(FINANCIALS!D27,0) -> 0.27520422 | E14: =IFERROR(FINANCIALS!E27,0) -> 0.25972519 | F14: =IFERROR(FINANCIALS!F27,0) -> 0.27929334 | G14: =IFERROR(FINANCIALS!G27,0) -> 0.24140785 | H14: =IFERROR(FINANCIALS!H27,0) -> 0.23420228 | I14: =IFERROR(FINANCIALS!I27,0) -> 0.21489625 | J14: =IFERROR(FINANCIALS!J27,0) -> 0.21636145 | ... L14: =IFERROR(FINANCIALS!L27,0) -> 0.2162737
B15: NET PROFIT MARGIN | C15: =IFERROR(FINANCIALS!C33,0) -> 0.17346669 | D15: =IFERROR(FINANCIALS!D33,0) -> 0.16967235 | E15: =IFERROR(FINANCIALS!E33,0) -> 0.15982636 | F15: =IFERROR(FINANCIALS!F33,0) -> 0.19687012 | G15: =IFERROR(FINANCIALS!G33,0) -> 0.17386517 | H15: =IFERROR(FINANCIALS!H33,0) -> 0.16951093 | I15: =IFERROR(FINANCIALS!I33,0) -> 0.15675392 | J15: =IFERROR(FINANCIALS!J33,0) -> 0.15389951 | ... L15: =IFERROR(FINANCIALS!L33,0) -> 0.15818055
B18: SALESEXPENSES%SALES | C18: =IFERROR(FINANCIALS!C15,0) -> 0.14225907 | D18: =IFERROR(FINANCIALS!D15,0) -> 0.13862602 | E18: =IFERROR(FINANCIALS!E15,0) -> 0.12783804 | F18: =IFERROR(FINANCIALS!F15,0) -> 0.13754572 | G18: =IFERROR(FINANCIALS!G15,0) -> 0.165907 | H18: =IFERROR(FINANCIALS!H15,0) -> 0.14372409 | I18: =IFERROR(FINANCIALS!I15,0) -> 0.13559145 | J18: =IFERROR(FINANCIALS!J15,0) -> 0.13694451 | ... L18: =IFERROR(FINANCIALS!L15,0) -> 0.14967753
B19: DEPRECIATION%SALES | C19: =IFERROR(FINANCIALS!C24,0) -> 0.023789996 | D19: =IFERROR(FINANCIALS!D24,0) -> 0.022148448 | E19: =IFERROR(FINANCIALS!E24,0) -> 0.023802487 | F19: =IFERROR(FINANCIALS!F24,0) -> 0.031846494 | G19: =IFERROR(FINANCIALS!G24,0) -> 0.051392803 | H19: =IFERROR(FINANCIALS!H24,0) -> 0.032782856 | I19: =IFERROR(FINANCIALS!I24,0) -> 0.026988848 | J19: =IFERROR(FINANCIALS!J24,0) -> 0.02904996 | ... L19: =IFERROR(FINANCIALS!L24,0) -> 0.028661587
B20: OPERATINGINCOME%SALES | C20: =C13 -> 0.28366362 | D20: =D13 -> 0.27553901 | E20: =E13 -> 0.26000435 | F20: =F13 -> 0.27960029 | G20: =G13 -> 0.24279594 | H20: =H13 -> 0.23477717 | I20: =I13 -> 0.21573613 | J20: =J13 -> 0.21784531 | ... L20: =L13 -> 0.2178974
B22: RETURN ON CAPITAL EMPLOYED | C22: =(FINANCIALS!C17-FINANCIALS!C23)/(SUM(FINANCIALS!C50:C52)) -> 0.97402042 | D22: =(FINANCIALS!D17-FINANCIALS!D23)/(SUM(FINANCIALS!D50:D52)) -> 0.96811253 | E22: =(FINANCIALS!E17-FINANCIALS!E23)/(SUM(FINANCIALS!E50:E52)) -> 0.87092291 | F22: =(FINANCIALS!F17-FINANCIALS!F23)/(SUM(FINANCIALS!F50:F52)) -> 0.79297707 | G22: =(FINANCIALS!G17-FINANCIALS!G23)/(SUM(FINANCIALS!G50:G52)) -> 0.5145132 | H22: =(FINANCIALS!H17-FINANCIALS!H23)/(SUM(FINANCIALS!H50:H52)) -> 0.59567978 | I22: =(FINANCIALS!I17-FINANCIALS!I23)/(SUM(FINANCIALS!I50:I52)) -> 0.53204579 | J22: =(FINANCIALS!J17-FINANCIALS!J23)/(SUM(FINANCIALS!J50:J52)) -> 0.50280173 | ... L22: =(FINANCIALS!L17-FINANCIALS!L23)/(SUM(FINANCIALS!L50:L52)) -> 0.63506375
B23: RETAINED EARNING% | C23: =IFERROR(FINANCIALS!C43,0) -> 0.069478654 | D23: =IFERROR(FINANCIALS!D43,0) -> 0 | E23: =IFERROR(FINANCIALS!E43,0) -> 0.2074994 | F23: =IFERROR(FINANCIALS!F43,0) -> 0.28721355 | G23: =IFERROR(FINANCIALS!G43,0) -> 0 | H23: =IFERROR(FINANCIALS!H43,0) -> 0.23442162 | I23: =IFERROR(FINANCIALS!I43,0) -> 0.14095027 | J23: =IFERROR(FINANCIALS!J43,0) -> 0.05011652 | ... L23: =IFERROR(FINANCIALS!L43,0) -> 0.043700209
B24: RETURN ON EQUITY % | C24: =IFERROR(FINANCIALS!C32/SUM(FINANCIALS!C50:C51),0) -> 0.59563543 | D24: =IFERROR(FINANCIALS!D32/SUM(FINANCIALS!D50:D51),0) -> 0.59614763 | E24: =IFERROR(FINANCIALS!E32/SUM(FINANCIALS!E50:E51),0) -> 0.53536194 | F24: =IFERROR(FINANCIALS!F32/SUM(FINANCIALS!F50:F51),0) -> 0.55834522 | G24: =IFERROR(FINANCIALS!G32/SUM(FINANCIALS!G50:G51),0) -> 0.36844078 | H24: =IFERROR(FINANCIALS!H32/SUM(FINANCIALS!H50:H51),0) -> 0.4318418 | I24: =IFERROR(FINANCIALS!I32/SUM(FINANCIALS!I50:I51),0) -> 0.39682296 | J24: =IFERROR(FINANCIALS!J32/SUM(FINANCIALS!J50:J51),0) -> 0.36809336 | ... L24: =IFERROR(FINANCIALS!L32/SUM(FINANCIALS!L50:L51),0) -> 0.47625638
B25: SELF SUSTAINED GROWTH RATE | C25: =IFERROR(C23*C24,0) -> 0.041383948 | D25: =IFERROR(D23*D24,0) -> 0 | E25: =IFERROR(E23*E24,0) -> 0.11108728 | F25: =IFERROR(F23*F24,0) -> 0.16036431 | G25: =IFERROR(G23*G24,0) -> 0 | H25: =IFERROR(H23*H24,0) -> 0.10123305 | I25: =IFERROR(I23*I24,0) -> 0.055932302 | J25: =IFERROR(J23*J24,0) -> 0.018447558 | ... L25: =IFERROR(L23*L24,0) -> 0.020812503
B26: INTEREST COVERAGE RATIO | C26: =(FINANCIALS!C17-FINANCIALS!C23)/FINANCIALS!C20 -> 645.97297 | D26: =(FINANCIALS!D17-FINANCIALS!D23)/FINANCIALS!D20 -> 823.01667 | E26: =(FINANCIALS!E17-FINANCIALS!E23)/FINANCIALS!E20 -> 931.37615 | F26: =(FINANCIALS!F17-FINANCIALS!F23)/FINANCIALS!F20 -> 910.89076 | G26: =(FINANCIALS!G17-FINANCIALS!G23)/FINANCIALS!G20 -> 174.91346 | H26: =(FINANCIALS!H17-FINANCIALS!H23)/FINANCIALS!H20 -> 408.38174 | I26: =(FINANCIALS!I17-FINANCIALS!I23)/FINANCIALS!I20 -> 256.86534 | J26: =(FINANCIALS!J17-FINANCIALS!J23)/FINANCIALS!J20 -> 146.81009 | ... L26: =(FINANCIALS!L17-FINANCIALS!L23)/FINANCIALS!L20 -> 134.19806
B28: Debtor Turnover Ratio | C28: =FINANCIALS!C5/FINANCIALS!C62 -> 13.205587 | D28: =FINANCIALS!D5/FINANCIALS!D62 -> 12.577885 | E28: =FINANCIALS!E5/FINANCIALS!E62 -> 9.9656713 | F28: =FINANCIALS!F5/FINANCIALS!F62 -> 8.0426944 | G28: =FINANCIALS!G5/FINANCIALS!G62 -> 16.604355 | H28: =FINANCIALS!H5/FINANCIALS!H62 -> 13.451179 | I28: =FINANCIALS!I5/FINANCIALS!I62 -> 13.627383 | J28: =FINANCIALS!J5/FINANCIALS!J62 -> 12.001821 | ... L28: =FINANCIALS!L5/FINANCIALS!L62 -> 12.090826
B29: Credit Turnover Ratio | C29: =IFERROR(FINANCIALS!C5/FINANCIALS!C53,0) -> 3.7167701 | D29: =IFERROR(FINANCIALS!D5/FINANCIALS!D53,0) -> 3.7461538 | E29: =IFERROR(FINANCIALS!E5/FINANCIALS!E53,0) -> 4.1488774 | F29: =IFERROR(FINANCIALS!F5/FINANCIALS!F53,0) -> 4.4983581 | G29: =IFERROR(FINANCIALS!G5/FINANCIALS!G53,0) -> 3.0603613 | H29: =IFERROR(FINANCIALS!H5/FINANCIALS!H53,0) -> 3.9856435 | I29: =IFERROR(FINANCIALS!I5/FINANCIALS!I53,0) -> 4.2139131 | J29: =IFERROR(FINANCIALS!J5/FINANCIALS!J53,0) -> 4.1551229 | ... L29: =IFERROR(FINANCIALS!L5/FINANCIALS!L53,0) -> 3.9961865
B30: Inventory Turnoover ratio | C30: =IFERROR(FINANCIALS!C5/FINANCIALS!C63,0) -> 9.8008898 | D30: =IFERROR(FINANCIALS!D5/FINANCIALS!D63,0) -> 11.216072 | E30: =IFERROR(FINANCIALS!E5/FINANCIALS!E63,0) -> 8.547801 | F30: =IFERROR(FINANCIALS!F5/FINANCIALS!F63,0) -> 12.722565 | G30: =IFERROR(FINANCIALS!G5/FINANCIALS!G63,0) -> 8.1688882 | H30: =IFERROR(FINANCIALS!H5/FINANCIALS!H63,0) -> 8.5265128 | I30: =IFERROR(FINANCIALS!I5/FINANCIALS!I63,0) -> 8.9336315 | J30: =IFERROR(FINANCIALS!J5/FINANCIALS!J63,0) -> 9.5222735 | ... L30: =IFERROR(FINANCIALS!L5/FINANCIALS!L63,0) -> 10.472416
B31: Fixed Asset Turnover | C31: =IFERROR(FINANCIALS!C5/FINANCIALS!C52,0) -> 0 | D31: =IFERROR(FINANCIALS!D5/FINANCIALS!D52,0) -> 0 | E31: =IFERROR(FINANCIALS!E5/FINANCIALS!E52,0) -> 0 | F31: =IFERROR(FINANCIALS!F5/FINANCIALS!F52,0) -> 0 | G31: =IFERROR(FINANCIALS!G5/FINANCIALS!G52,0) -> 0 | H31: =IFERROR(FINANCIALS!H5/FINANCIALS!H52,0) -> 623.81845 | I31: =IFERROR(FINANCIALS!I5/FINANCIALS!I52,0) -> 95.585385 | J31: =IFERROR(FINANCIALS!J5/FINANCIALS!J52,0) -> 65.946849 | ... L31: =IFERROR(FINANCIALS!L5/FINANCIALS!L52,0) -> 91.092183
B32: Capital Turnover Ratio | C32: =IFERROR(FINANCIALS!C5/SUM(FINANCIALS!C50:C51),) -> 3.4337164 | D32: =IFERROR(FINANCIALS!D5/SUM(FINANCIALS!D50:D51),) -> 3.5135225 | E32: =IFERROR(FINANCIALS!E5/SUM(FINANCIALS!E50:E51),) -> 3.3496474 | F32: =IFERROR(FINANCIALS!F5/SUM(FINANCIALS!F50:F51),) -> 2.8361096 | G32: =IFERROR(FINANCIALS!G5/SUM(FINANCIALS!G50:G51),) -> 2.1191178 | H32: =IFERROR(FINANCIALS!H5/SUM(FINANCIALS!H50:H51),) -> 2.5475749 | I32: =IFERROR(FINANCIALS!I5/SUM(FINANCIALS!I50:I51),) -> 2.5315027 | J32: =IFERROR(FINANCIALS!J5/SUM(FINANCIALS!J50:J51),) -> 2.3917773 | ... L32: =IFERROR(FINANCIALS!L5/SUM(FINANCIALS!L50:L51),) -> 3.0108404
B34: debtor days | C34: =IFERROR(365/C28,0) -> 27.639816
B35: Payable days | C35: =IFERROR(365/C29,0) -> 98.203544
B36: Inventory Days | C36: =IFERROR(365/C30,0) -> 37.241516
B37: Cash Conversion cycle

Sheet LBO
E2: CASTROL LTD | J2: ASSUMPTIONS
E3: LEVERAGED BUYOUT
J4: Market Cap | K4: 18999
B5: FINANCIAL FORECAST | C5: 45747 | D5: 46112 | E5: 46477 | F5: 46843 | G5: 47208 | H5: 47573 | J5: Current Price | K5: 192
B6: REVENUE | C6: =FINANCIALS!L5 -> 5721.5 | D6: =C6*(1+$K$6) -> 6093.3155 | E6: =D6*(1+$K$6) -> 6489.2936 | F6: =E6*(1+$K$6) -> 6911.0046 | G6: =F6*(1+$K$6) -> 7360.1209 | H6: =G6*(1+$K$6) -> 7838.4232 | J6: REVENUE | K6: =MEDIAN(FINANCIALS!D6:M6) -> 0.064985662
B7: COGS | C7: =C6*$K$7 -> 3443.0326 | D7: =D6*$K$7 -> 3666.7803 | E7: =E6*$K$7 -> 3905.0685 | F7: =F6*$K$7 -> 4158.842 | G7: =G6*$K$7 -> 4429.107 | H7: =H6*$K$7 -> 4716.9355 | J7: COGS | K7: =MEDIAN(FINANCIALS!C9:M9) -> 0.60177097
B8: GROSS PROFIT | C8: =C6-C7 -> 2278.4674 | D8: =D6-D7 -> 2426.5351 | E8: =E6-E7 -> 2584.2251 | F8: =F6-F7 -> 2752.1627 | G8: =G6-G7 -> 2931.0138 | H8: =H6-H7 -> 3121.4877 | J8: DEPRECIATION | K8: =MEDIAN(FINANCIALS!C24:M24) -> 0.028661587
B9: SELLING EXPENSES | C9: =C6*$K$12 -> 803.542 | D9: =D6*$K$12 -> 855.76071 | E9: =E6*$K$12 -> 911.37288 | F9: =F6*$K$12 -> 970.59905 | G9: =G6*$K$12 -> 1033.6741 | H9: =H6*$K$12 -> 1100.8481 | J9: TAXES | K9: 0.25
B10: EDITDA | C10: =C8-C9 -> 1474.9254 | D10: =D8-D9 -> 1570.7744 | E10: =E8-E9 -> 1672.8522 | F10: =F8-F9 -> 1781.5636 | G10: =G8-G9 -> 1897.3397 | H10: =H8-H9 -> 2020.6396 | J10: WPRKING CAP AS PERCENT OF SALES | K10: 0.01
B11: DEPRECIATION | C11: =C6*$K$8 -> 163.98727 | D11: =D6*$K$8 -> 174.64409 | E11: =E6*$K$8 -> 185.99346 | F11: =F6*$K$8 -> 198.08036 | G11: =G6*$K$8 -> 210.95275 | H11: =H6*$K$8 -> 224.66165 | J11: CURRENT EBIDTA | K11: =C10 -> 1474.9254
B12: EBIT | C12: =C10-C11 -> 1310.9381 | D12: =D10-D11 -> 1396.1303 | E12: =E10-E11 -> 1486.8588 | F12: =F10-F11 -> 1583.4833 | G12: =G10-G11 -> 1686.387 | H12: =H10-H11 -> 1795.978 | J12: SELLING EX | K12: =MEDIAN(FINANCIALS!C15:L15) -> 0.14044254
B13: INTEREST | D13: =SUM(D30,D38) -> 1069.3209 | E13: =SUM(E30,E38) -> 1052.7453 | F13: =SUM(F30,F38) -> 1029.283 | G13: =SUM(G30,G38) -> 998.09436 | H13: =SUM(H30,H38) -> 958.25872
B14: EBT | C14: =C12-C13 -> 1310.9381 | D14: =D12-D13 -> 326.8094 | E14: =E12-E13 -> 434.1135 | F14: =F12-F13 -> 554.2003 | G14: =G12-G13 -> 688.29263 | H14: =H12-H13 -> 837.71925 | J14: DEBT FACILITIES | T14: =K4+53 -> 19052
B15: TAXES | C15: =C14*$K$9 -> 327.73454 | D15: =D14*$K$9 -> 81.70235 | E15: =E14*$K$9 -> 108.52838 | F15: =F14*$K$9 -> 138.55008 | G15: =G14*$K$9 -> 172.07316 | H15: =H14*$K$9 -> 209.42981 | J15: TERM A | K15: 3
B16: NET INCOME | C16: =C14-C15 -> 983.20361 | D16: =D14-D15 -> 245.10705 | E16: =E14-E15 -> 325.58513 | F16: =F14-F15 -> 415.65023 | G16: =G14-G15 -> 516.21947 | H16: =H14-H15 -> 628.28944 | J16: TERM B | K16: 3.5
J18: INTEREST RATES
B19: CASH FLOW PROJECTION | C19: 45747 | D19: 46112 | E19: 46477 | F19: 46843 | G19: 47208 | H19: 47573 | J19: TERM A | K19: 0.09
B20: NET INCOME | C20: =C16 -> 983.20361 | D20: =D16 -> 245.10705 | E20: =E16 -> 325.58513 | F20: =F16 -> 415.65023 | G20: =G16 -> 516.21947 | H20: =H16 -> 628.28944 | J20: TERM B | K20: 0.13
B21: ADD BACK DEPRECIATION | C21: =C11 -> 163.98727 | D21: =D11 -> 174.64409 | E21: =E11 -> 185.99346 | F21: =F11 -> 198.08036 | G21: =G11 -> 210.95275 | H21: =H11 -> 224.66165
B22: CHANGE IN WORK CAP | C22: =-C6*$K$10 -> -57.215 | D22: =-D6*$K$10 -> -60.933155 | E22: =-E6*$K$10 -> -64.892936 | F22: =-F6*$K$10 -> -69.110046 | G22: =-G6*$K$10 -> -73.601209 | H22: =-H6*$K$10 -> -78.384232 | J22: ACQUISITION PREMIUM | K22: 0.15
B23: LESS NET CAPEX | C23: =-C21 -> -163.98727 | D23: =-D21 -> -174.64409 | E23: =-E21 -> -185.99346 | F23: =-F21 -> -198.08036 | G23: =-G21 -> -210.95275 | H23: =-H21 -> -224.66165 | J23: EQUITY VALUE | K23: =K4*(1+K22) -> 21848.85
B24: CASH FOR REIMBURSEMENT | C24: =SUM(C20:C23) -> 925.98861 | D24: =SUM(D20:D23) -> 184.17389 | E24: =SUM(E20:E23) -> 260.69219 | F24: =SUM(F20:F23) -> 346.54018 | G24: =SUM(G20:G23) -> 442.61826 | H24: =SUM(H20:H23) -> 549.9052 | J24: ENTERPRISE VALUE AT AQUISITITION | K24: =K23+53 -> 21901.85
J25: EV/EBITDA | K25: =T14/K11 -> 12.917263
J26: TOTAL EQUITY NEEDED | K26: =K24-K31 -> 12314.835
B27: DEBT STRUCTURE
B28: TERM A | C28: 45747 | D28: 46112 | E28: 46477 | F28: 46843 | G28: 47208 | H28: 47573 | J28: DEBT TOTAL
B29: BEGINNING BALANCE | D29: =K29 -> 4424.7762 | E29: =D33 -> 4240.6023 | F29: =E33 -> 3979.9102 | G29: =F33 -> 3633.37 | H29: =G33 -> 3190.7517 | J29: TERM A | K29: =K15*K11 -> 4424.7762
B30: INTEREST | D30: =D29*$K$19 -> 398.22986 | E30: =E29*$K$19 -> 381.65421 | F30: =F29*$K$19 -> 358.19191 | G30: =G29*$K$19 -> 327.0033 | H30: =H29*$K$19 -> 287.16765 | J30: TERM B | K30: =K16*K11 -> 5162.2389
B31: PAYDOWN | D31: =MIN(D24,D29) -> 184.17389 | E31: =MIN(E24,E29) -> 260.69219 | F31: =MIN(F24,F29) -> 346.54018 | G31: =MIN(G24,G29) -> 442.61826 | H31: =MIN(H24,H29) -> 549.9052 | J31: TOTAL | K31: =SUM(K29:K30) -> 9587.0152
B32: D
B33: ENDING BALANCE | D33: =D29-D31 -> 4240.6023 | E33: =E29-E31 -> 3979.9102 | F33: =F29-F31 -> 3633.37 | G33: =G29-G31 -> 3190.7517 | H33: =H29-H31 -> 2640.8465
B36: TERM B | C36: 45747 | D36: 46112 | E36: 46477 | F36: 46843 | G36: 47208 | H36: 47573
B37: BEGINNING BALANCE | D37: =K30 -> 5162.2389 | E37: =D41 -> 5162.2389 | F37: =E41 -> 5162.2389 | G37: =F41 -> 5162.2389 | H37: =G41 -> 5162.2389
B38: INTEREST | D38: =D37*$K$20 -> 671.09106 | E38: =E37*$K$20 -> 671.09106 | F38: =F37*$K$20 -> 671.09106 | G38: =G37*$K$20 -> 671.09106 | H38: =H37*$K$20 -> 671.09106
B39: PAYDOWN | D39: =MIN(D24,D24-D31) -> 0 | E39: =MIN(E24,E24-E31) -> 0 | F39: =MIN(F24,F24-F31) -> 0 | G39: =MIN(G24,G24-G31) -> 0 | H39: =MIN(H24,H24-H31) -> 0
B41: ENDING BALANCE | D41: =D37-D39 -> 5162.2389 | E41: =E37-E39 -> 5162.2389 | F41: =F37-F39 -> 5162.2389 | G41: =G37-G39 -> 5162.2389 | H41: =H37-H39 -> 5162.2389
B43: IRR
B44: EBITDA AT EXIT | H44: =H10 -> 2020.6396
B45: EXIT MULTIPLE | H45: 12
B46: ENTERPRISE VALUE | H46: =H44*H45 -> 24247.675
...

Sheet HISTORICAL FS
N3: 13041
T4: 42064 | U4: 42430 | V4: 42795 | W4: 43160 | X4: 43525 | Y4: 43891 | Z4: 44256 | AA4: 44621 | AB4: 44986 | AC4: 45352 | AD4: 45717 | AE4: 46082
S5: Cash from Operating Activity - | T5: 35531 | U5: 37900 | V5: 30199 | W5: 23857 | X5: 18891 | Y5: 26633 | Z5: 29001 | AA5: 14283 | AB5: 35388 | AC5: 67915 | AD5: 63102 | AE5: 13041
S6: Profit from operations | T6: 43397 | U6: 38626 | V6: 28840 | W6: 33312 | X6: 28771 | Y6: 23352 | Z6: 31198 | AA6: 26943 | AB6: 41694 | AC6: 65106 | AD6: 58937 | AE6: 25393
S7: Receivables | T7: -3179 | U7: -2223 | V7: -4152 | W7: -10688 | X7: -9109 | Y7: 9950 | Z7: -5505 | AA7: 185 | AB7: -2213 | AC7: -1876 | AD7: 3573 | AE7: -1587
S8: Inventory | T8: -3692 | U8: -5743 | V8: -6621 | W8: -3560 | X8: 2069 | Y8: 2326 | Z8: 3814 | AA8: 472 | AB8: -5665 | AC8: -7265 | AD8: 2127 | AE8: -4318
S9: Payables | T9: 3598 | U9: 3947 | V9: 9301 | W9: 7320 | X9: -4692 | Y9: -8085 | Z9: 5748 | AA9: -7012 | AB9: 6945 | AC9: 13706 | AD9: 1303 | AE9: -1973
S10: Loans Advances | T10: 0 | U10: -520 | V10: 0 | W10: 0 | X10: 0 | Y10: 0 | Z10: 0 | AA10: 0 | AB10: 0 | AC10: 0 | AD10: 0 | AE10: -815
S11: Other WC items | T11: -398 | U11: 5852 | V11: 4727 | W11: 494 | X11: 4512 | Y11: 875 | Z11: -4150 | AA11: -4396 | AB11: -2194 | AC11: 2760 | AD11: 1153 | AE11: -345
S12: Working capital changes | T12: -3672 | U12: 1313 | V12: 3254 | W12: -6434 | X12: -7221 | Y12: 5065 | Z12: -93 | AA12: -10750 | AB12: -3127 | AC12: 7325 | AD12: 8156 | AE12: -9038
S13: Direct taxes | T13: -4194 | U13: -2040 | V13: -1895 | W13: -3021 | X13: -2659 | Y13: -1785 | Z13: -2105 | AA13: -1910 | AB13: -3179 | AC13: -4516 | AD13: -3991 | AE13: -3314
S14: Cash from Investing Activity - | T14: -36232 | U14: -36694 | V14: -39571 | W14: -25139 | X14: -20878 | Y14: -33115 | Z14: -25672 | AA14: -4444 | AB14: -15417 | AC14: -22781 | AD14: -49982 | AE14: -24810
S15: Fixed assets purchased | T15: -31962 | U15: -31503 | V15: -16072 | W15: -35079 | X15: -35304 | Y15: -29702 | Z15: -20205 | AA15: -15168 | AB15: -19230 | AC15: -31414 | AD15: -38042 | AE15: -36282
S16: Fixed assets sold | T16: 74 | U16: 59 | V16: 53 | W16: 30 | X16: 67 | Y16: 171 | Z16: 351 | AA16: 230 | AB16: 285 | AC16: 231 | AD16: 974 | AE16: 46
... S19: Interest received | T19: 698 | U19: 731 | V19: 638 | W19: 690 | X19: 761 | Y19: 1104 | Z19: 428 | AA19: 653 | AB19: 973 | AC19: 2493 | AD19: 2420 | AE19: 1940
N20: 0 | S20: Dividends received | T20: 80 | U20: 58 | V20: 620 | W20: 1797 | X20: 232 | Y20: 21 | Z20: 18 | AA20: 32 | AB20: 46 | AC20: 47 | AD20: 64 | AE20: 199
N21: -512 | S21: Investment in group cos | T21: -160 | U21: 0 | V21: -107 | W21: -4 | X21: -9 | Y21: -606 | Z21: -10 | AA21: 0 | AB21: 0 | AC21: -150 | AD21: 0 | AE21: -5
N22: -83 | S22: Redemp n Canc of Shares | T22: 0 | U22: 0 | V22: 0 | W22: 14 | X22: 533 | Y22: 0 | Z22: 0 | AA22: 0 | AB22: 19 | AC22: 107 | AD22: 765 | AE22: 0
N23: -715 | S23: Acquisition of companies | T23: 0 | U23: -111 | V23: 0 | W23: 0 | X23: -8 | Y23: -27 | Z23: 0 | AA23: -98 | AB23: 0 | AC23: 0 | AD23: -688 | AE23: -512
N24: -1344 | S24: Inter corporate deposits | T24: 0 | U24: 0 | V24: 0 | W24: 0 | X24: 0 | Y24: 0 | Z24: 0 | AA24: 0 | AB24: 0 | AC24: -25 | AD24: -20 | AE24: -83
N25: 18 | S25: Other investing items | T25: 456 | U25: -1289 | V25: -26663 | W25: 5360 | X25: 7335 | Y25: -2659 | Z25: 1051 | AA25: 12813 | AB25: -4357 | AC25: -4817 | AD25: -2889 | AE25: -715
N26: 0 | S26: Cash from Financing Activity - | T26: 5201 | U26: -3795 | V26: 6205 | W26: 2012 | X26: 8830 | Y26: 3390 | Z26: 9904 | AA26: -3380 | AB26: -26243 | AC26: -37006 | AD26: -18786 | AE26: -1344
N27: 26425 | S27: Proceeds from shares | T27: 0 | U27: 7433 | V27: 5 | W27: 0 | X27: 0 | Y27: 3889 | Z27: 2603 | AA27: 19 | AB27: 20 | AC27: 82 | AD27: 1108 | AE27: 18
N28: -18110 | S28: Redemption of debentures | T28: -744 | U28: 0 | V28: 0 | W28: 0 | X28: 0 | Y28: 0 | Z28: 0 | AA28: 0 | AB28: 0 | AC28: 0 | AD28: 0 | AE28: 0
N29: -5111 | S29: Proceeds from borrowings | T29: 36363 | U29: 19519 | V29: 33390 | W29: 37482 | X29: 51128 | Y29: 38297 | Z29: 46641 | AA29: 46578 | AB29: 43934 | AC29: 18829 | AD29: 13384 | AE29: 26425
N30: -2203 | S30: Repayment of borrowings | T30: -23332 | U30: -24924 | V30: -21732 | W30: -29964 | X30: -35198 | Y30: -29847 | Z30: -29709 | AA30: -42816 | AB30: -62557 | AC30: -47414 | AD30: -21443 | AE30: -18110
N31: -2145 | S31: Interest paid fin | T31: -6307 | U31: -5716 | V31: -5336 | W31: -5411 | X31: -7005 | Y31: -7518 | Z31: -8123 | AA31: -9251 | AB31: -9336 | AC31: -9332 | AD31: -5814 | AE31: -5111
... N35: 0.87 | S35: Net Cash Flow | T35: 4500 | U35: -2589 | V35: -3167 | W35: 730 | X35: 6843 | Y35: -3092 | Z35: 13232 | AA35: 6459 | AB35: -6272 | AC35: 8128 | AD35: -5666 | AE35: -13113
S36: Free Cash Flow | T36: 3643 | U36: 6455 | V36: 14181 | W36: -11191 | X36: -16346 | Y36: -2898 | Z36: 9146 | AA36: -655 | AB36: 16443 | AC36: 36732 | AD36: 26034 | AE36: -23195
S37: CFO/OP | T37: 1.01 | U37: 1.04 | V37: 1.08 | W37: 0.85 | X37: 0.87 | Y37: 1.58 | Z37: 0.96 | AA37: 0.66 | AB37: 1.21 | AC37: 1.25 | AD37: 1.2 | AE37: 0.87

Sheet Data Sheet
A1: COMPANY NAME | B1: CASTROL INDIA LTD | E1: =IF(B2<>B3, "A NEW VERSION OF THE WORKSHEET IS AVAILABLE", "")
A2: LATEST VERSION | B2: 2.1 | E2: PLEASE DO NOT MAKE ANY CHANGES TO THIS SHEET
A3: CURRENT VERSION | B3: 2.1
A5: META
A6: Number of shares | B6: =IF(B9>0, B9/B8, 0) -> 98.912224
A7: Face Value | B7: 5
A8: Current Price | B8: 192.08
A9: Market Capitalization | B9: 18999.06
A15: PROFIT & LOSS
A16: Report Date | B16: 42735 | C16: 43100 | D16: 43465 | E16: 43830 | F16: 44196 | G16: 44561 | H16: 44926 | I16: 45291 | J16: 45657 | K16: 46022
A17: Sales | B17: 3370.33 | C17: 3584.32 | D17: 3904.55 | E17: 3876.82 | F17: 2996.92 | G17: 4192.06 | H17: 4774.49 | I17: 5074.61 | J17: 5364.85 | K17: 5721.5
A18: Raw Material Cost | B18: 1546.57 | C18: 1671.33 | D18: 1971.11 | E18: 1671.92 | F18: 1290.47 | G18: 2070.93 | H18: 2528.27 | I18: 2647.79 | J18: 2742.17 | K18: 2909.67
A19: Change in Inventory | B19: 14.98 | C19: 5.43 | D19: 64.55 | E19: -75.73 | F19: 24.13 | G19: 12.11 | H19: 28.35 | I19: 11.38 | J19: 14.34 | K19: -9.74
A20: Power and Fuel | B20: 4.6 | C20: 5.26 | D20: 5.96 | E20: 6.39 | F20: 5.11 | G20: 5.7 | H20: 6.21 | I20: 6.42 | J20: 7.15 | K20: 6.82
A21: Other Mfr. Exp | B21: 175.26 | C21: 186.81 | D21: 217.88 | E21: 221.81 | F21: 193.16 | G21: 225.13 | H21: 235.99 | I21: 246.29 | J21: 267.03 | K21: 293.97
A22: Employee Cost | B22: 178.42 | C22: 196.35 | D22: 204.23 | E22: 214.03 | F22: 220.84 | G22: 233.01 | H22: 273.57 | I22: 292.64 | J22: 313.87 | K22: 297.4
A23: Selling and admin | B23: 440.26 | C23: 437.82 | D23: 455.47 | E23: 482.82 | F23: 453.08 | G23: 561.89 | H23: 602.85 | I23: 653.01 | J23: 725.5 | K23: 813.08
A24: Other Expenses | B24: 39.2 | C24: 59.06 | D24: 43.68 | E24: 50.42 | F24: 44.13 | G24: 40.61 | H24: 44.53 | I24: 41.93 | J24: 45.07 | K24: 43.3
A25: Other Income | B25: 85.74 | C25: 83.65 | D25: 84.31 | E25: 64.14 | F25: 61.88 | G25: 47.49 | H25: 66.73 | I25: 83.15 | J25: 88.36 | K25: 44.9
A26: Depreciation | B26: 44.96 | C26: 45.5 | D26: 55.57 | E26: 69.74 | F26: 86.62 | G26: 82.7 | H26: 81.39 | I26: 92.43 | J26: 99.77 | K26: 100.82
A27: Interest | B27: 1.48 | C27: 1.2 | D27: 1.09 | E27: 1.19 | F27: 4.16 | G27: 2.41 | H27: 4.01 | I27: 7.53 | J27: 9.38 | K27: 9.29
... A31: Dividend Amount | B31: 544.02 | C31: 692.38 | D31: 494.56 | E31: 544.02 | F31: 544.02 | G31: 544.02 | H31: 642.93 | I31: 741.84 | J31: 1384.77 | K31: 865.48
A40: Quarters
A41: Report Date | B41: 45382 | C41: 45473 | D41: 45565 | E41: 45657 | F41: 45747 | G41: 45838 | H41: 45930 | I41: 46022 | J41: 46112 | K41: 46203
A42: Sales | B42: 1325.24 | C42: 1397.54 | D42: 1288.18 | E42: 1353.89 | F42: 1422 | G42: 1496.83 | H42: 1362.75 | I42: 1439.92 | J42: 1545.24 | K42: 1871.47
A43: Expenses | B43: 1031.5 | C43: 1075.1 | D43: 1002.07 | E43: 978.03 | F43: 1114.64 | G43: 1147.31 | H43: 1039.95 | I43: 1072.08 | J43: 1215.93 | K43: 1377.29
A44: Other Income | B44: 24.14 | C44: 20.4 | D44: 20.9 | E44: 23.17 | F44: 32.24 | G44: 9.26 | H44: 12.3 | I44: -8.9 | J44: 23.34 | K44: 14
A45: Depreciation | B45: 23.71 | C45: 26.12 | D45: 24.52 | E45: 25.42 | F45: 24.55 | G45: 26.62 | H45: 25.17 | I45: 24.48 | J45: 27.67 | K45: 30.45
A46: Interest | B46: 2.12 | C46: 2.55 | D46: 2.03 | E46: 2.68 | F46: 2.33 | G46: 2.62 | H46: 2.06 | I46: 2.28 | J46: 1.87 | K46: 1.7
A47: Profit before tax | B47: 292.05 | C47: 314.17 | D47: 280.46 | E47: 370.93 | F47: 312.72 | G47: 329.54 | H47: 307.87 | I47: 332.18 | J47: 323.11 | K47: 476.03
A48: Tax | B48: 75.81 | C48: 82 | D48: 73.03 | E48: 99.54 | F48: 79.26 | G48: 85.54 | H48: 80.07 | I48: 87.51 | J48: 80.93 | K48: 128.33
A49: Net profit | B49: 216.24 | C49: 232.17 | D49: 207.43 | E49: 271.39 | F49: 233.46 | G49: 244 | H49: 227.8 | I49: 244.67 | J49: 242.18 | K49: 347.7
A50: Operating Profit | B50: 293.74 | C50: 322.44 | D50: 286.11 | E50: 375.86 | F50: 307.36 | G50: 349.52 | H50: 322.8 | I50: 367.84 | J50: 329.31 | K50: 494.18
A55: BALANCE SHEET
A56: Report Date | B56: 42735 | C56: 43100 | D56: 43465 | E56: 43830 | F56: 44196 | G56: 44561 | H56: 44926 | I56: 45291 | J56: 45657 | K56: 46022
A57: Equity Share Capital | B57: 247.28 | C57: 494.56 | D57: 494.56 | E57: 494.56 | F57: 494.56 | G57: 494.56 | H57: 494.56 | I57: 494.56 | J57: 494.56 | K57: 494.56
A58: Reserves | B58: 734.26 | C58: 525.59 | D58: 671.1 | E58: 872.39 | F58: 919.67 | G58: 1150.95 | H58: 1391.47 | I58: 1627.13 | J58: 1783.81 | K58: 1405.74
A59: Borrowings | G59: 6.72 | H59: 49.95 | I59: 76.95 | J59: 82.02 | K59: 62.81
A60: Other Liabilities | B60: 906.79 | C60: 956.8 | D60: 941.11 | E60: 861.83 | F60: 979.27 | G60: 1051.79 | H60: 1133.03 | I60: 1221.29 | J60: 1274.9 | K60: 1431.74
A61: Total | B61: 1888.33 | C61: 1976.95 | D61: 2106.77 | E61: 2228.78 | F61: 2393.5 | G61: 2704.02 | H61: 3069.01 | I61: 3419.93 | J61: 3635.29 | K61: 3394.85
...

Sheet Profit & Loss
A1: ='Data Sheet'!B1 -> CASTROL INDIA LTD | H1: =UPDATE | M1: SCREENER.IN
A3: Narration | B3: ='Data Sheet'!B16 -> 42735 | C3: ='Data Sheet'!C16 -> 43100 | D3: ='Data Sheet'!D16 -> 43465 | E3: ='Data Sheet'!E16 -> 43830 | F3: ='Data Sheet'!F16 -> 44196 | G3: ='Data Sheet'!G16 -> 44561 | H3: ='Data Sheet'!H16 -> 44926 | I3: ='Data Sheet'!I16 -> 45291 | ... K3: ='Data Sheet'!K16 -> 46022 | L3: Trailing | M3: Best Case | N3: Worst Case
A4: Sales | B4: ='Data Sheet'!B17 -> 3370.33 | C4: ='Data Sheet'!C17 -> 3584.32 | D4: ='Data Sheet'!D17 -> 3904.55 | E4: ='Data Sheet'!E17 -> 3876.82 | F4: ='Data Sheet'!F17 -> 2996.92 | G4: ='Data Sheet'!G17 -> 4192.06 | H4: ='Data Sheet'!H17 -> 4774.49 | I4: ='Data Sheet'!I17 -> 5074.61 | ... K4: ='Data Sheet'!K17 -> 5721.5 | L4: =SUM(Quarters!H4:K4) -> 6219.38 | M4: =$K4+M23*K4 -> 6219.38 | N4: =$K4+N23*L4 -> 6070.415
A5: Expenses | B5: =SUM('Data Sheet'!B18,'Data Sheet'!B20:B24, -1*'Data Sheet'!B19) -> 2369.33 | C5: =SUM('Data Sheet'!C18,'Data Sheet'!C20:C24, -1*'Data Sheet'!C19) -> 2551.2 | D5: =SUM('Data Sheet'!D18,'Data Sheet'!D20:D24, -1*'Data Sheet'!D19) -> 2833.78 | E5: =SUM('Data Sheet'!E18,'Data Sheet'!E20:E24, -1*'Data Sheet'!E19) -> 2723.12 | F5: =SUM('Data Sheet'!F18,'Data Sheet'!F20:F24, -1*'Data Sheet'!F19) -> 2182.66 | G5: =SUM('Data Sheet'!G18,'Data Sheet'!G20:G24, -1*'Data Sheet'!G19) -> 3125.16 | H5: =SUM('Data Sheet'!H18,'Data Sheet'!H20:H24, -1*'Data Sheet'!H19) -> 3663.07 | I5: =SUM('Data Sheet'!I18,'Data Sheet'!I20:I24, -1*'Data Sheet'!I19) -> 3876.7 | ... K5: =SUM('Data Sheet'!K18,'Data Sheet'!K20:K24, -1*'Data Sheet'!K19) -> 4373.98 | L5: =SUM(Quarters!H5:K5) -> 4705.25 | M5: =M4-M6 -> 4705.25 | N5: =N4-N6 -> 4634.0997
A6: Operating Profit | B6: =B4-B5 -> 1001 | C6: =C4-C5 -> 1033.12 | D6: =D4-D5 -> 1070.77 | E6: =E4-E5 -> 1153.7 | F6: =F4-F5 -> 814.26 | G6: =G4-G5 -> 1066.9 | H6: =H4-H5 -> 1111.42 | I6: =I4-I5 -> 1197.91 | ... K6: =K4-K5 -> 1347.52 | L6: =SUM(Quarters!H6:K6) -> 1514.13 | M6: =M4*M24 -> 1514.13 | N6: =N4*N24 -> 1436.3154
A7: Other Income | B7: ='Data Sheet'!B25 -> 85.74 | C7: ='Data Sheet'!C25 -> 83.65 | D7: ='Data Sheet'!D25 -> 84.31 | E7: ='Data Sheet'!E25 -> 64.14 | F7: ='Data Sheet'!F25 -> 61.88 | G7: ='Data Sheet'!G25 -> 47.49 | H7: ='Data Sheet'!H25 -> 66.73 | I7: ='Data Sheet'!I25 -> 83.15 | ... K7: ='Data Sheet'!K25 -> 44.9 | L7: =SUM(Quarters!H7:K7) -> 40.74 | M7: 0 | N7: 0
A8: Depreciation | B8: ='Data Sheet'!B26 -> 44.96 | C8: ='Data Sheet'!C26 -> 45.5 | D8: ='Data Sheet'!D26 -> 55.57 | E8: ='Data Sheet'!E26 -> 69.74 | F8: ='Data Sheet'!F26 -> 86.62 | G8: ='Data Sheet'!G26 -> 82.7 | H8: ='Data Sheet'!H26 -> 81.39 | I8: ='Data Sheet'!I26 -> 92.43 | ... K8: ='Data Sheet'!K26 -> 100.82 | L8: =SUM(Quarters!H8:K8) -> 107.77 | M8: =+$L8 -> 107.77 | N8: =+$L8 -> 107.77
A9: Interest | B9: ='Data Sheet'!B27 -> 1.48 | C9: ='Data Sheet'!C27 -> 1.2 | D9: ='Data Sheet'!D27 -> 1.09 | E9: ='Data Sheet'!E27 -> 1.19 | F9: ='Data Sheet'!F27 -> 4.16 | G9: ='Data Sheet'!G27 -> 2.41 | H9: ='Data Sheet'!H27 -> 4.01 | I9: ='Data Sheet'!I27 -> 7.53 | ... K9: ='Data Sheet'!K27 -> 9.29 | L9: =SUM(Quarters!H9:K9) -> 7.91 | M9: =+$L9 -> 7.91 | N9: =+$L9 -> 7.91
A10: Profit before tax | B10: ='Data Sheet'!B28 -> 1040.3 | C10: ='Data Sheet'!C28 -> 1070.07 | D10: ='Data Sheet'!D28 -> 1098.42 | E10: ='Data Sheet'!E28 -> 1146.91 | F10: ='Data Sheet'!F28 -> 785.36 | G10: ='Data Sheet'!G28 -> 1029.28 | H10: ='Data Sheet'!H28 -> 1092.75 | I10: ='Data Sheet'!I28 -> 1181.1 | ... K10: ='Data Sheet'!K28 -> 1282.31 | L10: =SUM(Quarters!H10:K10) -> 1439.19 | M10: =M6+M7-SUM(M8:M9) -> 1398.45 | N10: =N6+N7-SUM(N8:N9) -> 1320.6354
A11: Tax | B11: ='Data Sheet'!B29 -> 369.92 | C11: ='Data Sheet'!C29 -> 378.26 | D11: ='Data Sheet'!D29 -> 390.06 | E11: ='Data Sheet'!E29 -> 319.54 | F11: ='Data Sheet'!F29 -> 202.42 | G11: ='Data Sheet'!G29 -> 271.19 | H11: ='Data Sheet'!H29 -> 277.6 | I11: ='Data Sheet'!I29 -> 316.97 | ... K11: ='Data Sheet'!K29 -> 332.38 | L11: =SUM(Quarters!H11:K11) -> 376.84 | M11: =IF($L10>0,$L11/$L10,0) -> 0.26184173 | N11: =IF($L10>0,$L11/$L10,0) -> 0.26184173
A12: Net profit | B12: ='Data Sheet'!B30 -> 670.38 | C12: ='Data Sheet'!C30 -> 691.81 | D12: ='Data Sheet'!D30 -> 708.36 | E12: ='Data Sheet'!E30 -> 827.37 | F12: ='Data Sheet'!F30 -> 582.94 | G12: ='Data Sheet'!G30 -> 758.09 | H12: ='Data Sheet'!H30 -> 815.15 | I12: ='Data Sheet'!I30 -> 864.13 | ... K12: ='Data Sheet'!K30 -> 949.93 | L12: =SUM(Quarters!H12:K12) -> 1062.35 | M12: =M10-M11*M10 -> 1032.2774 | N12: =N10-N11*N10 -> 974.83791
A13: EPS | B13: =IF('Data Sheet'!B93>0,B12/'Data Sheet'!B93,0) -> 6.7776767 | C13: =IF('Data Sheet'!C93>0,C12/'Data Sheet'!C93,0) -> 6.9943383 | D13: =IF('Data Sheet'!D93>0,D12/'Data Sheet'!D93,0) -> 7.1616621 | E13: =IF('Data Sheet'!E93>0,E12/'Data Sheet'!E93,0) -> 8.3648772 | F13: =IF('Data Sheet'!F93>0,F12/'Data Sheet'!F93,0) -> 5.8936407 | G13: =IF('Data Sheet'!G93>0,G12/'Data Sheet'!G93,0) -> 7.6644424 | H13: =IF('Data Sheet'!H93>0,H12/'Data Sheet'!H93,0) -> 8.2413305 | I13: =IF('Data Sheet'!I93>0,I12/'Data Sheet'!I93,0) -> 8.7365282 | ... K13: =IF('Data Sheet'!K93>0,K12/'Data Sheet'!K93,0) -> 9.6039834 | L13: =IF('Data Sheet'!$B6>0,'Profit & Loss'!L12/'Data Sheet'!$B6,0) -> 10.740331 | M13: =IF('Data Sheet'!$B6>0,'Profit & Loss'!M12/'Data Sheet'!$B6,0) -> 10.436298 | N13: =IF('Data Sheet'!$B6>0,'Profit & Loss'!N12/'Data Sheet'!$B6,0) -> 9.8555858
A14: Price to earning | B14: =IF(B15>0,B15/B13,"") -> 28.081894 | C14: =IF(C15>0,C15/C13,"") -> 27.622341 | D14: =IF(D15>0,D15/D13,"") -> 21.119399 | E14: =IF(E15>0,E15/E13,"") -> 15.457489 | F14: =IF(F15>0,F15/F13,"") -> 20.878436 | G14: =IF(G15>0,G15/G13,"") -> 16.02204 | H14: =IF(H15>0,H15/H13,"") -> 14.942976 | I14: =IF(I15>0,I15/I13,"") -> 20.574535 | ... K14: =IF(K15>0,K15/K13,"") -> 20.048973 | L14: =IF(L13>0,L15/L13,0) -> 17.883993 | M14: =M25 -> 19.891699 | N14: =N25 -> 17.883993
A15: Price | B15: ='Data Sheet'!B90 -> 190.33 | C15: ='Data Sheet'!C90 -> 193.2 | D15: ='Data Sheet'!D90 -> 151.25 | E15: ='Data Sheet'!E90 -> 129.3 | F15: ='Data Sheet'!F90 -> 123.05 | G15: ='Data Sheet'!G90 -> 122.8 | H15: ='Data Sheet'!H90 -> 123.15 | I15: ='Data Sheet'!I90 -> 179.75 | ... K15: ='Data Sheet'!K90 -> 192.55 | L15: ='Data Sheet'!B8 -> 192.08 | M15: =M13*M14 -> 207.5957 | N15: =N13*N14 -> 176.25723
A17: RATIOS:
A18: Dividend Payout | B18: =IF('Data Sheet'!B30>0, 'Data Sheet'!B31/'Data Sheet'!B30, 0) -> 0.81150989 | C18: =IF('Data Sheet'!C30>0, 'Data Sheet'!C31/'Data Sheet'!C30, 0) -> 1.0008239 | D18: =IF('Data Sheet'!D30>0, 'Data Sheet'!D31/'Data Sheet'!D30, 0) -> 0.69817607 | E18: =IF('Data Sheet'!E30>0, 'Data Sheet'!E31/'Data Sheet'!E30, 0) -> 0.65752928 | F18: =IF('Data Sheet'!F30>0, 'Data Sheet'!F31/'Data Sheet'!F30, 0) -> 0.93323498 | G18: =IF('Data Sheet'!G30>0, 'Data Sheet'!G31/'Data Sheet'!G30, 0) -> 0.71761928 | H18: =IF('Data Sheet'!H30>0, 'Data Sheet'!H31/'Data Sheet'!H30, 0) -> 0.788726 | I18: =IF('Data Sheet'!I30>0, 'Data Sheet'!I31/'Data Sheet'!I30, 0) -> 0.85848194 | ... K18: =IF('Data Sheet'!K30>0, 'Data Sheet'!K31/'Data Sheet'!K30, 0) -> 0.91109871
A19: OPM | B19: =IF(B6>0,B6/B4,0) -> 0.29700356 | C19: =IF(C6>0,C6/C4,0) -> 0.28823319 | D19: =IF(D6>0,D6/D4,0) -> 0.27423647 | E19: =IF(E6>0,E6/E4,0) -> 0.29758926 | F19: =IF(F6>0,F6/F4,0) -> 0.27169894 | G19: =IF(G6>0,G6/G4,0) -> 0.25450495 | H19: =IF(H6>0,H6/H4,0) -> 0.23278298 | I19: =IF(I6>0,I6/I4,0) -> 0.23605952 | ... L19: =IF(L6>0,L6/L4,0) -> 0.24345353
G22: TRENDS: | H22: 10 YEARS | I22: 7 YEARS | J22: 5 YEARS | K22: 3 YEARS | L22: RECENT | M22: BEST | N22: WORST
G23: Sales Growth | H23: =IF(B4=0,"",POWER($K4/B4,1/9)-1) -> 0.060565505 | I23: =IF(D4=0,"",POWER($K4/D4,1/7)-1) -> 0.056101256 | J23: =IF(F4=0,"",POWER($K4/F4,1/5)-1) -> 0.13806469 | K23: =IF(H4=0,"",POWER($K4/H4, 1/3)-1) -> 0.062170669 | L23: =IF(ISERROR(MAX(IF(J4=0,"",(K4-J4)/J4),IF(K4=0,"",(L4-K4)/K4))),"",MAX(IF(J4=0,"",(K4-J4)/J4),IF(K4=0,"",(L4-K4)/K4))) -> 0.087019138 | M23: =MAX(K23:L23) -> 0.087019138 | N23: =MIN(H23:L23) -> 0.056101256
G24: OPM | H24: =IF(SUM(B4:$K$4)=0,"",SUMPRODUCT(B19:$K$19,B4:$K$4)/SUM(B4:$K$4)) -> 0.25839673 | I24: =IF(SUM(E4:$K$4)=0,"",SUMPRODUCT(E19:$K$19,E4:$K$4)/SUM(E4:$K$4)) -> 0.24905621 | J24: =IF(SUM(G4:$K$4)=0,"",SUMPRODUCT(G19:$K$19,G4:$K$4)/SUM(G4:$K$4)) -> 0.23886768 | K24: =IF(SUM(I4:$K$4)=0, "", SUMPRODUCT(I19:$K$19,I4:$K$4)/SUM(I4:$K$4)) -> 0.23660909 | L24: =L19 -> 0.24345353 | M24: =MAX(K24:L24) -> 0.24345353 | N24: =MIN(H24:L24) -> 0.23660909
G25: Price to Earning | H25: =IF(ISERROR(AVERAGEIF(B14:$L14,">0")),"",AVERAGEIF(B14:$L14,">0")) -> 20.335579 | I25: =IF(ISERROR(AVERAGEIF(E14:$L14,">0")),"",AVERAGEIF(E14:$L14,">0")) -> 18.358467 | J25: =IF(ISERROR(AVERAGEIF(G14:$L14,">0")),"",AVERAGEIF(G14:$L14,">0")) -> 18.421969 | K25: =IF(ISERROR(AVERAGEIF(I14:$L14,">0")),"",AVERAGEIF(I14:$L14,">0")) -> 19.891699 | L25: =L14 -> 17.883993 | M25: =MAX(K25:L25) -> 19.891699 | N25: =MIN(H25:L25) -> 17.883993

Sheet Quarters
A1: ='Profit & Loss'!A1 -> CASTROL INDIA LTD | E1: =UPDATE | J1: SCREENER.IN
A3: Narration | B3: ='Data Sheet'!B41 -> 45382 | C3: ='Data Sheet'!C41 -> 45473 | D3: ='Data Sheet'!D41 -> 45565 | E3: ='Data Sheet'!E41 -> 45657 | F3: ='Data Sheet'!F41 -> 45747 | G3: ='Data Sheet'!G41 -> 45838 | H3: ='Data Sheet'!H41 -> 45930 | I3: ='Data Sheet'!I41 -> 46022 | ... K3: ='Data Sheet'!K41 -> 46203
A4: Sales | B4: ='Data Sheet'!B42 -> 1325.24 | C4: ='Data Sheet'!C42 -> 1397.54 | D4: ='Data Sheet'!D42 -> 1288.18 | E4: ='Data Sheet'!E42 -> 1353.89 | F4: ='Data Sheet'!F42 -> 1422 | G4: ='Data Sheet'!G42 -> 1496.83 | H4: ='Data Sheet'!H42 -> 1362.75 | I4: ='Data Sheet'!I42 -> 1439.92 | ... K4: ='Data Sheet'!K42 -> 1871.47
A5: Expenses | B5: ='Data Sheet'!B43 -> 1031.5 | C5: ='Data Sheet'!C43 -> 1075.1 | D5: ='Data Sheet'!D43 -> 1002.07 | E5: ='Data Sheet'!E43 -> 978.03 | F5: ='Data Sheet'!F43 -> 1114.64 | G5: ='Data Sheet'!G43 -> 1147.31 | H5: ='Data Sheet'!H43 -> 1039.95 | I5: ='Data Sheet'!I43 -> 1072.08 | ... K5: ='Data Sheet'!K43 -> 1377.29
A6: Operating Profit | B6: ='Data Sheet'!B50 -> 293.74 | C6: ='Data Sheet'!C50 -> 322.44 | D6: ='Data Sheet'!D50 -> 286.11 | E6: ='Data Sheet'!E50 -> 375.86 | F6: ='Data Sheet'!F50 -> 307.36 | G6: ='Data Sheet'!G50 -> 349.52 | H6: ='Data Sheet'!H50 -> 322.8 | I6: ='Data Sheet'!I50 -> 367.84 | ... K6: ='Data Sheet'!K50 -> 494.18
A7: Other Income | B7: ='Data Sheet'!B44 -> 24.14 | C7: ='Data Sheet'!C44 -> 20.4 | D7: ='Data Sheet'!D44 -> 20.9 | E7: ='Data Sheet'!E44 -> 23.17 | F7: ='Data Sheet'!F44 -> 32.24 | G7: ='Data Sheet'!G44 -> 9.26 | H7: ='Data Sheet'!H44 -> 12.3 | I7: ='Data Sheet'!I44 -> -8.9 | ... K7: ='Data Sheet'!K44 -> 14
A8: Depreciation | B8: ='Data Sheet'!B45 -> 23.71 | C8: ='Data Sheet'!C45 -> 26.12 | D8: ='Data Sheet'!D45 -> 24.52 | E8: ='Data Sheet'!E45 -> 25.42 | F8: ='Data Sheet'!F45 -> 24.55 | G8: ='Data Sheet'!G45 -> 26.62 | H8: ='Data Sheet'!H45 -> 25.17 | I8: ='Data Sheet'!I45 -> 24.48 | ... K8: ='Data Sheet'!K45 -> 30.45
A9: Interest | B9: ='Data Sheet'!B46 -> 2.12 | C9: ='Data Sheet'!C46 -> 2.55 | D9: ='Data Sheet'!D46 -> 2.03 | E9: ='Data Sheet'!E46 -> 2.68 | F9: ='Data Sheet'!F46 -> 2.33 | G9: ='Data Sheet'!G46 -> 2.62 | H9: ='Data Sheet'!H46 -> 2.06 | I9: ='Data Sheet'!I46 -> 2.28 | ... K9: ='Data Sheet'!K46 -> 1.7
A10: Profit before tax | B10: ='Data Sheet'!B47 -> 292.05 | C10: ='Data Sheet'!C47 -> 314.17 | D10: ='Data Sheet'!D47 -> 280.46 | E10: ='Data Sheet'!E47 -> 370.93 | F10: ='Data Sheet'!F47 -> 312.72 | G10: ='Data Sheet'!G47 -> 329.54 | H10: ='Data Sheet'!H47 -> 307.87 | I10: ='Data Sheet'!I47 -> 332.18 | ... K10: ='Data Sheet'!K47 -> 476.03
A11: Tax | B11: ='Data Sheet'!B48 -> 75.81 | C11: ='Data Sheet'!C48 -> 82 | D11: ='Data Sheet'!D48 -> 73.03 | E11: ='Data Sheet'!E48 -> 99.54 | F11: ='Data Sheet'!F48 -> 79.26 | G11: ='Data Sheet'!G48 -> 85.54 | H11: ='Data Sheet'!H48 -> 80.07 | I11: ='Data Sheet'!I48 -> 87.51 | ... K11: ='Data Sheet'!K48 -> 128.33
A12: Net profit | B12: ='Data Sheet'!B49 -> 216.24 | C12: ='Data Sheet'!C49 -> 232.17 | D12: ='Data Sheet'!D49 -> 207.43 | E12: ='Data Sheet'!E49 -> 271.39 | F12: ='Data Sheet'!F49 -> 233.46 | G12: ='Data Sheet'!G49 -> 244 | H12: ='Data Sheet'!H49 -> 227.8 | I12: ='Data Sheet'!I49 -> 244.67 | ... K12: ='Data Sheet'!K49 -> 347.7
A14: OPM | B14: =IF(B4>0,B6/B4,"") -> 0.22165042 | C14: =IF(C4>0,C6/C4,"") -> 0.23071969 | D14: =IF(D4>0,D6/D4,"") -> 0.22210405 | E14: =IF(E4>0,E6/E4,"") -> 0.27761487 | F14: =IF(F4>0,F6/F4,"") -> 0.21614627 | G14: =IF(G4>0,G6/G4,"") -> 0.23350681 | H14: =IF(H4>0,H6/H4,"") -> 0.23687397 | I14: =IF(I4>0,I6/I4,"") -> 0.25545864 | ... K14: =IF(K4>0,K6/K4,"") -> 0.2640598

Sheet Balance Sheet
A1: ='Profit & Loss'!A1 -> CASTROL INDIA LTD | E1: =UPDATE | J1: SCREENER.IN
A3: Narration | B3: ='Data Sheet'!B56 -> 42735 | C3: ='Data Sheet'!C56 -> 43100 | D3: ='Data Sheet'!D56 -> 43465 | E3: ='Data Sheet'!E56 -> 43830 | F3: ='Data Sheet'!F56 -> 44196 | G3: ='Data Sheet'!G56 -> 44561 | H3: ='Data Sheet'!H56 -> 44926 | I3: ='Data Sheet'!I56 -> 45291 | ... K3: ='Data Sheet'!K56 -> 46022
A4: Equity Share Capital | B4: ='Data Sheet'!B57 -> 247.28 | C4: ='Data Sheet'!C57 -> 494.56 | D4: ='Data Sheet'!D57 -> 494.56 | E4: ='Data Sheet'!E57 -> 494.56 | F4: ='Data Sheet'!F57 -> 494.56 | G4: ='Data Sheet'!G57 -> 494.56 | H4: ='Data Sheet'!H57 -> 494.56 | I4: ='Data Sheet'!I57 -> 494.56 | ... K4: ='Data Sheet'!K57 -> 494.56
A5: Reserves | B5: ='Data Sheet'!B58 -> 734.26 | C5: ='Data Sheet'!C58 -> 525.59 | D5: ='Data Sheet'!D58 -> 671.1 | E5: ='Data Sheet'!E58 -> 872.39 | F5: ='Data Sheet'!F58 -> 919.67 | G5: ='Data Sheet'!G58 -> 1150.95 | H5: ='Data Sheet'!H58 -> 1391.47 | I5: ='Data Sheet'!I58 -> 1627.13 | ... K5: ='Data Sheet'!K58 -> 1405.74
A6: Borrowings | B6: ='Data Sheet'!B59 -> 0 | C6: ='Data Sheet'!C59 -> 0 | D6: ='Data Sheet'!D59 -> 0 | E6: ='Data Sheet'!E59 -> 0 | F6: ='Data Sheet'!F59 -> 0 | G6: ='Data Sheet'!G59 -> 6.72 | H6: ='Data Sheet'!H59 -> 49.95 | I6: ='Data Sheet'!I59 -> 76.95 | ... K6: ='Data Sheet'!K59 -> 62.81
A7: Other Liabilities | B7: ='Data Sheet'!B60 -> 906.79 | C7: ='Data Sheet'!C60 -> 956.8 | D7: ='Data Sheet'!D60 -> 941.11 | E7: ='Data Sheet'!E60 -> 861.83 | F7: ='Data Sheet'!F60 -> 979.27 | G7: ='Data Sheet'!G60 -> 1051.79 | H7: ='Data Sheet'!H60 -> 1133.03 | I7: ='Data Sheet'!I60 -> 1221.29 | ... K7: ='Data Sheet'!K60 -> 1431.74
A8: Total | B8: ='Data Sheet'!B61 -> 1888.33 | C8: ='Data Sheet'!C61 -> 1976.95 | D8: ='Data Sheet'!D61 -> 2106.77 | E8: ='Data Sheet'!E61 -> 2228.78 | F8: ='Data Sheet'!F61 -> 2393.5 | G8: ='Data Sheet'!G61 -> 2704.02 | H8: ='Data Sheet'!H61 -> 3069.01 | I8: ='Data Sheet'!I61 -> 3419.93 | ... K8: ='Data Sheet'!K61 -> 3394.85
A10: Net Block | B10: ='Data Sheet'!B62 -> 146.97 | C10: ='Data Sheet'!C62 -> 138.97 | D10: ='Data Sheet'!D62 -> 186.04 | E10: ='Data Sheet'!E62 -> 199.7 | F10: ='Data Sheet'!F62 -> 209.21 | G10: ='Data Sheet'!G62 -> 201.18 | H10: ='Data Sheet'!H62 -> 260.79 | I10: ='Data Sheet'!I62 -> 258.85 | ... K10: ='Data Sheet'!K62 -> 333.6
A11: Capital Work in Progress | B11: ='Data Sheet'!B63 -> 37.26 | C11: ='Data Sheet'!C63 -> 57.27 | D11: ='Data Sheet'!D63 -> 35.04 | E11: ='Data Sheet'!E63 -> 27.33 | F11: ='Data Sheet'!F63 -> 43.54 | G11: ='Data Sheet'!G63 -> 50.04 | H11: ='Data Sheet'!H63 -> 60.76 | I11: ='Data Sheet'!I63 -> 108.36 | ... K11: ='Data Sheet'!K63 -> 72.07
A12: Investments | B12: ='Data Sheet'!B64 -> 0 | C12: ='Data Sheet'!C64 -> 0 | D12: ='Data Sheet'!D64 -> 0 | E12: ='Data Sheet'!E64 -> 0 | F12: ='Data Sheet'!F64 -> 0 | G12: ='Data Sheet'!G64 -> 0 | H12: ='Data Sheet'!H64 -> 325 | I12: ='Data Sheet'!I64 -> 487.5 | ... K12: ='Data Sheet'!K64 -> 442.8
