Workbook
Name UPDATE: 'Data Sheet'!$E$1

Sheet FINANCIALS
B2: ="HISTORICAL FINANCIAL STATEMENT - "&'Data Sheet'!B1 -> HISTORICAL FINANCIAL STATEMENT - HINDUSTAN UNILEVER LTD
B3: YEARS | C3: ='Data Sheet'!B16 -> 42825 | D3: ='Data Sheet'!C16 -> 43190 | E3: ='Data Sheet'!D16 -> 43555 | F3: ='Data Sheet'!E16 -> 43921 | G3: ='Data Sheet'!F16 -> 44286 | H3: ='Data Sheet'!G16 -> 44651 | I3: ='Data Sheet'!H16 -> 45016 | J3: ='Data Sheet'!I16 -> 45382 | ... L3: ='Data Sheet'!K16 -> 46112 | M3: LTM
A4: # | B4: INCOME STATEMENT (IN CRORES)
B5: SALES | C5: =IFERROR('Data Sheet'!B17,0) -> 33162 | D5: =IFERROR('Data Sheet'!C17,0) -> 35545 | E5: =IFERROR('Data Sheet'!D17,0) -> 39310 | F5: =IFERROR('Data Sheet'!E17,0) -> 39783 | G5: =IFERROR('Data Sheet'!F17,0) -> 47028 | H5: =IFERROR('Data Sheet'!G17,0) -> 52446 | I5: =IFERROR('Data Sheet'!H17,0) -> 60580 | J5: =IFERROR('Data Sheet'!I17,0) -> 61896 | ... L5: =IFERROR('Data Sheet'!K17,0) -> 64468 | M5: =IFERROR(SUM('Data Sheet'!H42:K42),0) -> 65225
B6: SALES GROWTH | C6: - | D6: =D5/C5-1 -> 0.071859357 | E6: =E5/D5-1 -> 0.10592207 | F6: =F5/E5-1 -> 0.012032562 | G6: =G5/F5-1 -> 0.18211296 | H6: =H5/G5-1 -> 0.11520796 | I6: =I5/H5-1 -> 0.15509286 | J6: =J5/I5-1 -> 0.021723341 | K6: =K5/J5-1 -> -0.0091766835 | ... M6: =M5/L5-1 -> 0.01174226
B8: COGS | C8: =IFERROR(SUM('Data Sheet'!B18,'Data Sheet'!B20,'Data Sheet'!B21,'Data Sheet'!B22-1*'Data Sheet'!B19),0) -> 18675 | D8: =IFERROR(SUM('Data Sheet'!C18,'Data Sheet'!C20,'Data Sheet'!C21,'Data Sheet'!C22-1*'Data Sheet'!C19),0) -> 19314 | E8: =IFERROR(SUM('Data Sheet'!D18,'Data Sheet'!D20,'Data Sheet'!D21,'Data Sheet'!D22-1*'Data Sheet'!D19),0) -> 21081 | F8: =IFERROR(SUM('Data Sheet'!E18,'Data Sheet'!E20,'Data Sheet'!E21,'Data Sheet'!E22-1*'Data Sheet'!E19),0) -> 20614 | G8: =IFERROR(SUM('Data Sheet'!F18,'Data Sheet'!F20,'Data Sheet'!F21,'Data Sheet'!F22-1*'Data Sheet'!F19),0) -> 25301 | H8: =IFERROR(SUM('Data Sheet'!G18,'Data Sheet'!G20,'Data Sheet'!G21,'Data Sheet'!G22-1*'Data Sheet'!G19),0) -> 29066 | I8: =IFERROR(SUM('Data Sheet'!H18,'Data Sheet'!H20,'Data Sheet'!H21,'Data Sheet'!H22-1*'Data Sheet'!H19),0) -> 35381 | J8: =IFERROR(SUM('Data Sheet'!I18,'Data Sheet'!I20,'Data Sheet'!I21,'Data Sheet'!I22-1*'Data Sheet'!I19),0) -> 33651 | ... L8: =IFERROR(SUM('Data Sheet'!K18,'Data Sheet'!K20,'Data Sheet'!K21,'Data Sheet'!K22-1*'Data Sheet'!K19),0) -> 35634 | M8: =IFERROR(SUM('Data Sheet'!H43:K43),0) -> 50108
B9: COGS % SALES | C9: =C8/C5 -> 0.56314456 | D9: =D8/D5 -> 0.54336756 | E9: =E8/E5 -> 0.53627576 | F9: =F8/F5 -> 0.51816102 | G9: =G8/G5 -> 0.53799864 | H9: =H8/H5 -> 0.55420814 | I9: =I8/I5 -> 0.58403764 | J9: =J8/J5 -> 0.54367003 | ... M9: =M8/M5 -> 0.76823304
B11: GROSS PROFIT | C11: =C5-C8 -> 14487 | D11: =D5-D8 -> 16231 | E11: =E5-E8 -> 18229 | F11: =F5-F8 -> 19169 | G11: =G5-G8 -> 21727 | H11: =H5-H8 -> 23380 | I11: =I5-I8 -> 25199 | J11: =J5-J8 -> 28245 | ... M11: =M5-M8 -> 15117
B12: GROSS PROFIT % SALES | C12: =C11/C5 -> 0.43685544 | D12: =D11/D5 -> 0.45663244 | E12: =E11/E5 -> 0.46372424 | F12: =F11/F5 -> 0.48183898 | G12: =G11/G5 -> 0.46200136 | H12: =H11/H5 -> 0.44579186 | I12: =I11/I5 -> 0.41596236 | J12: =J11/J5 -> 0.45632997 | ... M12: =M11/M5 -> 0.23176696
B14: SELLING &GENERAL EXPENSES | C14: =IFERROR(SUM('Data Sheet'!B23:B24),0) -> 8159 | D14: =IFERROR(SUM('Data Sheet'!C23:C24),0) -> 8732 | E14: =IFERROR(SUM('Data Sheet'!D23:D24),0) -> 9349 | F14: =IFERROR(SUM('Data Sheet'!E23:E24),0) -> 9308 | G14: =IFERROR(SUM('Data Sheet'!F23:F24),0) -> 10101 | H14: =IFERROR(SUM('Data Sheet'!G23:G24),0) -> 10523 | I14: =IFERROR(SUM('Data Sheet'!H23:H24),0) -> 11052 | J14: =IFERROR(SUM('Data Sheet'!I23:I24),0) -> 13586 | ... M14: =IFERROR(SUM('Data Sheet'!L23:L24),0) -> 0
B15: SG EXP % SALES | C15: =C14/C5 -> 0.24603462 | D15: =D14/D5 -> 0.24566043 | E15: =E14/E5 -> 0.23782752 | F15: =F14/F5 -> 0.23396928 | G15: =G14/G5 -> 0.21478694 | H15: =H14/H5 -> 0.20064447 | I15: =I14/I5 -> 0.18243645 | J15: =J14/J5 -> 0.21949722 | ... L15: =L14/L5 -> 0.21398213
B17: EBITDA | C17: =C11-C14 -> 6328 | D17: =D11-D14 -> 7499 | E17: =E11-E14 -> 8880 | F17: =F11-F14 -> 9861 | G17: =G11-G14 -> 11626 | H17: =H11-H14 -> 12857 | I17: =I11-I14 -> 14147 | J17: =J11-J14 -> 14659 | ... M17: =M11-M14 -> 15117
B18: EBITDA % SALES | C18: =C17/C5 -> 0.19082082 | D18: =D17/D5 -> 0.21097201 | E18: =E17/E5 -> 0.22589672 | F18: =F17/F5 -> 0.24786969 | G18: =G17/G5 -> 0.24721443 | H18: =H17/H5 -> 0.24514739 | I18: =I17/I5 -> 0.23352592 | J18: =J17/J5 -> 0.23683275 | ... M18: =M17/M5 -> 0.23176696
B20: INTEREST | C20: =IFERROR('Data Sheet'!B27,0) -> 35 | D20: =IFERROR('Data Sheet'!C27,0) -> 26 | E20: =IFERROR('Data Sheet'!D27,0) -> 33 | F20: =IFERROR('Data Sheet'!E27,0) -> 118 | G20: =IFERROR('Data Sheet'!F27,0) -> 117 | H20: =IFERROR('Data Sheet'!G27,0) -> 106 | I20: =IFERROR('Data Sheet'!H27,0) -> 114 | J20: =IFERROR('Data Sheet'!I27,0) -> 334 | ... L20: =IFERROR('Data Sheet'!K27,0) -> 410 | M20: =IFERROR(SUM('Data Sheet'!H46:K46),0) -> 415
B21: INTEREST % SALES | C21: =C20/C5 -> 0.0010554249 | D21: =D20/D5 -> 0.00073146715 | E21: =E20/E5 -> 0.00083948105 | F21: =F20/F5 -> 0.002966091 | G21: =G20/G5 -> 0.0024878796 | H21: =H20/H5 -> 0.0020211265 | I21: =I20/I5 -> 0.0018818092 | J21: =J20/J5 -> 0.0053961484 | ... M21: =M20/M5 -> 0.006362591
B23: DEPRECIATION | C23: =IFERROR('Data Sheet'!B26,0) -> 432 | D23: =IFERROR('Data Sheet'!C26,0) -> 520 | E23: =IFERROR('Data Sheet'!D26,0) -> 565 | F23: =IFERROR('Data Sheet'!E26,0) -> 1002 | G23: =IFERROR('Data Sheet'!F26,0) -> 1074 | H23: =IFERROR('Data Sheet'!G26,0) -> 1091 | I23: =IFERROR('Data Sheet'!H26,0) -> 1137 | J23: =IFERROR('Data Sheet'!I26,0) -> 1216 | ... L23: =IFERROR('Data Sheet'!K26,0) -> 1333 | M23: =IFERROR(SUM('Data Sheet'!H45:K45),0) -> 1368
B24: DEPRECIATION% SALES | C24: =C23/C8 -> 0.02313253 | D24: =D23/D8 -> 0.026923475 | E24: =E23/E8 -> 0.026801385 | F24: =F23/F8 -> 0.048607742 | G24: =G23/G8 -> 0.042448915 | H24: =H23/H8 -> 0.037535265 | I24: =I23/I8 -> 0.032135892 | J24: =J23/J8 -> 0.036135627 | ... M24: =M23/M8 -> 0.02730103
B26: EARNINGS BEFORE TAX | C26: =IFERROR(C17-SUM(C20,C23),0) -> 5861 | D26: =IFERROR(D17-SUM(D20,D23),0) -> 6953 | E26: =IFERROR(E17-SUM(E20,E23),0) -> 8282 | F26: =IFERROR(F17-SUM(F20,F23),0) -> 8741 | G26: =IFERROR(G17-SUM(G20,G23),0) -> 10435 | H26: =IFERROR(H17-SUM(H20,H23),0) -> 11660 | I26: =IFERROR(I17-SUM(I20,I23),0) -> 12896 | J26: =IFERROR(J17-SUM(J20,J23),0) -> 13109 | ... M26: =IFERROR(M17-SUM(M20,M23),0) -> 13334
B27: EBT % SALES | C27: =C26/C5 -> 0.17673844 | D27: =D26/D5 -> 0.1956112 | E27: =E26/E5 -> 0.2106843 | F27: =F26/F5 -> 0.21971696 | G27: =G26/G5 -> 0.22188909 | H27: =H26/H5 -> 0.22232391 | I27: =I26/I5 -> 0.21287554 | J27: =J26/J5 -> 0.21179075 | ... M27: =M26/M5 -> 0.20443082
B29: TAX | C29: =IFERROR('Data Sheet'!B29,0) -> 1977 | D29: =IFERROR('Data Sheet'!C29,0) -> 2079 | E29: =IFERROR('Data Sheet'!D29,0) -> 2544 | F29: =IFERROR('Data Sheet'!E29,0) -> 2409 | G29: =IFERROR('Data Sheet'!F29,0) -> 2606 | H29: =IFERROR('Data Sheet'!G29,0) -> 2987 | I29: =IFERROR('Data Sheet'!H29,0) -> 3201 | J29: =IFERROR('Data Sheet'!I29,0) -> 3644 | ... L29: =IFERROR('Data Sheet'!K29,0) -> 3160 | M29: =IFERROR(SUM('Data Sheet'!H48:K48),0) -> 3169
B30: EFFECTIVE TAX RATE | C30: =C29/C26 -> 0.33731445 | D30: =D29/D26 -> 0.29900762 | E30: =E29/E26 -> 0.30717218 | F30: =F29/F26 -> 0.27559776 | G30: =G29/G26 -> 0.24973646 | H30: =H29/H26 -> 0.25617496 | I30: =I29/I26 -> 0.2482165 | J30: =J29/J26 -> 0.27797696 | ... M30: =M29/M26 -> 0.23766312
B32: NET PROFIT | C32: =C26-C29 -> 3884 | D32: =D26-D29 -> 4874 | E32: =E26-E29 -> 5738 | F32: =F26-F29 -> 6332 | G32: =G26-G29 -> 7829 | H32: =H26-H29 -> 8673 | I32: =I26-I29 -> 9695 | J32: =J26-J29 -> 9465 | ... M32: =M26-M29 -> 10165
B33: NET PROFIT % SALES | C33: =IFERROR(C32/C5,0) -> 0.11712201 | D33: =IFERROR(D32/D5,0) -> 0.13712196 | E33: =IFERROR(E32/E5,0) -> 0.14596795 | F33: =IFERROR(F32/F5,0) -> 0.15916346 | G33: =IFERROR(G32/G5,0) -> 0.16647529 | H33: =IFERROR(H32/H5,0) -> 0.16537009 | I33: =IFERROR(I32/I5,0) -> 0.16003632 | J33: =IFERROR(J32/J5,0) -> 0.1529178 | ... M33: =IFERROR(M32/M5,0) -> 0.15584515
B35: NO OF EQUITY SHARES | C35: =IFERROR('Data Sheet'!B93,0) -> 216.43 | D35: =IFERROR('Data Sheet'!C93,0) -> 216.45 | E35: =IFERROR('Data Sheet'!D93,0) -> 216.47 | F35: =IFERROR('Data Sheet'!E93,0) -> 216.48 | G35: =IFERROR('Data Sheet'!F93,0) -> 234.96 | H35: =IFERROR('Data Sheet'!G93,0) -> 234.96 | I35: =IFERROR('Data Sheet'!H93,0) -> 234.96 | J35: =IFERROR('Data Sheet'!I93,0) -> 234.96 | ... M35: =IFERROR('Data Sheet'!L93,0) -> 0
B37: EPS | C37: =IFERROR(C32/C35,0) -> 17.945756 | D37: =IFERROR(D32/D35,0) -> 22.517903 | E37: =IFERROR(E32/E35,0) -> 26.507137 | F37: =IFERROR(F32/F35,0) -> 29.249815 | G37: =IFERROR(G32/G35,0) -> 33.320565 | H37: =IFERROR(H32/H35,0) -> 36.912666 | I37: =IFERROR(I32/I35,0) -> 41.262343 | J37: =IFERROR(J32/J35,0) -> 40.283453 | ... M37: =IFERROR(M32/M35,0) -> 0
B38: EPS GROWTH % | D38: =IFERROR(D37/C37-1,0) -> 0.25477591 | E38: =E37/D37-1 -> 0.17715836 | F38: =F37/E37-1 -> 0.10346941 | G38: =G37/F37-1 -> 0.13917182 | H38: =H37/G37-1 -> 0.10780432 | I38: =I37/H37-1 -> 0.11783697 | J38: =J37/I37-1 -> -0.023723569 | K38: =K37/J37-1 -> -0.015742208 | L38: =L37/K37-1 -> 0.08802061 | M38: =M37/L37-1 -> -1
B40: DIVIDEND PER SHARE | C40: =IFERROR('Data Sheet'!B31/FINANCIALS!C35,0) -> 16.966225 | D40: =IFERROR('Data Sheet'!C31/FINANCIALS!D35,0) -> 19.95842 | E40: =IFERROR('Data Sheet'!D31/FINANCIALS!E35,0) -> 21.952234 | F40: =IFERROR('Data Sheet'!E31/FINANCIALS!F35,0) -> 24.944568 | G40: =IFERROR('Data Sheet'!F31/FINANCIALS!G35,0) -> 40.506895 | H40: =IFERROR('Data Sheet'!G31/FINANCIALS!H35,0) -> 34.005788 | I40: =IFERROR('Data Sheet'!H31/FINANCIALS!I35,0) -> 39.006639 | J40: =IFERROR('Data Sheet'!I31/FINANCIALS!J35,0) -> 42.00715 | ... M40: =IFERROR('Data Sheet'!L31/FINANCIALS!M35,0) -> 0
B41: DIVIDEND PAYOUT RATIO | C41: =IFERROR(C40/C37,0) -> 0.9454171 | D41: =IFERROR(D40/D37,0) -> 0.88633566 | E41: =IFERROR(E40/E37,0) -> 0.82816312 | F41: =IFERROR(F40/F37,0) -> 0.85281112 | G41: =IFERROR(G40/G37,0) -> 1.2156725 | H41: =IFERROR(H40/H37,0) -> 0.92124986 | I41: =IFERROR(I40/I37,0) -> 0.94533265 | J41: =IFERROR(J40/J37,0) -> 1.0427892 | ... M41: =IFERROR(M40/M37,0) -> 0
B43: RETAINED EARNINGS | C43: =IFERROR(IF(C37>C40,1-C41,0),0) -> 0.054582904 | D43: =IFERROR(IF(D37>D40,1-D41,0),0) -> 0.11366434 | E43: =IFERROR(IF(E37>E40,1-E41,0),0) -> 0.17183688 | F43: =IFERROR(IF(F37>F40,1-F41,0),0) -> 0.14718888 | G43: =IFERROR(IF(G37>G40,1-G41,0),0) -> 0 | H43: =IFERROR(IF(H37>H40,1-H41,0),0) -> 0.078750144 | I43: =IFERROR(IF(I37>I40,1-I41,0),0) -> 0.054667354 | J43: =IFERROR(IF(J37>J40,1-J41,0),0) -> 0 | ... M43: =IFERROR(IF(M37>M40,1-M41,0),0) -> 0
B48: YEARS | C48: 42825 | D48: 43190 | E48: 43555 | F48: 43921 | G48: 44286 | H48: 44651 | I48: 45016 | J48: 45382 | K48: 45747 | L48: 46112 | M48: LTM
A49: # | B49: BALANCE SHEET
B50: Equity Share Capital | C50: =IFERROR('Data Sheet'!B57,0) -> 216 | D50: =IFERROR('Data Sheet'!C57,0) -> 216 | E50: =IFERROR('Data Sheet'!D57,0) -> 216 | F50: =IFERROR('Data Sheet'!E57,0) -> 216 | G50: =IFERROR('Data Sheet'!F57,0) -> 235 | H50: =IFERROR('Data Sheet'!G57,0) -> 235 | I50: =IFERROR('Data Sheet'!H57,0) -> 235 | J50: =IFERROR('Data Sheet'!I57,0) -> 235 | ... L50: =IFERROR('Data Sheet'!K57,0) -> 235
B51: Reserves | C51: =IFERROR('Data Sheet'!B58,0) -> 6528 | D51: =IFERROR('Data Sheet'!C58,0) -> 7065 | E51: =IFERROR('Data Sheet'!D58,0) -> 7651 | F51: =IFERROR('Data Sheet'!E58,0) -> 8013 | G51: =IFERROR('Data Sheet'!F58,0) -> 47439 | H51: =IFERROR('Data Sheet'!G58,0) -> 48826 | I51: =IFERROR('Data Sheet'!H58,0) -> 50069 | J51: =IFERROR('Data Sheet'!I58,0) -> 50983 | ... L51: =IFERROR('Data Sheet'!K58,0) -> 48504
B52: Borrowings | C52: =IFERROR('Data Sheet'!B59,0) -> 277 | D52: =IFERROR('Data Sheet'!C59,0) -> 0 | E52: =IFERROR('Data Sheet'!D59,0) -> 99 | F52: =IFERROR('Data Sheet'!E59,0) -> 0 | G52: =IFERROR('Data Sheet'!F59,0) -> 0 | H52: =IFERROR('Data Sheet'!G59,0) -> 1043 | I52: =IFERROR('Data Sheet'!H59,0) -> 1219 | J52: =IFERROR('Data Sheet'!I59,0) -> 1484 | ... L52: =IFERROR('Data Sheet'!K59,0) -> 1478
B53: Other Liabilities | C53: =IFERROR('Data Sheet'!B60,0) -> 8685 | D53: =IFERROR('Data Sheet'!C60,0) -> 10581 | E53: =IFERROR('Data Sheet'!D60,0) -> 10663 | F53: =IFERROR('Data Sheet'!E60,0) -> 11924 | G53: =IFERROR('Data Sheet'!F60,0) -> 21066 | H53: =IFERROR('Data Sheet'!G60,0) -> 20402 | I53: =IFERROR('Data Sheet'!H60,0) -> 21554 | J53: =IFERROR('Data Sheet'!I60,0) -> 25787 | ... L53: =IFERROR('Data Sheet'!K60,0) -> 29521
B54: Total LIABILITY | C54: =IFERROR('Data Sheet'!B61,0) -> 15706 | D54: =IFERROR('Data Sheet'!C61,0) -> 17862 | E54: =IFERROR('Data Sheet'!D61,0) -> 18629 | F54: =IFERROR('Data Sheet'!E61,0) -> 20153 | G54: =IFERROR('Data Sheet'!F61,0) -> 68740 | H54: =IFERROR('Data Sheet'!G61,0) -> 70506 | I54: =IFERROR('Data Sheet'!H61,0) -> 73077 | J54: =IFERROR('Data Sheet'!I61,0) -> 78489 | ... L54: =IFERROR('Data Sheet'!K61,0) -> 79738
B56: FIXED ASSETS NET BLOCK | C56: =IFERROR('Data Sheet'!B62,0) -> 4419 | D56: =IFERROR('Data Sheet'!C62,0) -> 4528 | E56: =IFERROR('Data Sheet'!D62,0) -> 4715 | F56: =IFERROR('Data Sheet'!E62,0) -> 5479 | G56: =IFERROR('Data Sheet'!F62,0) -> 51443 | H56: =IFERROR('Data Sheet'!G62,0) -> 51473 | I56: =IFERROR('Data Sheet'!H62,0) -> 52678 | J56: =IFERROR('Data Sheet'!I62,0) -> 53744 | ... L56: =IFERROR('Data Sheet'!K62,0) -> 57428
B57: Capital Work in Progress | C57: =IFERROR('Data Sheet'!B63,0) -> 229 | D57: =IFERROR('Data Sheet'!C63,0) -> 461 | E57: =IFERROR('Data Sheet'!D63,0) -> 406 | F57: =IFERROR('Data Sheet'!E63,0) -> 597 | G57: =IFERROR('Data Sheet'!F63,0) -> 745 | H57: =IFERROR('Data Sheet'!G63,0) -> 1313 | I57: =IFERROR('Data Sheet'!H63,0) -> 1132 | J57: =IFERROR('Data Sheet'!I63,0) -> 1025 | ... L57: =IFERROR('Data Sheet'!K63,0) -> 880
B58: Investments | C58: =IFERROR('Data Sheet'!B64,0) -> 3794 | D58: =IFERROR('Data Sheet'!C64,0) -> 2873 | E58: =IFERROR('Data Sheet'!D64,0) -> 2716 | F58: =IFERROR('Data Sheet'!E64,0) -> 1255 | G58: =IFERROR('Data Sheet'!F64,0) -> 2709 | H58: =IFERROR('Data Sheet'!G64,0) -> 3521 | I58: =IFERROR('Data Sheet'!H64,0) -> 2882 | J58: =IFERROR('Data Sheet'!I64,0) -> 4625 | ... L58: =IFERROR('Data Sheet'!K64,0) -> 4359
B59: Other Assets | C59: =IFERROR('Data Sheet'!B65-SUM('Data Sheet'!B67:B69),0) -> 1810 | D59: =IFERROR('Data Sheet'!C65-SUM('Data Sheet'!C67:C69),0) -> 2692 | E59: =IFERROR('Data Sheet'!D65-SUM('Data Sheet'!D67:D69),0) -> 2645 | F59: =IFERROR('Data Sheet'!E65-SUM('Data Sheet'!E67:E69),0) -> 3793 | G59: =IFERROR('Data Sheet'!F65-SUM('Data Sheet'!F67:F69),0) -> 4035 | H59: =IFERROR('Data Sheet'!G65-SUM('Data Sheet'!G67:G69),0) -> 4021 | I59: =IFERROR('Data Sheet'!H65-SUM('Data Sheet'!H67:H69),0) -> 4377 | J59: =IFERROR('Data Sheet'!I65-SUM('Data Sheet'!I67:I69),0) -> 4517 | ... L59: =IFERROR('Data Sheet'!K65-SUM('Data Sheet'!K67:K69),0) -> 5655
...

Sheet Sheet1
B2: ="RATIO ANALYSIS - "&'Data Sheet'!B1 -> RATIO ANALYSIS - HINDUSTAN UNILEVER LTD
B3: YEARS | C3: ='Data Sheet'!B16 -> 42825 | D3: ='Data Sheet'!C16 -> 43190 | E3: ='Data Sheet'!D16 -> 43555 | F3: ='Data Sheet'!E16 -> 43921 | G3: ='Data Sheet'!F16 -> 44286 | H3: ='Data Sheet'!G16 -> 44651 | I3: ='Data Sheet'!H16 -> 45016 | J3: ='Data Sheet'!I16 -> 45382 | ... L3: ='Data Sheet'!K16 -> 46112
B5: SALES GROWTH | D5: =IFERROR(FINANCIALS!D6,0) -> 0.071859357 | E5: =IFERROR(FINANCIALS!E6,0) -> 0.10592207 | F5: =IFERROR(FINANCIALS!F6,0) -> 0.012032562 | G5: =IFERROR(FINANCIALS!G6,0) -> 0.18211296 | H5: =IFERROR(FINANCIALS!H6,0) -> 0.11520796 | I5: =IFERROR(FINANCIALS!I6,0) -> 0.15509286 | J5: =IFERROR(FINANCIALS!J6,0) -> 0.021723341 | K5: =IFERROR(FINANCIALS!K6,0) -> -0.0091766835 | L5: =IFERROR(FINANCIALS!L6,0) -> 0.051200104
B6: EBITDA GROWTH | D6: =IFERROR(FINANCIALS!D17/FINANCIALS!C17-1,0) -> 0.18505057 | E6: =IFERROR(FINANCIALS!E17/FINANCIALS!D17-1,0) -> 0.18415789 | F6: =IFERROR(FINANCIALS!F17/FINANCIALS!E17-1,0) -> 0.11047297 | G6: =IFERROR(FINANCIALS!G17/FINANCIALS!F17-1,0) -> 0.17898793 | H6: =IFERROR(FINANCIALS!H17/FINANCIALS!G17-1,0) -> 0.10588336 | I6: =IFERROR(FINANCIALS!I17/FINANCIALS!H17-1,0) -> 0.10033445 | J6: =IFERROR(FINANCIALS!J17/FINANCIALS!I17-1,0) -> 0.036191419 | K6: =IFERROR(FINANCIALS!K17/FINANCIALS!J17-1,0) -> 0.0026604816 | L6: =IFERROR(FINANCIALS!L17/FINANCIALS!K17-1,0) -> 0.023200435
B7: EBIT GROWTH | D7: =IFERROR(FINANCIALS!D26/FINANCIALS!C26-1,0) -> 0.18631633 | E7: =IFERROR(FINANCIALS!E26/FINANCIALS!D26-1,0) -> 0.19114051 | F7: =IFERROR(FINANCIALS!F26/FINANCIALS!E26-1,0) -> 0.055421396 | G7: =IFERROR(FINANCIALS!G26/FINANCIALS!F26-1,0) -> 0.19379934 | H7: =IFERROR(FINANCIALS!H26/FINANCIALS!G26-1,0) -> 0.11739339 | I7: =IFERROR(FINANCIALS!I26/FINANCIALS!H26-1,0) -> 0.10600343 | J7: =IFERROR(FINANCIALS!J26/FINANCIALS!I26-1,0) -> 0.016516749 | K7: =IFERROR(FINANCIALS!K26/FINANCIALS!J26-1,0) -> -0.0034327561 | L7: =IFERROR(FINANCIALS!L26/FINANCIALS!K26-1,0) -> 0.017758726
B8: NET PROFIT GROWTH | D8: =IFERROR(FINANCIALS!D32/FINANCIALS!C32-1,0) -> 0.25489186 | E8: =IFERROR(FINANCIALS!E32/FINANCIALS!D32-1,0) -> 0.17726713 | F8: =IFERROR(FINANCIALS!F32/FINANCIALS!E32-1,0) -> 0.10352039 | G8: =IFERROR(FINANCIALS!G32/FINANCIALS!F32-1,0) -> 0.23641819 | H8: =IFERROR(FINANCIALS!H32/FINANCIALS!G32-1,0) -> 0.10780432 | I8: =IFERROR(FINANCIALS!I32/FINANCIALS!H32-1,0) -> 0.11783697 | J8: =IFERROR(FINANCIALS!J32/FINANCIALS!I32-1,0) -> -0.023723569 | K8: =IFERROR(FINANCIALS!K32/FINANCIALS!J32-1,0) -> -0.015742208 | L8: =IFERROR(FINANCIALS!L32/FINANCIALS!K32-1,0) -> 0.08802061
B9: DIVIDENED GROWTH | D9: =IFERROR(FINANCIALS!D40/FINANCIALS!C40-1,0) -> 0.17636188 | E9: =IFERROR(FINANCIALS!E40/FINANCIALS!D40-1,0) -> 0.099898369 | F9: =IFERROR(FINANCIALS!F40/FINANCIALS!E40-1,0) -> 0.13631114 | G9: =IFERROR(FINANCIALS!G40/FINANCIALS!F40-1,0) -> 0.6238764 | H9: =IFERROR(FINANCIALS!H40/FINANCIALS!G40-1,0) -> -0.16049383 | I9: =IFERROR(FINANCIALS!I40/FINANCIALS!H40-1,0) -> 0.14705882 | J9: =IFERROR(FINANCIALS!J40/FINANCIALS!I40-1,0) -> 0.076923077 | K9: =IFERROR(FINANCIALS!K40/FINANCIALS!J40-1,0) -> 0.26190476 | L9: =IFERROR(FINANCIALS!L40/FINANCIALS!K40-1,0) -> -0.22641509
B11: GROSS MARGIN | C11: =IFERROR(FINANCIALS!C12,0) -> 0.43685544 | D11: =IFERROR(FINANCIALS!D12,0) -> 0.45663244 | E11: =IFERROR(FINANCIALS!E12,0) -> 0.46372424 | F11: =IFERROR(FINANCIALS!F12,0) -> 0.48183898 | G11: =IFERROR(FINANCIALS!G12,0) -> 0.46200136 | H11: =IFERROR(FINANCIALS!H12,0) -> 0.44579186 | I11: =IFERROR(FINANCIALS!I12,0) -> 0.41596236 | J11: =IFERROR(FINANCIALS!J12,0) -> 0.45632997 | ... L11: =IFERROR(FINANCIALS!L12,0) -> 0.44726066
B12: EDITDA MARGIN | C12: =IFERROR(FINANCIALS!C18,0) -> 0.19082082 | D12: =IFERROR(FINANCIALS!D18,0) -> 0.21097201 | E12: =IFERROR(FINANCIALS!E18,0) -> 0.22589672 | F12: =IFERROR(FINANCIALS!F18,0) -> 0.24786969 | G12: =IFERROR(FINANCIALS!G18,0) -> 0.24721443 | H12: =IFERROR(FINANCIALS!H18,0) -> 0.24514739 | I12: =IFERROR(FINANCIALS!I18,0) -> 0.23352592 | J12: =IFERROR(FINANCIALS!J18,0) -> 0.23683275 | ... L12: =IFERROR(FINANCIALS!L18,0) -> 0.23327853
B13: EBIT MARGIN | C13: =IFERROR((FINANCIALS!C17-FINANCIALS!C23)/FINANCIALS!C5,0) -> 0.17779386 | D13: =IFERROR((FINANCIALS!D17-FINANCIALS!D23)/FINANCIALS!D5,0) -> 0.19634266 | E13: =IFERROR((FINANCIALS!E17-FINANCIALS!E23)/FINANCIALS!E5,0) -> 0.21152379 | F13: =IFERROR((FINANCIALS!F17-FINANCIALS!F23)/FINANCIALS!F5,0) -> 0.22268306 | G13: =IFERROR((FINANCIALS!G17-FINANCIALS!G23)/FINANCIALS!G5,0) -> 0.22437697 | H13: =IFERROR((FINANCIALS!H17-FINANCIALS!H23)/FINANCIALS!H5,0) -> 0.22434504 | I13: =IFERROR((FINANCIALS!I17-FINANCIALS!I23)/FINANCIALS!I5,0) -> 0.21475735 | J13: =IFERROR((FINANCIALS!J17-FINANCIALS!J23)/FINANCIALS!J5,0) -> 0.21718689 | ... L13: =IFERROR((FINANCIALS!L17-FINANCIALS!L23)/FINANCIALS!L5,0) -> 0.2126016
B14: EBT MARGIN | C14: =IFERROR(FINANCIALS!C27,0) -> 0.17673844 | D14: =IFERROR(FINANCIALS!D27,0) -> 0.1956112 | E14: =IFERROR(FINANCIALS!E27,0) -> 0.2106843 | F14: =IFERROR(FINANCIALS!F27,0) -> 0.21971696 | G14: =IFERROR(FINANCIALS!G27,0) -> 0.22188909 | H14: =IFERROR(FINANCIALS!H27,0) -> 0.22232391 | I14: =IFERROR(FINANCIALS!I27,0) -> 0.21287554 | J14: =IFERROR(FINANCIALS!J27,0) -> 0.21179075 | ... L14: =IFERROR(FINANCIALS!L27,0) -> 0.20624186
B15: NET PROFIT MARGIN | C15: =IFERROR(FINANCIALS!C33,0) -> 0.11712201 | D15: =IFERROR(FINANCIALS!D33,0) -> 0.13712196 | E15: =IFERROR(FINANCIALS!E33,0) -> 0.14596795 | F15: =IFERROR(FINANCIALS!F33,0) -> 0.15916346 | G15: =IFERROR(FINANCIALS!G33,0) -> 0.16647529 | H15: =IFERROR(FINANCIALS!H33,0) -> 0.16537009 | I15: =IFERROR(FINANCIALS!I33,0) -> 0.16003632 | J15: =IFERROR(FINANCIALS!J33,0) -> 0.1529178 | ... L15: =IFERROR(FINANCIALS!L33,0) -> 0.15722529
B18: SALESEXPENSES%SALES | C18: =IFERROR(FINANCIALS!C15,0) -> 0.24603462 | D18: =IFERROR(FINANCIALS!D15,0) -> 0.24566043 | E18: =IFERROR(FINANCIALS!E15,0) -> 0.23782752 | F18: =IFERROR(FINANCIALS!F15,0) -> 0.23396928 | G18: =IFERROR(FINANCIALS!G15,0) -> 0.21478694 | H18: =IFERROR(FINANCIALS!H15,0) -> 0.20064447 | I18: =IFERROR(FINANCIALS!I15,0) -> 0.18243645 | J18: =IFERROR(FINANCIALS!J15,0) -> 0.21949722 | ... L18: =IFERROR(FINANCIALS!L15,0) -> 0.21398213
B19: DEPRECIATION%SALES | C19: =IFERROR(FINANCIALS!C24,0) -> 0.02313253 | D19: =IFERROR(FINANCIALS!D24,0) -> 0.026923475 | E19: =IFERROR(FINANCIALS!E24,0) -> 0.026801385 | F19: =IFERROR(FINANCIALS!F24,0) -> 0.048607742 | G19: =IFERROR(FINANCIALS!G24,0) -> 0.042448915 | H19: =IFERROR(FINANCIALS!H24,0) -> 0.037535265 | I19: =IFERROR(FINANCIALS!I24,0) -> 0.032135892 | J19: =IFERROR(FINANCIALS!J24,0) -> 0.036135627 | ... L19: =IFERROR(FINANCIALS!L24,0) -> 0.037408093
B20: OPERATINGINCOME%SALES | C20: =C13 -> 0.17779386 | D20: =D13 -> 0.19634266 | E20: =E13 -> 0.21152379 | F20: =F13 -> 0.22268306 | G20: =G13 -> 0.22437697 | H20: =H13 -> 0.22434504 | I20: =I13 -> 0.21475735 | J20: =J13 -> 0.21718689 | ... L20: =L13 -> 0.2126016
B22: RETURN ON CAPITAL EMPLOYED | C22: =(FINANCIALS!C17-FINANCIALS!C23)/(SUM(FINANCIALS!C50:C52)) -> 0.83976642 | D22: =(FINANCIALS!D17-FINANCIALS!D23)/(SUM(FINANCIALS!D50:D52)) -> 0.95852218 | E22: =(FINANCIALS!E17-FINANCIALS!E23)/(SUM(FINANCIALS!E50:E52)) -> 1.0438112 | F22: =(FINANCIALS!F17-FINANCIALS!F23)/(SUM(FINANCIALS!F50:F52)) -> 1.0765585 | G22: =(FINANCIALS!G17-FINANCIALS!G23)/(SUM(FINANCIALS!G50:G52)) -> 0.22133658 | H22: =(FINANCIALS!H17-FINANCIALS!H23)/(SUM(FINANCIALS!H50:H52)) -> 0.23483155 | I22: =(FINANCIALS!I17-FINANCIALS!I23)/(SUM(FINANCIALS!I50:I52)) -> 0.25250859 | J22: =(FINANCIALS!J17-FINANCIALS!J23)/(SUM(FINANCIALS!J50:J52)) -> 0.25507571 | ... L22: =(FINANCIALS!L17-FINANCIALS!L23)/(SUM(FINANCIALS!L50:L52)) -> 0.27293546
B23: RETAINED EARNING% | C23: =IFERROR(FINANCIALS!C43,0) -> 0.054582904 | D23: =IFERROR(FINANCIALS!D43,0) -> 0.11366434 | E23: =IFERROR(FINANCIALS!E43,0) -> 0.17183688 | F23: =IFERROR(FINANCIALS!F43,0) -> 0.14718888 | G23: =IFERROR(FINANCIALS!G43,0) -> 0 | H23: =IFERROR(FINANCIALS!H43,0) -> 0.078750144 | I23: =IFERROR(FINANCIALS!I43,0) -> 0.054667354 | J23: =IFERROR(FINANCIALS!J43,0) -> 0 | ... L23: =IFERROR(FINANCIALS!L43,0) -> 0.049427782
B24: RETURN ON EQUITY % | C24: =IFERROR(FINANCIALS!C32/SUM(FINANCIALS!C50:C51),0) -> 0.57591934 | D24: =IFERROR(FINANCIALS!D32/SUM(FINANCIALS!D50:D51),0) -> 0.66941354 | E24: =IFERROR(FINANCIALS!E32/SUM(FINANCIALS!E50:E51),0) -> 0.72937587 | F24: =IFERROR(FINANCIALS!F32/SUM(FINANCIALS!F50:F51),0) -> 0.76947381 | G24: =IFERROR(FINANCIALS!G32/SUM(FINANCIALS!G50:G51),0) -> 0.16421949 | H24: =IFERROR(FINANCIALS!H32/SUM(FINANCIALS!H50:H51),0) -> 0.17677993 | I24: =IFERROR(FINANCIALS!I32/SUM(FINANCIALS!I50:I51),0) -> 0.19272821 | J24: =IFERROR(FINANCIALS!J32/SUM(FINANCIALS!J50:J51),0) -> 0.18479831 | ... L24: =IFERROR(FINANCIALS!L32/SUM(FINANCIALS!L50:L51),0) -> 0.20796487
B25: SELF SUSTAINED GROWTH RATE | C25: =IFERROR(C23*C24,0) -> 0.03143535 | D25: =IFERROR(D23*D24,0) -> 0.076088449 | E25: =IFERROR(E23*E24,0) -> 0.12533367 | F25: =IFERROR(F23*F24,0) -> 0.11325799 | G25: =IFERROR(G23*G24,0) -> 0 | H25: =IFERROR(H23*H24,0) -> 0.013921445 | I25: =IFERROR(I23*I24,0) -> 0.010535941 | J25: =IFERROR(J23*J24,0) -> 0 | ... L25: =IFERROR(L23*L24,0) -> 0.010279242
B26: INTEREST COVERAGE RATIO | C26: =(FINANCIALS!C17-FINANCIALS!C23)/FINANCIALS!C20 -> 168.45714 | D26: =(FINANCIALS!D17-FINANCIALS!D23)/FINANCIALS!D20 -> 268.42308 | E26: =(FINANCIALS!E17-FINANCIALS!E23)/FINANCIALS!E20 -> 251.9697 | F26: =(FINANCIALS!F17-FINANCIALS!F23)/FINANCIALS!F20 -> 75.076271 | G26: =(FINANCIALS!G17-FINANCIALS!G23)/FINANCIALS!G20 -> 90.188034 | H26: =(FINANCIALS!H17-FINANCIALS!H23)/FINANCIALS!H20 -> 111 | I26: =(FINANCIALS!I17-FINANCIALS!I23)/FINANCIALS!I20 -> 114.12281 | J26: =(FINANCIALS!J17-FINANCIALS!J23)/FINANCIALS!J20 -> 40.248503 | ... L26: =(FINANCIALS!L17-FINANCIALS!L23)/FINANCIALS!L20 -> 33.429268
B28: Debtor Turnover Ratio | C28: =FINANCIALS!C5/FINANCIALS!C62 -> 30.564055 | D28: =FINANCIALS!D5/FINANCIALS!D62 -> 27.133588 | E28: =FINANCIALS!E5/FINANCIALS!E62 -> 21.646476 | F28: =FINANCIALS!F5/FINANCIALS!F62 -> 34.624021 | G28: =FINANCIALS!G5/FINANCIALS!G62 -> 26.750853 | H28: =FINANCIALS!H5/FINANCIALS!H62 -> 23.455277 | I28: =FINANCIALS!I5/FINANCIALS!I62 -> 19.675219 | J28: =FINANCIALS!J5/FINANCIALS!J62 -> 20.652653 | ... L28: =FINANCIALS!L5/FINANCIALS!L62 -> 19.079017
B29: Credit Turnover Ratio | C29: =IFERROR(FINANCIALS!C5/FINANCIALS!C53,0) -> 3.8183074 | D29: =IFERROR(FINANCIALS!D5/FINANCIALS!D53,0) -> 3.3593233 | E29: =IFERROR(FINANCIALS!E5/FINANCIALS!E53,0) -> 3.6865798 | F29: =IFERROR(FINANCIALS!F5/FINANCIALS!F53,0) -> 3.3363804 | G29: =IFERROR(FINANCIALS!G5/FINANCIALS!G53,0) -> 2.2324124 | H29: =IFERROR(FINANCIALS!H5/FINANCIALS!H53,0) -> 2.5706303 | I29: =IFERROR(FINANCIALS!I5/FINANCIALS!I53,0) -> 2.8106152 | J29: =IFERROR(FINANCIALS!J5/FINANCIALS!J53,0) -> 2.4002792 | ... L29: =IFERROR(FINANCIALS!L5/FINANCIALS!L53,0) -> 2.1838014
B30: Inventory Turnoover ratio | C30: =IFERROR(FINANCIALS!C5/FINANCIALS!C63,0) -> 13.050767 | D30: =IFERROR(FINANCIALS!D5/FINANCIALS!D63,0) -> 14.144449 | E30: =IFERROR(FINANCIALS!E5/FINANCIALS!E63,0) -> 15.27195 | F30: =IFERROR(FINANCIALS!F5/FINANCIALS!F63,0) -> 14.377665 | G30: =IFERROR(FINANCIALS!G5/FINANCIALS!G63,0) -> 13.139983 | H30: =IFERROR(FINANCIALS!H5/FINANCIALS!H63,0) -> 12.804199 | I30: =IFERROR(FINANCIALS!I5/FINANCIALS!I63,0) -> 14.250765 | J30: =IFERROR(FINANCIALS!J5/FINANCIALS!J63,0) -> 15.389359 | ... L30: =IFERROR(FINANCIALS!L5/FINANCIALS!L63,0) -> 13.461683
B31: Fixed Asset Turnover | C31: =IFERROR(FINANCIALS!C5/FINANCIALS!C52,0) -> 119.71841 | D31: =IFERROR(FINANCIALS!D5/FINANCIALS!D52,0) -> 0 | E31: =IFERROR(FINANCIALS!E5/FINANCIALS!E52,0) -> 397.07071 | F31: =IFERROR(FINANCIALS!F5/FINANCIALS!F52,0) -> 0 | G31: =IFERROR(FINANCIALS!G5/FINANCIALS!G52,0) -> 0 | H31: =IFERROR(FINANCIALS!H5/FINANCIALS!H52,0) -> 50.283797 | I31: =IFERROR(FINANCIALS!I5/FINANCIALS!I52,0) -> 49.696473 | J31: =IFERROR(FINANCIALS!J5/FINANCIALS!J52,0) -> 41.708895 | ... L31: =IFERROR(FINANCIALS!L5/FINANCIALS!L52,0) -> 43.618403
B32: Capital Turnover Ratio | C32: =IFERROR(FINANCIALS!C5/SUM(FINANCIALS!C50:C51),) -> 4.9172598 | D32: =IFERROR(FINANCIALS!D5/SUM(FINANCIALS!D50:D51),) -> 4.8818844 | E32: =IFERROR(FINANCIALS!E5/SUM(FINANCIALS!E50:E51),) -> 4.9968222 | F32: =IFERROR(FINANCIALS!F5/SUM(FINANCIALS!F50:F51),) -> 4.8344878 | G32: =IFERROR(FINANCIALS!G5/SUM(FINANCIALS!G50:G51),) -> 0.98644964 | H32: =IFERROR(FINANCIALS!H5/SUM(FINANCIALS!H50:H51),) -> 1.0689957 | I32: =IFERROR(FINANCIALS!I5/SUM(FINANCIALS!I50:I51),) -> 1.204278 | J32: =IFERROR(FINANCIALS!J5/SUM(FINANCIALS!J50:J51),) -> 1.2084814 | ... L32: =IFERROR(FINANCIALS!L5/SUM(FINANCIALS!L50:L51),) -> 1.322719
B34: debtor days | C34: =IFERROR(365/C28,0) -> 11.942133
B35: Payable days | C35: =IFERROR(365/C29,0) -> 95.592093
B36: Inventory Days | C36: =IFERROR(365/C30,0) -> 27.967704
B37: Cash Conversion cycle

Sheet HISTORICAL FS
N3: 13041
T4: 42064 | U4: 42430 | V4: 42795 | W4: 43160 | X4: 43525 | Y4: 43891 | Z4: 44256 | AA4: 44621 | AB4: 44986 | AC4: 45352 | AD4: 45717 | AE4: 46082
S5: Cash from Operating Activity - | T5: 35531 | U5: 37900 | V5: 30199 | W5: 23857 | X5: 18891 | Y5: 26633 | Z5: 29001 | AA5: 14283 | AB5: 35388 | AC5: 67915 | AD5: 63102 | AE5: 13041
S6: Profit from operations | T6: 43397 | U6: 38626 | V6: 28840 | W6: 33312 | X6: 28771 | Y6: 23352 | Z6: 31198 | AA6: 26943 | AB6: 41694 | AC6: 65106 | AD6: 58937 | AE6: 25393
S7: Receivables | T7: -3179 | U7: -2223 | V7: -4152 | W7: -10688 | X7: -9109 | Y7: 9950 | Z7: -5505 | AA7: 185 | AB7: -2213 | AC7: -1876 | AD7: 3573 | AE7: -1587
S8: Inventory | T8: -3692 | U8: -5743 | V8: -6621 | W8: -3560 | X8: 2069 | Y8: 2326 | Z8: 3814 | AA8: 472 | AB8: -5665 | AC8: -7265 | AD8: 2127 | AE8: -4318
S9: Payables | T9: 3598 | U9: 3947 | V9: 9301 | W9: 7320 | X9: -4692 | Y9: -8085 | Z9: 5748 | AA9: -7012 | AB9: 6945 | AC9: 13706 | AD9: 1303 | AE9: -1973
S10: Loans Advances | T10: 0 | U10: -520 | V10: 0 | W10: 0 | X10: 0 | Y10: 0 | Z10: 0 | AA10: 0 | AB10: 0 | AC10: 0 | AD10: 0 | AE10: -815
S11: Other WC items | T11: -398 | U11: 5852 | V11: 4727 | W11: 494 | X11: 4512 | Y11: 875 | Z11: -4150 | AA11: -4396 | AB11: -2194 | AC11: 2760 | AD11: 1153 | AE11: -345
S12: Working capital changes | T12: -3672 | U12: 1313 | V12: 3254 | W12: -6434 | X12: -7221 | Y12: 5065 | Z12: -93 | AA12: -10750 | AB12: -3127 | AC12: 7325 | AD12: 8156 | AE12: -9038
S13: Direct taxes | T13: -4194 | U13: -2040 | V13: -1895 | W13: -3021 | X13: -2659 | Y13: -1785 | Z13: -2105 | AA13: -1910 | AB13: -3179 | AC13: -4516 | AD13: -3991 | AE13: -3314
S14: Cash from Investing Activity - | T14: -36232 | U14: -36694 | V14: -39571 | W14: -25139 | X14: -20878 | Y14: -33115 | Z14: -25672 | AA14: -4444 | AB14: -15417 | AC14: -22781 | AD14: -49982 | AE14: -24810
S15: Fixed assets purchased | T15: -31962 | U15: -31503 | V15: -16072 | W15: -35079 | X15: -35304 | Y15: -29702 | Z15: -20205 | AA15: -15168 | AB15: -19230 | AC15: -31414 | AD15: -38042 | AE15: -36282
S16: Fixed assets sold | T16: 74 | U16: 59 | V16: 53 | W16: 30 | X16: 67 | Y16: 171 | Z16: 351 | AA16: 230 | AB16: 285 | AC16: 231 | AD16: 974 | AE16: 46
... S19: Interest received | T19: 698 | U19: 731 | V19: 638 | W19: 690 | X19: 761 | Y19: 1104 | Z19: 428 | AA19: 653 | AB19: 973 | AC19: 2493 | AD19: 2420 | AE19: 1940
N20: 0 | S20: Dividends received | T20: 80 | U20: 58 | V20: 620 | W20: 1797 | X20: 232 | Y20: 21 | Z20: 18 | AA20: 32 | AB20: 46 | AC20: 47 | AD20: 64 | AE20: 199
N21: -512 | S21: Investment in group cos | T21: -160 | U21: 0 | V21: -107 | W21: -4 | X21: -9 | Y21: -606 | Z21: -10 | AA21: 0 | AB21: 0 | AC21: -150 | AD21: 0 | AE21: -5
N22: -83 | S22: Redemp n Canc of Shares | T22: 0 | U22: 0 | V22: 0 | W22: 14 | X22: 533 | Y22: 0 | Z22: 0 | AA22: 0 | AB22: 19 | AC22: 107 | AD22: 765 | AE22: 0
N23: -715 | S23: Acquisition of companies | T23: 0 | U23: -111 | V23: 0 | W23: 0 | X23: -8 | Y23: -27 | Z23: 0 | AA23: -98 | AB23: 0 | AC23: 0 | AD23: -688 | AE23: -512
N24: -1344 | S24: Inter corporate deposits | T24: 0 | U24: 0 | V24: 0 | W24: 0 | X24: 0 | Y24: 0 | Z24: 0 | AA24: 0 | AB24: 0 | AC24: -25 | AD24: -20 | AE24: -83
N25: 18 | S25: Other investing items | T25: 456 | U25: -1289 | V25: -26663 | W25: 5360 | X25: 7335 | Y25: -2659 | Z25: 1051 | AA25: 12813 | AB25: -4357 | AC25: -4817 | AD25: -2889 | AE25: -715
N26: 0 | S26: Cash from Financing Activity - | T26: 5201 | U26: -3795 | V26: 6205 | W26: 2012 | X26: 8830 | Y26: 3390 | Z26: 9904 | AA26: -3380 | AB26: -26243 | AC26: -37006 | AD26: -18786 | AE26: -1344
N27: 26425 | S27: Proceeds from shares | T27: 0 | U27: 7433 | V27: 5 | W27: 0 | X27: 0 | Y27: 3889 | Z27: 2603 | AA27: 19 | AB27: 20 | AC27: 82 | AD27: 1108 | AE27: 18
N28: -18110 | S28: Redemption of debentures | T28: -744 | U28: 0 | V28: 0 | W28: 0 | X28: 0 | Y28: 0 | Z28: 0 | AA28: 0 | AB28: 0 | AC28: 0 | AD28: 0 | AE28: 0
N29: -5111 | S29: Proceeds from borrowings | T29: 36363 | U29: 19519 | V29: 33390 | W29: 37482 | X29: 51128 | Y29: 38297 | Z29: 46641 | AA29: 46578 | AB29: 43934 | AC29: 18829 | AD29: 13384 | AE29: 26425
N30: -2203 | S30: Repayment of borrowings | T30: -23332 | U30: -24924 | V30: -21732 | W30: -29964 | X30: -35198 | Y30: -29847 | Z30: -29709 | AA30: -42816 | AB30: -62557 | AC30: -47414 | AD30: -21443 | AE30: -18110
N31: -2145 | S31: Interest paid fin | T31: -6307 | U31: -5716 | V31: -5336 | W31: -5411 | X31: -7005 | Y31: -7518 | Z31: -8123 | AA31: -9251 | AB31: -9336 | AC31: -9332 | AD31: -5814 | AE31: -5111
... N35: 0.87 | S35: Net Cash Flow | T35: 4500 | U35: -2589 | V35: -3167 | W35: 730 | X35: 6843 | Y35: -3092 | Z35: 13232 | AA35: 6459 | AB35: -6272 | AC35: 8128 | AD35: -5666 | AE35: -13113
S36: Free Cash Flow | T36: 3643 | U36: 6455 | V36: 14181 | W36: -11191 | X36: -16346 | Y36: -2898 | Z36: 9146 | AA36: -655 | AB36: 16443 | AC36: 36732 | AD36: 26034 | AE36: -23195
S37: CFO/OP | T37: 1.01 | U37: 1.04 | V37: 1.08 | W37: 0.85 | X37: 0.87 | Y37: 1.58 | Z37: 0.96 | AA37: 0.66 | AB37: 1.21 | AC37: 1.25 | AD37: 1.2 | AE37: 0.87

Sheet Data Sheet
A1: COMPANY NAME | B1: HINDUSTAN UNILEVER LTD | E1: =IF(B2<>B3, "A NEW VERSION OF THE WORKSHEET IS AVAILABLE", "")
A2: LATEST VERSION | B2: 2.1 | E2: PLEASE DO NOT MAKE ANY CHANGES TO THIS SHEET
A3: CURRENT VERSION | B3: 2.1
A5: META
A6: Number of shares | B6: =IF(B9>0, B9/B8, 0) -> 234.95912
A7: Face Value | B7: 1
A8: Current Price | B8: 2143.8
A9: Market Capitalization | B9: 503705.37
A15: PROFIT & LOSS
A16: Report Date | B16: 42825 | C16: 43190 | D16: 43555 | E16: 43921 | F16: 44286 | G16: 44651 | H16: 45016 | I16: 45382 | J16: 45747 | K16: 46112
A17: Sales | B17: 33162 | C17: 35545 | D17: 39310 | E17: 39783 | F17: 47028 | G17: 52446 | H17: 60580 | I17: 61896 | J17: 61328 | K17: 64468
A18: Raw Material Cost | B18: 13606 | C18: 14233 | D18: 15845 | E18: 15697 | F18: 20141 | G18: 22871 | H18: 28427 | I18: 26822 | J18: 26602 | K18: 29158
A19: Change in Inventory | B19: -144 | C19: 72 | D19: -12 | E19: 108 | F19: 405 | G19: 22 | H19: 75 | I19: 11 | J19: 125 | K19: 429
A20: Power and Fuel | B20: 295 | C20: 295 | D20: 308 | E20: 299 | F20: 339 | G20: 318 | H20: 384 | I20: 446 | J20: 403 | K20: 426
A21: Other Mfr. Exp | B21: 2887 | C21: 2998 | D21: 3041 | E21: 2906 | F21: 2868 | G21: 3354 | H21: 3791 | I21: 3385 | J21: 3687 | K21: 3304
A22: Employee Cost | B22: 1743 | C22: 1860 | D22: 1875 | E22: 1820 | F22: 2358 | G22: 2545 | H22: 2854 | I22: 3009 | J22: 2952 | K22: 3175
A23: Selling and admin | B23: 6689 | C23: 7252 | D23: 7796 | E23: 7620 | F23: 7906 | G23: 8164 | H23: 8785 | I23: 10780 | J23: 10145 | K23: 10744
A24: Other Expenses | B24: 1470 | C24: 1480 | D24: 1553 | E24: 1688 | F24: 2195 | G24: 2359 | H24: 2267 | I24: 2806 | J24: 2966 | K24: 3051
A25: Other Income | B25: 606 | C25: 353 | D25: 322 | E25: 424 | F25: 170 | G25: 219 | H25: 448 | I25: 817 | J25: 1355 | K25: 4923
A26: Depreciation | B26: 432 | C26: 520 | D26: 565 | E26: 1002 | F26: 1074 | G26: 1091 | H26: 1137 | I26: 1216 | J26: 1253 | K26: 1333
A27: Interest | B27: 35 | C27: 26 | D27: 33 | E27: 118 | F27: 117 | G27: 106 | H27: 114 | I27: 334 | J27: 381 | K27: 410
... A31: Dividend Amount | B31: 3672 | C31: 4320 | D31: 4752 | E31: 5400 | F31: 9517.5 | G31: 7990 | H31: 9165 | I31: 9870 | J31: 12455 | K31: 9635
A40: Quarters
A41: Report Date | B41: 45291 | C41: 45382 | D41: 45473 | E41: 45565 | F41: 45657 | G41: 45747 | H41: 45838 | I41: 45930 | J41: 46022 | K41: 46112
A42: Sales | B42: 15567 | C42: 15210 | D42: 15707 | E42: 15926 | F42: 15556 | G42: 15190 | H42: 16514 | I42: 15919 | J42: 16441 | K42: 16351
A43: Expenses | B43: 11902 | C43: 11675 | D43: 11965 | E43: 12139 | F43: 11867 | G43: 11572 | H43: 12797 | I43: 12137 | J43: 12660 | K43: 12514
A44: Other Income | B44: 184 | C44: 309 | D44: 209 | E44: 203 | F44: 733 | G44: 149 | H44: 74 | I44: 269 | J44: 4048 | K44: 503
A45: Depreciation | B45: 313 | C45: 320 | D45: 329 | E45: 338 | F45: 318 | G45: 318 | H45: 361 | I45: 322 | J45: 337 | K45: 348
A46: Interest | B46: 91 | C46: 105 | D46: 93 | E46: 110 | F46: 109 | G46: 77 | H46: 127 | I46: 124 | J46: 88 | K46: 76
A47: Profit before tax | B47: 3445 | C47: 3419 | D47: 3529 | E47: 3542 | F47: 3995 | G47: 3372 | H47: 3303 | I47: 3605 | J47: 7404 | K47: 3916
A48: Tax | B48: 937 | C48: 858 | D48: 917 | E48: 947 | F48: 1006 | G48: 897 | H48: 535 | I48: 911 | J48: 801 | K48: 922
A49: Net profit | B49: 2509 | C49: 2558 | D49: 2610 | E49: 2591 | F49: 2984 | G49: 2464 | H49: 2756 | I49: 2685 | J49: 6607 | K49: 2992
A50: Operating Profit | B50: 3665 | C50: 3535 | D50: 3742 | E50: 3787 | F50: 3689 | G50: 3618 | H50: 3717 | I50: 3782 | J50: 3781 | K50: 3837
A55: BALANCE SHEET
A56: Report Date | B56: 42825 | C56: 43190 | D56: 43555 | E56: 43921 | F56: 44286 | G56: 44651 | H56: 45016 | I56: 45382 | J56: 45747 | K56: 46112
A57: Equity Share Capital | B57: 216 | C57: 216 | D57: 216 | E57: 216 | F57: 235 | G57: 235 | H57: 235 | I57: 235 | J57: 235 | K57: 235
A58: Reserves | B58: 6528 | C58: 7065 | D58: 7651 | E58: 8013 | F58: 47439 | G58: 48826 | H58: 50069 | I58: 50983 | J58: 49167 | K58: 48504
A59: Borrowings | B59: 277 | D59: 99 | G59: 1043 | H59: 1219 | I59: 1484 | J59: 1648 | K59: 1478
A60: Other Liabilities | B60: 8685 | C60: 10581 | D60: 10663 | E60: 11924 | F60: 21066 | G60: 20402 | H60: 21554 | I60: 25787 | J60: 28813 | K60: 29521
A61: Total | B61: 15706 | C61: 17862 | D61: 18629 | E61: 20153 | F61: 68740 | G61: 70506 | H61: 73077 | I61: 78489 | J61: 79863 | K61: 79738
...

Sheet Profit & Loss
A1: ='Data Sheet'!B1 -> HINDUSTAN UNILEVER LTD | H1: =UPDATE | M1: SCREENER.IN
A3: Narration | B3: ='Data Sheet'!B16 -> 42825 | C3: ='Data Sheet'!C16 -> 43190 | D3: ='Data Sheet'!D16 -> 43555 | E3: ='Data Sheet'!E16 -> 43921 | F3: ='Data Sheet'!F16 -> 44286 | G3: ='Data Sheet'!G16 -> 44651 | H3: ='Data Sheet'!H16 -> 45016 | I3: ='Data Sheet'!I16 -> 45382 | ... K3: ='Data Sheet'!K16 -> 46112 | L3: Trailing | M3: Best Case | N3: Worst Case
A4: Sales | B4: ='Data Sheet'!B17 -> 33162 | C4: ='Data Sheet'!C17 -> 35545 | D4: ='Data Sheet'!D17 -> 39310 | E4: ='Data Sheet'!E17 -> 39783 | F4: ='Data Sheet'!F17 -> 47028 | G4: ='Data Sheet'!G17 -> 52446 | H4: ='Data Sheet'!H17 -> 60580 | I4: ='Data Sheet'!I17 -> 61896 | ... K4: ='Data Sheet'!K17 -> 64468 | L4: =SUM(Quarters!H4:K4) -> 65225 | M4: =$K4+M23*K4 -> 67768.768 | N4: =$K4+N23*L4 -> 65834.541
A5: Expenses | B5: =SUM('Data Sheet'!B18,'Data Sheet'!B20:B24, -1*'Data Sheet'!B19) -> 26834 | C5: =SUM('Data Sheet'!C18,'Data Sheet'!C20:C24, -1*'Data Sheet'!C19) -> 28046 | D5: =SUM('Data Sheet'!D18,'Data Sheet'!D20:D24, -1*'Data Sheet'!D19) -> 30430 | E5: =SUM('Data Sheet'!E18,'Data Sheet'!E20:E24, -1*'Data Sheet'!E19) -> 29922 | F5: =SUM('Data Sheet'!F18,'Data Sheet'!F20:F24, -1*'Data Sheet'!F19) -> 35402 | G5: =SUM('Data Sheet'!G18,'Data Sheet'!G20:G24, -1*'Data Sheet'!G19) -> 39589 | H5: =SUM('Data Sheet'!H18,'Data Sheet'!H20:H24, -1*'Data Sheet'!H19) -> 46433 | I5: =SUM('Data Sheet'!I18,'Data Sheet'!I20:I24, -1*'Data Sheet'!I19) -> 47237 | ... K5: =SUM('Data Sheet'!K18,'Data Sheet'!K20:K24, -1*'Data Sheet'!K19) -> 49429 | L5: =SUM(Quarters!H5:K5) -> 50108 | M5: =M4-M6 -> 51738.984 | N5: =N4-N6 -> 50576.269
A6: Operating Profit | B6: =B4-B5 -> 6328 | C6: =C4-C5 -> 7499 | D6: =D4-D5 -> 8880 | E6: =E4-E5 -> 9861 | F6: =F4-F5 -> 11626 | G6: =G4-G5 -> 12857 | H6: =H4-H5 -> 14147 | I6: =I4-I5 -> 14659 | ... K6: =K4-K5 -> 15039 | L6: =SUM(Quarters!H6:K6) -> 15117 | M6: =M4*M24 -> 16029.784 | N6: =N4*N24 -> 15258.271
A7: Other Income | B7: ='Data Sheet'!B25 -> 606 | C7: ='Data Sheet'!C25 -> 353 | D7: ='Data Sheet'!D25 -> 322 | E7: ='Data Sheet'!E25 -> 424 | F7: ='Data Sheet'!F25 -> 170 | G7: ='Data Sheet'!G25 -> 219 | H7: ='Data Sheet'!H25 -> 448 | I7: ='Data Sheet'!I25 -> 817 | ... K7: ='Data Sheet'!K25 -> 4923 | L7: =SUM(Quarters!H7:K7) -> 4894 | M7: 0 | N7: 0
A8: Depreciation | B8: ='Data Sheet'!B26 -> 432 | C8: ='Data Sheet'!C26 -> 520 | D8: ='Data Sheet'!D26 -> 565 | E8: ='Data Sheet'!E26 -> 1002 | F8: ='Data Sheet'!F26 -> 1074 | G8: ='Data Sheet'!G26 -> 1091 | H8: ='Data Sheet'!H26 -> 1137 | I8: ='Data Sheet'!I26 -> 1216 | ... K8: ='Data Sheet'!K26 -> 1333 | L8: =SUM(Quarters!H8:K8) -> 1368 | M8: =+$L8 -> 1368 | N8: =+$L8 -> 1368
A9: Interest | B9: ='Data Sheet'!B27 -> 35 | C9: ='Data Sheet'!C27 -> 26 | D9: ='Data Sheet'!D27 -> 33 | E9: ='Data Sheet'!E27 -> 118 | F9: ='Data Sheet'!F27 -> 117 | G9: ='Data Sheet'!G27 -> 106 | H9: ='Data Sheet'!H27 -> 114 | I9: ='Data Sheet'!I27 -> 334 | ... K9: ='Data Sheet'!K27 -> 410 | L9: =SUM(Quarters!H9:K9) -> 415 | M9: =+$L9 -> 415 | N9: =+$L9 -> 415
A10: Profit before tax | B10: ='Data Sheet'!B28 -> 6467 | C10: ='Data Sheet'!C28 -> 7306 | D10: ='Data Sheet'!D28 -> 8604 | E10: ='Data Sheet'!E28 -> 9165 | F10: ='Data Sheet'!F28 -> 10605 | G10: ='Data Sheet'!G28 -> 11879 | H10: ='Data Sheet'!H28 -> 13344 | I10: ='Data Sheet'!I28 -> 13926 | ... K10: ='Data Sheet'!K28 -> 18219 | L10: =SUM(Quarters!H10:K10) -> 18228 | M10: =M6+M7-SUM(M8:M9) -> 14246.784 | N10: =N6+N7-SUM(N8:N9) -> 13475.271
A11: Tax | B11: ='Data Sheet'!B29 -> 1977 | C11: ='Data Sheet'!C29 -> 2079 | D11: ='Data Sheet'!D29 -> 2544 | E11: ='Data Sheet'!E29 -> 2409 | F11: ='Data Sheet'!F29 -> 2606 | G11: ='Data Sheet'!G29 -> 2987 | H11: ='Data Sheet'!H29 -> 3201 | I11: ='Data Sheet'!I29 -> 3644 | ... K11: ='Data Sheet'!K29 -> 3160 | L11: =SUM(Quarters!H11:K11) -> 3169 | M11: =IF($L10>0,$L11/$L10,0) -> 0.17385341 | N11: =IF($L10>0,$L11/$L10,0) -> 0.17385341
A12: Net profit | B12: ='Data Sheet'!B30 -> 4476 | C12: ='Data Sheet'!C30 -> 5214 | D12: ='Data Sheet'!D30 -> 6054 | E12: ='Data Sheet'!E30 -> 6748 | F12: ='Data Sheet'!F30 -> 7995 | G12: ='Data Sheet'!G30 -> 8879 | H12: ='Data Sheet'!H30 -> 10120 | I12: ='Data Sheet'!I30 -> 10277 | ... K12: ='Data Sheet'!K30 -> 15040 | L12: =SUM(Quarters!H12:K12) -> 15040 | M12: =M10-M11*M10 -> 11769.932 | N12: =N10-N11*N10 -> 11132.55
A13: EPS | B13: =IF('Data Sheet'!B93>0,B12/'Data Sheet'!B93,0) -> 20.681052 | C13: =IF('Data Sheet'!C93>0,C12/'Data Sheet'!C93,0) -> 24.088704 | D13: =IF('Data Sheet'!D93>0,D12/'Data Sheet'!D93,0) -> 27.966924 | E13: =IF('Data Sheet'!E93>0,E12/'Data Sheet'!E93,0) -> 31.171471 | F13: =IF('Data Sheet'!F93>0,F12/'Data Sheet'!F93,0) -> 34.027068 | G13: =IF('Data Sheet'!G93>0,G12/'Data Sheet'!G93,0) -> 37.789411 | H13: =IF('Data Sheet'!H93>0,H12/'Data Sheet'!H93,0) -> 43.071161 | I13: =IF('Data Sheet'!I93>0,I12/'Data Sheet'!I93,0) -> 43.73936 | ... K13: =IF('Data Sheet'!K93>0,K12/'Data Sheet'!K93,0) -> 64.010895 | L13: =IF('Data Sheet'!$B6>0,'Profit & Loss'!L12/'Data Sheet'!$B6,0) -> 64.011134 | M13: =IF('Data Sheet'!$B6>0,'Profit & Loss'!M12/'Data Sheet'!$B6,0) -> 50.093531 | N13: =IF('Data Sheet'!$B6>0,'Profit & Loss'!N12/'Data Sheet'!$B6,0) -> 47.380793
A14: Price to earning | B14: =IF(B15>0,B15/B13,"") -> 42.193696 | C14: =IF(C15>0,C15/C13,"") -> 52.975453 | D14: =IF(D15>0,D15/D13,"") -> 58.409356 | E14: =IF(E15>0,E15/E13,"") -> 70.571903 | F14: =IF(F15>0,F15/F13,"") -> 68.390258 | G14: =IF(G15>0,G15/G13,"") -> 51.884905 | H14: =IF(H15>0,H15/H13,"") -> 56.892824 | I14: =IF(I15>0,I15/I13,"") -> 49.546678 | ... K14: =IF(K15>0,K15/K13,"") -> 32.107034 | L14: =IF(L13>0,L15/L13,0) -> 33.491049 | M14: =M25 -> 40.711144 | N14: =N25 -> 33.491049
A15: Price | B15: ='Data Sheet'!B90 -> 872.61 | C15: ='Data Sheet'!C90 -> 1276.11 | D15: ='Data Sheet'!D90 -> 1633.53 | E15: ='Data Sheet'!E90 -> 2199.83 | F15: ='Data Sheet'!F90 -> 2327.12 | G15: ='Data Sheet'!G90 -> 1960.7 | H15: ='Data Sheet'!H90 -> 2450.44 | I15: ='Data Sheet'!I90 -> 2167.14 | ... K15: ='Data Sheet'!K90 -> 2055.2 | L15: ='Data Sheet'!B8 -> 2143.8 | M15: =M13*M14 -> 2039.3649 | N15: =N13*N14 -> 1586.8324
A17: RATIOS:
A18: Dividend Payout | B18: =IF('Data Sheet'!B30>0, 'Data Sheet'!B31/'Data Sheet'!B30, 0) -> 0.82037534 | C18: =IF('Data Sheet'!C30>0, 'Data Sheet'!C31/'Data Sheet'!C30, 0) -> 0.82853855 | D18: =IF('Data Sheet'!D30>0, 'Data Sheet'!D31/'Data Sheet'!D30, 0) -> 0.78493558 | E18: =IF('Data Sheet'!E30>0, 'Data Sheet'!E31/'Data Sheet'!E30, 0) -> 0.80023711 | F18: =IF('Data Sheet'!F30>0, 'Data Sheet'!F31/'Data Sheet'!F30, 0) -> 1.1904315 | G18: =IF('Data Sheet'!G30>0, 'Data Sheet'!G31/'Data Sheet'!G30, 0) -> 0.89987611 | H18: =IF('Data Sheet'!H30>0, 'Data Sheet'!H31/'Data Sheet'!H30, 0) -> 0.90563241 | I18: =IF('Data Sheet'!I30>0, 'Data Sheet'!I31/'Data Sheet'!I30, 0) -> 0.960397 | ... K18: =IF('Data Sheet'!K30>0, 'Data Sheet'!K31/'Data Sheet'!K30, 0) -> 0.640625
A19: OPM | B19: =IF(B6>0,B6/B4,0) -> 0.19082082 | C19: =IF(C6>0,C6/C4,0) -> 0.21097201 | D19: =IF(D6>0,D6/D4,0) -> 0.22589672 | E19: =IF(E6>0,E6/E4,0) -> 0.24786969 | F19: =IF(F6>0,F6/F4,0) -> 0.24721443 | G19: =IF(G6>0,G6/G4,0) -> 0.24514739 | H19: =IF(H6>0,H6/H4,0) -> 0.23352592 | I19: =IF(I6>0,I6/I4,0) -> 0.23683275 | ... L19: =IF(L6>0,L6/L4,0) -> 0.23176696
G22: TRENDS: | H22: 10 YEARS | I22: 7 YEARS | J22: 5 YEARS | K22: 3 YEARS | L22: RECENT | M22: BEST | N22: WORST
G23: Sales Growth | H23: =IF(B4=0,"",POWER($K4/B4,1/9)-1) -> 0.076658974 | I23: =IF(D4=0,"",POWER($K4/D4,1/7)-1) -> 0.073227008 | J23: =IF(F4=0,"",POWER($K4/F4,1/5)-1) -> 0.065117542 | K23: =IF(H4=0,"",POWER($K4/H4, 1/3)-1) -> 0.020951182 | L23: =IF(ISERROR(MAX(IF(J4=0,"",(K4-J4)/J4),IF(K4=0,"",(L4-K4)/K4))),"",MAX(IF(J4=0,"",(K4-J4)/J4),IF(K4=0,"",(L4-K4)/K4))) -> 0.051200104 | M23: =MAX(K23:L23) -> 0.051200104 | N23: =MIN(H23:L23) -> 0.020951182
G24: OPM | H24: =IF(SUM(B4:$K$4)=0,"",SUMPRODUCT(B19:$K$19,B4:$K$4)/SUM(B4:$K$4)) -> 0.23326593 | I24: =IF(SUM(E4:$K$4)=0,"",SUMPRODUCT(E19:$K$19,E4:$K$4)/SUM(E4:$K$4)) -> 0.23969045 | J24: =IF(SUM(G4:$K$4)=0,"",SUMPRODUCT(G19:$K$19,G4:$K$4)/SUM(G4:$K$4)) -> 0.23743175 | K24: =IF(SUM(I4:$K$4)=0, "", SUMPRODUCT(I19:$K$19,I4:$K$4)/SUM(I4:$K$4)) -> 0.23653645 | L24: =L19 -> 0.23176696 | M24: =MAX(K24:L24) -> 0.23653645 | N24: =MIN(H24:L24) -> 0.23176696
G25: Price to Earning | H25: =IF(ISERROR(AVERAGEIF(B14:$L14,">0")),"",AVERAGEIF(B14:$L14,">0")) -> 51.287543 | I25: =IF(ISERROR(AVERAGEIF(E14:$L14,">0")),"",AVERAGEIF(E14:$L14,">0")) -> 51.323058 | J25: =IF(ISERROR(AVERAGEIF(G14:$L14,">0")),"",AVERAGEIF(G14:$L14,">0")) -> 45.270384 | K25: =IF(ISERROR(AVERAGEIF(I14:$L14,">0")),"",AVERAGEIF(I14:$L14,">0")) -> 40.711144 | L25: =L14 -> 33.491049 | M25: =MAX(K25:L25) -> 40.711144 | N25: =MIN(H25:L25) -> 33.491049

Sheet Quarters
A1: ='Profit & Loss'!A1 -> HINDUSTAN UNILEVER LTD | E1: =UPDATE | J1: SCREENER.IN
A3: Narration | B3: ='Data Sheet'!B41 -> 45291 | C3: ='Data Sheet'!C41 -> 45382 | D3: ='Data Sheet'!D41 -> 45473 | E3: ='Data Sheet'!E41 -> 45565 | F3: ='Data Sheet'!F41 -> 45657 | G3: ='Data Sheet'!G41 -> 45747 | H3: ='Data Sheet'!H41 -> 45838 | I3: ='Data Sheet'!I41 -> 45930 | ... K3: ='Data Sheet'!K41 -> 46112
A4: Sales | B4: ='Data Sheet'!B42 -> 15567 | C4: ='Data Sheet'!C42 -> 15210 | D4: ='Data Sheet'!D42 -> 15707 | E4: ='Data Sheet'!E42 -> 15926 | F4: ='Data Sheet'!F42 -> 15556 | G4: ='Data Sheet'!G42 -> 15190 | H4: ='Data Sheet'!H42 -> 16514 | I4: ='Data Sheet'!I42 -> 15919 | ... K4: ='Data Sheet'!K42 -> 16351
A5: Expenses | B5: ='Data Sheet'!B43 -> 11902 | C5: ='Data Sheet'!C43 -> 11675 | D5: ='Data Sheet'!D43 -> 11965 | E5: ='Data Sheet'!E43 -> 12139 | F5: ='Data Sheet'!F43 -> 11867 | G5: ='Data Sheet'!G43 -> 11572 | H5: ='Data Sheet'!H43 -> 12797 | I5: ='Data Sheet'!I43 -> 12137 | ... K5: ='Data Sheet'!K43 -> 12514
A6: Operating Profit | B6: ='Data Sheet'!B50 -> 3665 | C6: ='Data Sheet'!C50 -> 3535 | D6: ='Data Sheet'!D50 -> 3742 | E6: ='Data Sheet'!E50 -> 3787 | F6: ='Data Sheet'!F50 -> 3689 | G6: ='Data Sheet'!G50 -> 3618 | H6: ='Data Sheet'!H50 -> 3717 | I6: ='Data Sheet'!I50 -> 3782 | ... K6: ='Data Sheet'!K50 -> 3837
A7: Other Income | B7: ='Data Sheet'!B44 -> 184 | C7: ='Data Sheet'!C44 -> 309 | D7: ='Data Sheet'!D44 -> 209 | E7: ='Data Sheet'!E44 -> 203 | F7: ='Data Sheet'!F44 -> 733 | G7: ='Data Sheet'!G44 -> 149 | H7: ='Data Sheet'!H44 -> 74 | I7: ='Data Sheet'!I44 -> 269 | ... K7: ='Data Sheet'!K44 -> 503
A8: Depreciation | B8: ='Data Sheet'!B45 -> 313 | C8: ='Data Sheet'!C45 -> 320 | D8: ='Data Sheet'!D45 -> 329 | E8: ='Data Sheet'!E45 -> 338 | F8: ='Data Sheet'!F45 -> 318 | G8: ='Data Sheet'!G45 -> 318 | H8: ='Data Sheet'!H45 -> 361 | I8: ='Data Sheet'!I45 -> 322 | ... K8: ='Data Sheet'!K45 -> 348
A9: Interest | B9: ='Data Sheet'!B46 -> 91 | C9: ='Data Sheet'!C46 -> 105 | D9: ='Data Sheet'!D46 -> 93 | E9: ='Data Sheet'!E46 -> 110 | F9: ='Data Sheet'!F46 -> 109 | G9: ='Data Sheet'!G46 -> 77 | H9: ='Data Sheet'!H46 -> 127 | I9: ='Data Sheet'!I46 -> 124 | ... K9: ='Data Sheet'!K46 -> 76
A10: Profit before tax | B10: ='Data Sheet'!B47 -> 3445 | C10: ='Data Sheet'!C47 -> 3419 | D10: ='Data Sheet'!D47 -> 3529 | E10: ='Data Sheet'!E47 -> 3542 | F10: ='Data Sheet'!F47 -> 3995 | G10: ='Data Sheet'!G47 -> 3372 | H10: ='Data Sheet'!H47 -> 3303 | I10: ='Data Sheet'!I47 -> 3605 | ... K10: ='Data Sheet'!K47 -> 3916
A11: Tax | B11: ='Data Sheet'!B48 -> 937 | C11: ='Data Sheet'!C48 -> 858 | D11: ='Data Sheet'!D48 -> 917 | E11: ='Data Sheet'!E48 -> 947 | F11: ='Data Sheet'!F48 -> 1006 | G11: ='Data Sheet'!G48 -> 897 | H11: ='Data Sheet'!H48 -> 535 | I11: ='Data Sheet'!I48 -> 911 | ... K11: ='Data Sheet'!K48 -> 922
A12: Net profit | B12: ='Data Sheet'!B49 -> 2509 | C12: ='Data Sheet'!C49 -> 2558 | D12: ='Data Sheet'!D49 -> 2610 | E12: ='Data Sheet'!E49 -> 2591 | F12: ='Data Sheet'!F49 -> 2984 | G12: ='Data Sheet'!G49 -> 2464 | H12: ='Data Sheet'!H49 -> 2756 | I12: ='Data Sheet'!I49 -> 2685 | ... K12: ='Data Sheet'!K49 -> 2992
A14: OPM | B14: =IF(B4>0,B6/B4,"") -> 0.23543393 | C14: =IF(C4>0,C6/C4,"") -> 0.23241289 | D14: =IF(D4>0,D6/D4,"") -> 0.23823773 | E14: =IF(E4>0,E6/E4,"") -> 0.23778727 | F14: =IF(F4>0,F6/F4,"") -> 0.23714322 | G14: =IF(G4>0,G6/G4,"") -> 0.23818302 | H14: =IF(H4>0,H6/H4,"") -> 0.22508175 | I14: =IF(I4>0,I6/I4,"") -> 0.23757774 | ... K14: =IF(K4>0,K6/K4,"") -> 0.23466455

Sheet Balance Sheet
A1: ='Profit & Loss'!A1 -> HINDUSTAN UNILEVER LTD | E1: =UPDATE | J1: SCREENER.IN
A3: Narration | B3: ='Data Sheet'!B56 -> 42825 | C3: ='Data Sheet'!C56 -> 43190 | D3: ='Data Sheet'!D56 -> 43555 | E3: ='Data Sheet'!E56 -> 43921 | F3: ='Data Sheet'!F56 -> 44286 | G3: ='Data Sheet'!G56 -> 44651 | H3: ='Data Sheet'!H56 -> 45016 | I3: ='Data Sheet'!I56 -> 45382 | ... K3: ='Data Sheet'!K56 -> 46112
A4: Equity Share Capital | B4: ='Data Sheet'!B57 -> 216 | C4: ='Data Sheet'!C57 -> 216 | D4: ='Data Sheet'!D57 -> 216 | E4: ='Data Sheet'!E57 -> 216 | F4: ='Data Sheet'!F57 -> 235 | G4: ='Data Sheet'!G57 -> 235 | H4: ='Data Sheet'!H57 -> 235 | I4: ='Data Sheet'!I57 -> 235 | ... K4: ='Data Sheet'!K57 -> 235
A5: Reserves | B5: ='Data Sheet'!B58 -> 6528 | C5: ='Data Sheet'!C58 -> 7065 | D5: ='Data Sheet'!D58 -> 7651 | E5: ='Data Sheet'!E58 -> 8013 | F5: ='Data Sheet'!F58 -> 47439 | G5: ='Data Sheet'!G58 -> 48826 | H5: ='Data Sheet'!H58 -> 50069 | I5: ='Data Sheet'!I58 -> 50983 | ... K5: ='Data Sheet'!K58 -> 48504
A6: Borrowings | B6: ='Data Sheet'!B59 -> 277 | C6: ='Data Sheet'!C59 -> 0 | D6: ='Data Sheet'!D59 -> 99 | E6: ='Data Sheet'!E59 -> 0 | F6: ='Data Sheet'!F59 -> 0 | G6: ='Data Sheet'!G59 -> 1043 | H6: ='Data Sheet'!H59 -> 1219 | I6: ='Data Sheet'!I59 -> 1484 | ... K6: ='Data Sheet'!K59 -> 1478
A7: Other Liabilities | B7: ='Data Sheet'!B60 -> 8685 | C7: ='Data Sheet'!C60 -> 10581 | D7: ='Data Sheet'!D60 -> 10663 | E7: ='Data Sheet'!E60 -> 11924 | F7: ='Data Sheet'!F60 -> 21066 | G7: ='Data Sheet'!G60 -> 20402 | H7: ='Data Sheet'!H60 -> 21554 | I7: ='Data Sheet'!I60 -> 25787 | ... K7: ='Data Sheet'!K60 -> 29521
A8: Total | B8: ='Data Sheet'!B61 -> 15706 | C8: ='Data Sheet'!C61 -> 17862 | D8: ='Data Sheet'!D61 -> 18629 | E8: ='Data Sheet'!E61 -> 20153 | F8: ='Data Sheet'!F61 -> 68740 | G8: ='Data Sheet'!G61 -> 70506 | H8: ='Data Sheet'!H61 -> 73077 | I8: ='Data Sheet'!I61 -> 78489 | ... K8: ='Data Sheet'!K61 -> 79738
A10: Net Block | B10: ='Data Sheet'!B62 -> 4419 | C10: ='Data Sheet'!C62 -> 4528 | D10: ='Data Sheet'!D62 -> 4715 | E10: ='Data Sheet'!E62 -> 5479 | F10: ='Data Sheet'!F62 -> 51443 | G10: ='Data Sheet'!G62 -> 51473 | H10: ='Data Sheet'!H62 -> 52678 | I10: ='Data Sheet'!I62 -> 53744 | ... K10: ='Data Sheet'!K62 -> 57428
A11: Capital Work in Progress | B11: ='Data Sheet'!B63 -> 229 | C11: ='Data Sheet'!C63 -> 461 | D11: ='Data Sheet'!D63 -> 406 | E11: ='Data Sheet'!E63 -> 597 | F11: ='Data Sheet'!F63 -> 745 | G11: ='Data Sheet'!G63 -> 1313 | H11: ='Data Sheet'!H63 -> 1132 | I11: ='Data Sheet'!I63 -> 1025 | ... K11: ='Data Sheet'!K63 -> 880
A12: Investments | B12: ='Data Sheet'!B64 -> 3794 | C12: ='Data Sheet'!C64 -> 2873 | D12: ='Data Sheet'!D64 -> 2716 | E12: ='Data Sheet'!E64 -> 1255 | F12: ='Data Sheet'!F64 -> 2709 | G12: ='Data Sheet'!G64 -> 3521 | H12: ='Data Sheet'!H64 -> 2882 | I12: ='Data Sheet'!I64 -> 4625 | ... K12: ='Data Sheet'!K64 -> 4359
A13: Other Assets | B13: ='Data Sheet'!B65 -> 7264 | C13: ='Data Sheet'!C65 -> 10000 | D13: ='Data Sheet'!D65 -> 10792 | E13: ='Data Sheet'!E65 -> 12822 | F13: ='Data Sheet'!F65 -> 13843 | G13: ='Data Sheet'!G65 -> 14199 | H13: ='Data Sheet'!H65 -> 16385 | I13: ='Data Sheet'!I65 -> 19095 | ... K13: ='Data Sheet'!K65 -> 17071
A14: Total | B14: ='Data Sheet'!B66 -> 15706 | C14: ='Data Sheet'!C66 -> 17862 | D14: ='Data Sheet'!D66 -> 18629 | E14: ='Data Sheet'!E66 -> 20153 | F14: ='Data Sheet'!F66 -> 68740 | G14: ='Data Sheet'!G66 -> 70506 | H14: ='Data Sheet'!H66 -> 73077 | I14: ='Data Sheet'!I66 -> 78489 | ... K14: ='Data Sheet'!K66 -> 79738
A16: Working Capital | B16: =B13-B7 -> -1421 | C16: =C13-C7 -> -581 | D16: =D13-D7 -> 129 | E16: =E13-E7 -> 898 | F16: =F13-F7 -> -7223 | G16: =G13-G7 -> -6203 | H16: =H13-H7 -> -5169 | I16: =I13-I7 -> -6692 | ... K16: =K13-K7 -> -12450
A17: Debtors | B17: ='Data Sheet'!B67 -> 1085 | C17: ='Data Sheet'!C67 -> 1310 | D17: ='Data Sheet'!D67 -> 1816 | E17: ='Data Sheet'!E67 -> 1149 | F17: ='Data Sheet'!F67 -> 1758 | G17: ='Data Sheet'!G67 -> 2236 | H17: ='Data Sheet'!H67 -> 3079 | I17: ='Data Sheet'!I67 -> 2997 | ... K17: ='Data Sheet'!K67 -> 3379
A18: Inventory | B18: ='Data Sheet'!B68 -> 2541 | C18: ='Data Sheet'!C68 -> 2513 | D18: ='Data Sheet'!D68 -> 2574 | E18: ='Data Sheet'!E68 -> 2767 | F18: ='Data Sheet'!F68 -> 3579 | G18: ='Data Sheet'!G68 -> 4096 | H18: ='Data Sheet'!H68 -> 4251 | I18: ='Data Sheet'!I68 -> 4022 | ... K18: ='Data Sheet'!K68 -> 4789
A20: Debtor Days | B20: =IF('Profit & Loss'!B4>0,'Balance Sheet'!B17/('Profit & Loss'!B4/365),0) -> 11.942133 | C20: =IF('Profit & Loss'!C4>0,'Balance Sheet'!C17/('Profit & Loss'!C4/365),0) -> 13.451962 | D20: =IF('Profit & Loss'!D4>0,'Balance Sheet'!D17/('Profit & Loss'!D4/365),0) -> 16.861867 | E20: =IF('Profit & Loss'!E4>0,'Balance Sheet'!E17/('Profit & Loss'!E4/365),0) -> 10.541814 | F20: =IF('Profit & Loss'!F4>0,'Balance Sheet'!F17/('Profit & Loss'!F4/365),0) -> 13.644425 | G20: =IF('Profit & Loss'!G4>0,'Balance Sheet'!G17/('Profit & Loss'!G4/365),0) -> 15.56153 | H20: =IF('Profit & Loss'!H4>0,'Balance Sheet'!H17/('Profit & Loss'!H4/365),0) -> 18.551255 | I20: =IF('Profit & Loss'!I4>0,'Balance Sheet'!I17/('Profit & Loss'!I4/365),0) -> 17.673275 | ... K20: =IF('Profit & Loss'!K4>0,'Balance Sheet'!K17/('Profit & Loss'!K4/365),0) -> 19.130964
A21: Inventory Turnover | B21: =IF('Balance Sheet'!B18>0,'Profit & Loss'!B4/'Balance Sheet'!B18,0) -> 13.050767 | C21: =IF('Balance Sheet'!C18>0,'Profit & Loss'!C4/'Balance Sheet'!C18,0) -> 14.144449 | D21: =IF('Balance Sheet'!D18>0,'Profit & Loss'!D4/'Balance Sheet'!D18,0) -> 15.27195 | E21: =IF('Balance Sheet'!E18>0,'Profit & Loss'!E4/'Balance Sheet'!E18,0) -> 14.377665 | F21: =IF('Balance Sheet'!F18>0,'Profit & Loss'!F4/'Balance Sheet'!F18,0) -> 13.139983 | G21: =IF('Balance Sheet'!G18>0,'Profit & Loss'!G4/'Balance Sheet'!G18,0) -> 12.804199 | H21: =IF('Balance Sheet'!H18>0,'Profit & Loss'!H4/'Balance Sheet'!H18,0) -> 14.250765 | I21: =IF('Balance Sheet'!I18>0,'Profit & Loss'!I4/'Balance Sheet'!I18,0) -> 15.389359 | ... K21: =IF('Balance Sheet'!K18>0,'Profit & Loss'!K4/'Balance Sheet'!K18,0) -> 13.461683
A23: Return on Equity | B23: =IF(SUM('Balance Sheet'!B4:B5)>0,'Profit & Loss'!B12/SUM('Balance Sheet'!B4:B5),"") -> 0.66370107 | C23: =IF(SUM('Balance Sheet'!C4:C5)>0,'Profit & Loss'!C12/SUM('Balance Sheet'!C4:C5),"") -> 0.71611042 | D23: =IF(SUM('Balance Sheet'!D4:D5)>0,'Profit & Loss'!D12/SUM('Balance Sheet'!D4:D5),"") -> 0.76954366 | E23: =IF(SUM('Balance Sheet'!E4:E5)>0,'Profit & Loss'!E12/SUM('Balance Sheet'!E4:E5),"") -> 0.82002673 | F23: =IF(SUM('Balance Sheet'!F4:F5)>0,'Profit & Loss'!F12/SUM('Balance Sheet'!F4:F5),"") -> 0.16770147 | G23: =IF(SUM('Balance Sheet'!G4:G5)>0,'Profit & Loss'!G12/SUM('Balance Sheet'!G4:G5),"") -> 0.18097878 | H23: =IF(SUM('Balance Sheet'!H4:H5)>0,'Profit & Loss'!H12/SUM('Balance Sheet'!H4:H5),"") -> 0.20117684 | I23: =IF(SUM('Balance Sheet'!I4:I5)>0,'Profit & Loss'!I12/SUM('Balance Sheet'!I4:I5),"") -> 0.20065211 | ... K23: =IF(SUM('Balance Sheet'!K4:K5)>0,'Profit & Loss'!K12/SUM('Balance Sheet'!K4:K5),"") -> 0.30858245
A24: Return on Capital Emp | C24: =IF((B4+B5+B6+C4+C5+C6)>0,('Profit & Loss'!C10+'Profit & Loss'!C9)*2/(B4+B5+B6+C4+C5+C6),"") -> 1.0253111 | D24: =IF((C4+C5+C6+D4+D5+D6)>0,('Profit & Loss'!D10+'Profit & Loss'!D9)*2/(C4+C5+C6+D4+D5+D6),"") -> 1.1329442 | E24: =IF((D4+D5+D6+E4+E5+E6)>0,('Profit & Loss'!E10+'Profit & Loss'!E9)*2/(D4+D5+D6+E4+E5+E6),"") -> 1.1464032 | F24: =IF((E4+E5+E6+F4+F5+F6)>0,('Profit & Loss'!F10+'Profit & Loss'!F9)*2/(E4+E5+E6+F4+F5+F6),"") -> 0.38359301 | G24: =IF((F4+F5+F6+G4+G5+G6)>0,('Profit & Loss'!G10+'Profit & Loss'!G9)*2/(F4+F5+F6+G4+G5+G6),"") -> 0.24514717 | H24: =IF((G4+G5+G6+H4+H5+H6)>0,('Profit & Loss'!H10+'Profit & Loss'!H9)*2/(G4+G5+G6+H4+H5+H6),"") -> 0.26485088 | I24: =IF((H4+H5+H6+I4+I5+I6)>0,('Profit & Loss'!I10+'Profit & Loss'!I9)*2/(H4+H5+H6+I4+I5+I6),"") -> 0.27363876 | J24: =IF((I4+I5+I6+J4+J5+J6)>0,('Profit & Loss'!J10+'Profit & Loss'!J9)*2/(I4+I5+I6+J4+J5+J6),"") -> 0.28529571 | K24: =IF((J4+J5+J6+K4+K5+K6)>0,('Profit & Loss'!K10+'Profit & Loss'!K9)*2/(J4+J5+J6+K4+K5+K6),"") -> 0.36791847

Sheet Cash Flow
A1: ='Balance Sheet'!A1 -> HINDUSTAN UNILEVER LTD | E1: =UPDATE | J1: SCREENER.IN
A3: Narration | B3: ='Data Sheet'!B81 -> 42825 | C3: ='Data Sheet'!C81 -> 43190 | D3: ='Data Sheet'!D81 -> 43555 | E3: ='Data Sheet'!E81 -> 43921 | F3: ='Data Sheet'!F81 -> 44286 | G3: ='Data Sheet'!G81 -> 44651 | H3: ='Data Sheet'!H81 -> 45016 | I3: ='Data Sheet'!I81 -> 45382 | ... K3: ='Data Sheet'!K81 -> 46112
A4: Cash from Operating Activity | B4: ='Data Sheet'!B82 -> 5185 | C4: ='Data Sheet'!C82 -> 6059 | D4: ='Data Sheet'!D82 -> 5800 | E4: ='Data Sheet'!E82 -> 7623 | F4: ='Data Sheet'!F82 -> 9163 | G4: ='Data Sheet'!G82 -> 9048 | H4: ='Data Sheet'!H82 -> 9991 | I4: ='Data Sheet'!I82 -> 15469 | ... K4: ='Data Sheet'!K82 -> 10999
A5: Cash from Investing Activity | B5: ='Data Sheet'!B83 -> -1173 | C5: ='Data Sheet'!C83 -> -1063 | D5: ='Data Sheet'!D83 -> -438 | E5: ='Data Sheet'!E83 -> 1791 | F5: ='Data Sheet'!F83 -> -1228 | G5: ='Data Sheet'!G83 -> -1728 | H5: ='Data Sheet'!H83 -> -1484 | I5: ='Data Sheet'!I83 -> -5324 | ... K5: ='Data Sheet'!K83 -> -3676
A6: Cash from Financing Activity | B6: ='Data Sheet'!B84 -> -4214 | C6: ='Data Sheet'!C84 -> -4975 | D6: ='Data Sheet'!D84 -> -5390 | E6: ='Data Sheet'!E84 -> -6819 | F6: ='Data Sheet'!F84 -> -9309 | G6: ='Data Sheet'!G84 -> -8015 | H6: ='Data Sheet'!H84 -> -8953 | I6: ='Data Sheet'!I84 -> -10034 | ... K6: ='Data Sheet'!K84 -> -10810
A7: Net Cash Flow | B7: ='Data Sheet'!B85 -> -202 | C7: ='Data Sheet'!C85 -> 21 | D7: ='Data Sheet'!D85 -> -28 | E7: ='Data Sheet'!E85 -> 2595 | F7: ='Data Sheet'!F85 -> -1374 | G7: ='Data Sheet'!G85 -> -695 | H7: ='Data Sheet'!H85 -> -446 | I7: ='Data Sheet'!I85 -> 111 | ... K7: ='Data Sheet'!K85 -> -3487

Sheet Customization
A1: How to use it?
A3: You can customize this workbook as you want.
B4: You can add custom formating, add conditional formating, add your own formulas… do ANYTHING.
B5: Please don't edit the "Data Sheet" only.
A7: After customization, you can upload this back on Screener.
