Workbook
Name UPDATE: 'Data Sheet'!$E$1

Sheet FINANCIALS
B2: ="HISTORICAL FINANCIAL STATEMENT - "&'Data Sheet'!B1 -> HISTORICAL FINANCIAL STATEMENT - WIPRO LTD
B3: YEARS | C3: ='Data Sheet'!B16 -> 42825 | D3: ='Data Sheet'!C16 -> 43190 | E3: ='Data Sheet'!D16 -> 43555 | F3: ='Data Sheet'!E16 -> 43921 | G3: ='Data Sheet'!F16 -> 44286 | H3: ='Data Sheet'!G16 -> 44651 | I3: ='Data Sheet'!H16 -> 45016 | J3: ='Data Sheet'!I16 -> 45382 | ... L3: ='Data Sheet'!K16 -> 46112 | M3: LTM
A4: # | B4: INCOME STATEMENT (IN CRORES)
B5: SALES | C5: =IFERROR('Data Sheet'!B17,0) -> 55448.4 | D5: =IFERROR('Data Sheet'!C17,0) -> 54487.1 | E5: =IFERROR('Data Sheet'!D17,0) -> 59018.9 | F5: =IFERROR('Data Sheet'!E17,0) -> 61137.6 | G5: =IFERROR('Data Sheet'!F17,0) -> 61934.9 | H5: =IFERROR('Data Sheet'!G17,0) -> 79312 | I5: =IFERROR('Data Sheet'!H17,0) -> 90487.6 | J5: =IFERROR('Data Sheet'!I17,0) -> 89760.3 | ... L5: =IFERROR('Data Sheet'!K17,0) -> 92624 | M5: =IFERROR(SUM('Data Sheet'!H42:K42),0) -> 94968
B6: SALES GROWTH | C6: - | D6: =D5/C5-1 -> -0.017336839 | E6: =E5/D5-1 -> 0.08317198 | F6: =F5/E5-1 -> 0.03589867 | G6: =G5/F5-1 -> 0.013041075 | H6: =H5/G5-1 -> 0.28057041 | I6: =I5/H5-1 -> 0.1409068 | J6: =J5/I5-1 -> -0.0080375654 | K6: =K5/J5-1 -> -0.0074854919 | ... M6: =M5/L5-1 -> 0.025306616
B8: COGS | C8: =IFERROR(SUM('Data Sheet'!B18,'Data Sheet'!B20,'Data Sheet'!B21,'Data Sheet'!B22-1*'Data Sheet'!B19),0) -> 29505.2 | D8: =IFERROR(SUM('Data Sheet'!C18,'Data Sheet'!C20,'Data Sheet'!C21,'Data Sheet'!C22-1*'Data Sheet'!C19),0) -> 29116.2 | E8: =IFERROR(SUM('Data Sheet'!D18,'Data Sheet'!D20,'Data Sheet'!D21,'Data Sheet'!D22-1*'Data Sheet'!D19),0) -> 31317.4 | F8: =IFERROR(SUM('Data Sheet'!E18,'Data Sheet'!E20,'Data Sheet'!E21,'Data Sheet'!E22-1*'Data Sheet'!E19),0) -> 33795.3 | G8: =IFERROR(SUM('Data Sheet'!F18,'Data Sheet'!F20,'Data Sheet'!F21,'Data Sheet'!F22-1*'Data Sheet'!F19),0) -> 33964.3 | H8: =IFERROR(SUM('Data Sheet'!G18,'Data Sheet'!G20,'Data Sheet'!G21,'Data Sheet'!G22-1*'Data Sheet'!G19),0) -> 46972 | I8: =IFERROR(SUM('Data Sheet'!H18,'Data Sheet'!H20,'Data Sheet'!H21,'Data Sheet'!H22-1*'Data Sheet'!H19),0) -> 56300.5 | J8: =IFERROR(SUM('Data Sheet'!I18,'Data Sheet'!I20,'Data Sheet'!I21,'Data Sheet'!I22-1*'Data Sheet'!I19),0) -> 57178.9 | ... L8: =IFERROR(SUM('Data Sheet'!K18,'Data Sheet'!K20,'Data Sheet'!K21,'Data Sheet'!K22-1*'Data Sheet'!K19),0) -> 58350.1 | M8: =IFERROR(SUM('Data Sheet'!H43:K43),0) -> 76757.2
B9: COGS % SALES | C9: =C8/C5 -> 0.53211995 | D9: =D8/D5 -> 0.53436869 | E9: =E8/E5 -> 0.53063341 | F9: =F8/F5 -> 0.5527744 | G9: =G8/G5 -> 0.5483871 | H9: =H8/H5 -> 0.59224329 | I9: =I8/I5 -> 0.62219022 | J9: =J8/J5 -> 0.6370177 | ... M9: =M8/M5 -> 0.80824278
B11: GROSS PROFIT | C11: =C5-C8 -> 25943.2 | D11: =D5-D8 -> 25370.9 | E11: =E5-E8 -> 27701.5 | F11: =F5-F8 -> 27342.3 | G11: =G5-G8 -> 27970.6 | H11: =H5-H8 -> 32340 | I11: =I5-I8 -> 34187.1 | J11: =J5-J8 -> 32581.4 | ... M11: =M5-M8 -> 18210.8
B12: GROSS PROFIT % SALES | C12: =C11/C5 -> 0.46788005 | D12: =D11/D5 -> 0.46563131 | E12: =E11/E5 -> 0.46936659 | F12: =F11/F5 -> 0.4472256 | G12: =G11/G5 -> 0.4516129 | H12: =H11/H5 -> 0.40775671 | I12: =I11/I5 -> 0.37780978 | J12: =J11/J5 -> 0.3629823 | ... M12: =M11/M5 -> 0.19175722
B14: SELLING &GENERAL EXPENSES | C14: =IFERROR(SUM('Data Sheet'!B23:B24),0) -> 14622.3 | D14: =IFERROR(SUM('Data Sheet'!C23:C24),0) -> 14983.8 | E14: =IFERROR(SUM('Data Sheet'!D23:D24),0) -> 16088.9 | F14: =IFERROR(SUM('Data Sheet'!E23:E24),0) -> 15000 | G14: =IFERROR(SUM('Data Sheet'!F23:F24),0) -> 13199.2 | H14: =IFERROR(SUM('Data Sheet'!G23:G24),0) -> 15655.8 | I14: =IFERROR(SUM('Data Sheet'!H23:H24),0) -> 17348.1 | J14: =IFERROR(SUM('Data Sheet'!I23:I24),0) -> 15828.9 | ... M14: =IFERROR(SUM('Data Sheet'!L23:L24),0) -> 0
B15: SG EXP % SALES | C15: =C14/C5 -> 0.26371004 | D15: =D14/D5 -> 0.2749972 | E15: =E14/E5 -> 0.27260589 | F15: =F14/F5 -> 0.2453482 | G15: =G14/G5 -> 0.21311409 | H15: =H14/H5 -> 0.1973951 | I15: =I14/I5 -> 0.19171798 | J15: =J14/J5 -> 0.17634634 | ... L15: =L14/L5 -> 0.17773687
B17: EBITDA | C17: =C11-C14 -> 11320.9 | D17: =D11-D14 -> 10387.1 | E17: =E11-E14 -> 11612.6 | F17: =F11-F14 -> 12342.3 | G17: =G11-G14 -> 14771.4 | H17: =H11-H14 -> 16684.2 | I17: =I11-I14 -> 16839 | J17: =J11-J14 -> 16752.5 | ... M17: =M11-M14 -> 18210.8
B18: EBITDA % SALES | C18: =C17/C5 -> 0.20417 | D18: =D17/D5 -> 0.19063411 | E18: =E17/E5 -> 0.1967607 | F18: =F17/F5 -> 0.2018774 | G18: =G17/G5 -> 0.23849881 | H18: =H17/H5 -> 0.21036161 | I18: =I17/I5 -> 0.1860918 | J18: =J17/J5 -> 0.18663596 | ... M18: =M17/M5 -> 0.19175722
B20: INTEREST | C20: =IFERROR('Data Sheet'!B27,0) -> 594.2 | D20: =IFERROR('Data Sheet'!C27,0) -> 583 | E20: =IFERROR('Data Sheet'!D27,0) -> 737.5 | F20: =IFERROR('Data Sheet'!E27,0) -> 732.8 | G20: =IFERROR('Data Sheet'!F27,0) -> 508.8 | H20: =IFERROR('Data Sheet'!G27,0) -> 532.5 | I20: =IFERROR('Data Sheet'!H27,0) -> 1007.7 | J20: =IFERROR('Data Sheet'!I27,0) -> 1255.2 | ... L20: =IFERROR('Data Sheet'!K27,0) -> 1457.7 | M20: =IFERROR(SUM('Data Sheet'!H46:K46),0) -> 1569.7
B21: INTEREST % SALES | C21: =C20/C5 -> 0.01071627 | D21: =D20/D5 -> 0.01069978 | E21: =E20/E5 -> 0.012495997 | F21: =F20/F5 -> 0.011986077 | G21: =G20/G5 -> 0.0082150774 | H21: =H20/H5 -> 0.0067139903 | I21: =I20/I5 -> 0.011136332 | J21: =J20/J5 -> 0.01398391 | ... M21: =M20/M5 -> 0.016528725
B23: DEPRECIATION | C23: =IFERROR('Data Sheet'!B26,0) -> 2310 | D23: =IFERROR('Data Sheet'!C26,0) -> 2111.7 | E23: =IFERROR('Data Sheet'!D26,0) -> 1946.7 | F23: =IFERROR('Data Sheet'!E26,0) -> 2085.5 | G23: =IFERROR('Data Sheet'!F26,0) -> 2763.4 | H23: =IFERROR('Data Sheet'!G26,0) -> 3077.8 | I23: =IFERROR('Data Sheet'!H26,0) -> 3340.2 | J23: =IFERROR('Data Sheet'!I26,0) -> 3407.1 | ... L23: =IFERROR('Data Sheet'!K26,0) -> 2910.7 | M23: =IFERROR(SUM('Data Sheet'!H45:K45),0) -> 3029.6
B24: DEPRECIATION% SALES | C24: =C23/C8 -> 0.078291284 | D24: =D23/D8 -> 0.072526635 | E24: =E23/E8 -> 0.062160333 | F24: =F23/F8 -> 0.061709764 | G24: =G23/G8 -> 0.081361901 | H24: =H23/H8 -> 0.065524142 | I24: =I23/I8 -> 0.05932807 | J24: =J23/J8 -> 0.059586666 | ... M24: =M23/M8 -> 0.039469913
B26: EARNINGS BEFORE TAX | C26: =IFERROR(C17-SUM(C20,C23),0) -> 8416.7 | D26: =IFERROR(D17-SUM(D20,D23),0) -> 7692.4 | E26: =IFERROR(E17-SUM(E20,E23),0) -> 8928.4 | F26: =IFERROR(F17-SUM(F20,F23),0) -> 9524 | G26: =IFERROR(G17-SUM(G20,G23),0) -> 11499.2 | H26: =IFERROR(H17-SUM(H20,H23),0) -> 13073.9 | I26: =IFERROR(I17-SUM(I20,I23),0) -> 12491.1 | J26: =IFERROR(J17-SUM(J20,J23),0) -> 12090.2 | ... M26: =IFERROR(M17-SUM(M20,M23),0) -> 13611.5
B27: EBT % SALES | C27: =C26/C5 -> 0.15179338 | D27: =D26/D5 -> 0.14117837 | E27: =E26/E5 -> 0.15128035 | F27: =F26/F5 -> 0.15577975 | G27: =G26/G5 -> 0.18566592 | H27: =H26/H5 -> 0.16484139 | I27: =I26/I5 -> 0.13804212 | J27: =J26/J5 -> 0.13469429 | ... M27: =M26/M5 -> 0.14332723
B29: TAX | C29: =IFERROR('Data Sheet'!B29,0) -> 2521.4 | D29: =IFERROR('Data Sheet'!C29,0) -> 2239.1 | E29: =IFERROR('Data Sheet'!D29,0) -> 2524.3 | F29: =IFERROR('Data Sheet'!E29,0) -> 2480.1 | G29: =IFERROR('Data Sheet'!F29,0) -> 3034.9 | H29: =IFERROR('Data Sheet'!G29,0) -> 2897.4 | I29: =IFERROR('Data Sheet'!H29,0) -> 3399.2 | J29: =IFERROR('Data Sheet'!I29,0) -> 3608.9 | ... L29: =IFERROR('Data Sheet'!K29,0) -> 4076.7 | M29: =IFERROR(SUM('Data Sheet'!H48:K48),0) -> 4133.1
B30: EFFECTIVE TAX RATE | C30: =C29/C26 -> 0.29957109 | D30: =D29/D26 -> 0.29107951 | E30: =E29/E26 -> 0.28272703 | F30: =F29/F26 -> 0.26040529 | G30: =G29/G26 -> 0.26392271 | H30: =H29/H26 -> 0.22161712 | I30: =I29/I26 -> 0.27212976 | J30: =J29/J26 -> 0.29849796 | ... M30: =M29/M26 -> 0.30364765
B32: NET PROFIT | C32: =C26-C29 -> 5895.3 | D32: =D26-D29 -> 5453.3 | E32: =E26-E29 -> 6404.1 | F32: =F26-F29 -> 7043.9 | G32: =G26-G29 -> 8464.3 | H32: =H26-H29 -> 10176.5 | I32: =I26-I29 -> 9091.9 | J32: =J26-J29 -> 8481.3 | ... M32: =M26-M29 -> 9478.4
B33: NET PROFIT % SALES | C33: =IFERROR(C32/C5,0) -> 0.10632047 | D33: =IFERROR(D32/D5,0) -> 0.10008424 | E33: =IFERROR(E32/E5,0) -> 0.10850931 | F33: =IFERROR(F32/F5,0) -> 0.11521388 | G33: =IFERROR(G32/G5,0) -> 0.13666447 | H33: =IFERROR(H32/H5,0) -> 0.12830971 | I33: =IFERROR(I32/I5,0) -> 0.10047675 | J33: =IFERROR(J32/J5,0) -> 0.094488321 | ... M33: =IFERROR(M32/M5,0) -> 0.099806251
B35: NO OF EQUITY SHARES | C35: =IFERROR('Data Sheet'!B93,0) -> 1296.48 | D35: =IFERROR('Data Sheet'!C93,0) -> 1206.35 | E35: =IFERROR('Data Sheet'!D93,0) -> 1206.79 | F35: =IFERROR('Data Sheet'!E93,0) -> 1142.67 | G35: =IFERROR('Data Sheet'!F93,0) -> 1095.83 | H35: =IFERROR('Data Sheet'!G93,0) -> 1096.41 | I35: =IFERROR('Data Sheet'!H93,0) -> 1097.58 | J35: =IFERROR('Data Sheet'!I93,0) -> 1045.03 | ... M35: =IFERROR('Data Sheet'!L93,0) -> 0
B37: EPS | C37: =IFERROR(C32/C35,0) -> 4.5471585 | D37: =IFERROR(D32/D35,0) -> 4.5204957 | E37: =IFERROR(E32/E35,0) -> 5.3067228 | F37: =IFERROR(F32/F35,0) -> 6.1644219 | G37: =IFERROR(G32/G35,0) -> 7.7240995 | H37: =IFERROR(H32/H35,0) -> 9.2816556 | I37: =IFERROR(I32/I35,0) -> 8.2835875 | J37: =IFERROR(J32/J35,0) -> 8.1158436 | ... M37: =IFERROR(M32/M35,0) -> 0
B38: EPS GROWTH % | D38: =IFERROR(D37/C37-1,0) -> -0.0058636069 | E38: =E37/D37-1 -> 0.17392497 | F38: =F37/E37-1 -> 0.16162501 | G38: =G37/F37-1 -> 0.25301279 | H38: =H37/G37-1 -> 0.20164888 | I38: =I37/H37-1 -> -0.10753125 | J38: =J37/I37-1 -> -0.020250159 | K38: =K37/J37-1 -> 0.095259227 | L38: =L37/K37-1 -> 0.0046133859 | M38: =M37/L37-1 -> -1
B40: DIVIDEND PER SHARE | C40: =IFERROR('Data Sheet'!B31/FINANCIALS!C35,0) -> 0.37493829 | D40: =IFERROR('Data Sheet'!C31/FINANCIALS!D35,0) -> 0.37501554 | E40: =IFERROR('Data Sheet'!D31/FINANCIALS!E35,0) -> 0.50000414 | F40: =IFERROR('Data Sheet'!E31/FINANCIALS!F35,0) -> 0.50001313 | G40: =IFERROR('Data Sheet'!F31/FINANCIALS!G35,0) -> 0.49998631 | H40: =IFERROR('Data Sheet'!G31/FINANCIALS!H35,0) -> 2.9999726 | I40: =IFERROR('Data Sheet'!H31/FINANCIALS!I35,0) -> 0.50000911 | J40: =IFERROR('Data Sheet'!I31/FINANCIALS!J35,0) -> 0.49998565 | ... M40: =IFERROR('Data Sheet'!L31/FINANCIALS!M35,0) -> 0
B41: DIVIDEND PAYOUT RATIO | C41: =IFERROR(C40/C37,0) -> 0.082455515 | D41: =IFERROR(D40/D37,0) -> 0.082958942 | E41: =IFERROR(E40/E37,0) -> 0.09422089 | F41: =IFERROR(F40/F37,0) -> 0.081112736 | G41: =IFERROR(G40/G37,0) -> 0.064730692 | H41: =IFERROR(H40/H37,0) -> 0.32321525 | I41: =IFERROR(I40/I37,0) -> 0.060361421 | J41: =IFERROR(J40/J37,0) -> 0.061606122 | ... M41: =IFERROR(M40/M37,0) -> 0
B43: RETAINED EARNINGS | C43: =IFERROR(IF(C37>C40,1-C41,0),0) -> 0.91754448 | D43: =IFERROR(IF(D37>D40,1-D41,0),0) -> 0.91704106 | E43: =IFERROR(IF(E37>E40,1-E41,0),0) -> 0.90577911 | F43: =IFERROR(IF(F37>F40,1-F41,0),0) -> 0.91888726 | G43: =IFERROR(IF(G37>G40,1-G41,0),0) -> 0.93526931 | H43: =IFERROR(IF(H37>H40,1-H41,0),0) -> 0.67678475 | I43: =IFERROR(IF(I37>I40,1-I41,0),0) -> 0.93963858 | J43: =IFERROR(IF(J37>J40,1-J41,0),0) -> 0.93839388 | ... M43: =IFERROR(IF(M37>M40,1-M41,0),0) -> 0
B48: YEARS | C48: 42825 | D48: 43190 | E48: 43555 | F48: 43921 | G48: 44286 | H48: 44651 | I48: 45016 | J48: 45382 | K48: 45747 | L48: 46112 | M48: LTM
A49: # | B49: BALANCE SHEET
B50: Equity Share Capital | C50: =IFERROR('Data Sheet'!B57,0) -> 486.1 | D50: =IFERROR('Data Sheet'!C57,0) -> 904.8 | E50: =IFERROR('Data Sheet'!D57,0) -> 1206.8 | F50: =IFERROR('Data Sheet'!E57,0) -> 1142.7 | G50: =IFERROR('Data Sheet'!F57,0) -> 1095.8 | H50: =IFERROR('Data Sheet'!G57,0) -> 1096.4 | I50: =IFERROR('Data Sheet'!H57,0) -> 1097.6 | J50: =IFERROR('Data Sheet'!I57,0) -> 1045 | ... L50: =IFERROR('Data Sheet'!K57,0) -> 2097.7
B51: Reserves | C51: =IFERROR('Data Sheet'!B58,0) -> 51184.1 | D51: =IFERROR('Data Sheet'!C58,0) -> 47021.5 | E51: =IFERROR('Data Sheet'!D58,0) -> 55215.8 | F51: =IFERROR('Data Sheet'!E58,0) -> 54179 | G51: =IFERROR('Data Sheet'!F58,0) -> 53805.2 | H51: =IFERROR('Data Sheet'!G58,0) -> 64306.6 | I51: =IFERROR('Data Sheet'!H58,0) -> 76570.3 | J51: =IFERROR('Data Sheet'!I58,0) -> 73488 | ... L51: =IFERROR('Data Sheet'!K58,0) -> 85920.6
B52: Borrowings | C52: =IFERROR('Data Sheet'!B59,0) -> 14241.2 | D52: =IFERROR('Data Sheet'!C59,0) -> 13901.2 | E52: =IFERROR('Data Sheet'!D59,0) -> 9946.7 | F52: =IFERROR('Data Sheet'!E59,0) -> 9724 | G52: =IFERROR('Data Sheet'!F59,0) -> 10451.4 | H52: =IFERROR('Data Sheet'!G59,0) -> 17592.9 | I52: =IFERROR('Data Sheet'!H59,0) -> 17466.6 | J52: =IFERROR('Data Sheet'!I59,0) -> 16464.9 | ... L52: =IFERROR('Data Sheet'!K59,0) -> 20291
B53: Other Liabilities | C53: =IFERROR('Data Sheet'!B60,0) -> 12760.8 | D53: =IFERROR('Data Sheet'!C60,0) -> 13563.3 | E53: =IFERROR('Data Sheet'!D60,0) -> 16217.1 | F53: =IFERROR('Data Sheet'!E60,0) -> 15953.9 | G53: =IFERROR('Data Sheet'!F60,0) -> 17213.4 | H53: =IFERROR('Data Sheet'!G60,0) -> 24279.7 | I53: =IFERROR('Data Sheet'!H60,0) -> 21789.2 | J53: =IFERROR('Data Sheet'!I60,0) -> 23611 | ... L53: =IFERROR('Data Sheet'!K60,0) -> 32574.2
B54: Total LIABILITY | C54: =IFERROR('Data Sheet'!B61,0) -> 78672.2 | D54: =IFERROR('Data Sheet'!C61,0) -> 75390.8 | E54: =IFERROR('Data Sheet'!D61,0) -> 82586.4 | F54: =IFERROR('Data Sheet'!E61,0) -> 80999.6 | G54: =IFERROR('Data Sheet'!F61,0) -> 82565.8 | H54: =IFERROR('Data Sheet'!G61,0) -> 107275.6 | I54: =IFERROR('Data Sheet'!H61,0) -> 116923.7 | J54: =IFERROR('Data Sheet'!I61,0) -> 114608.9 | ... L54: =IFERROR('Data Sheet'!K61,0) -> 140883.5
B56: FIXED ASSETS NET BLOCK | C56: =IFERROR('Data Sheet'!B62,0) -> 19886.5 | D56: =IFERROR('Data Sheet'!C62,0) -> 18126.7 | E56: =IFERROR('Data Sheet'!D62,0) -> 17464.7 | F56: =IFERROR('Data Sheet'!E62,0) -> 22062.1 | G56: =IFERROR('Data Sheet'!F62,0) -> 23040.3 | H56: =IFERROR('Data Sheet'!G62,0) -> 37989.6 | I56: =IFERROR('Data Sheet'!H62,0) -> 44756.8 | J56: =IFERROR('Data Sheet'!I62,0) -> 43628 | ... L56: =IFERROR('Data Sheet'!K62,0) -> 51690.1
B57: Capital Work in Progress | C57: =IFERROR('Data Sheet'!B63,0) -> 737.7 | D57: =IFERROR('Data Sheet'!C63,0) -> 1377.7 | E57: =IFERROR('Data Sheet'!D63,0) -> 2141.8 | F57: =IFERROR('Data Sheet'!E63,0) -> 1881.1 | G57: =IFERROR('Data Sheet'!F63,0) -> 1853.2 | H57: =IFERROR('Data Sheet'!G63,0) -> 1601.5 | I57: =IFERROR('Data Sheet'!H63,0) -> 617.1 | J57: =IFERROR('Data Sheet'!I63,0) -> 723.4 | ... L57: =IFERROR('Data Sheet'!K63,0) -> 412.2
B58: Investments | C58: =IFERROR('Data Sheet'!B64,0) -> 29913.3 | D58: =IFERROR('Data Sheet'!C64,0) -> 25796.8 | E58: =IFERROR('Data Sheet'!D64,0) -> 22886.7 | F58: =IFERROR('Data Sheet'!E64,0) -> 20032 | G58: =IFERROR('Data Sheet'!F64,0) -> 18774.7 | H58: =IFERROR('Data Sheet'!G64,0) -> 26153.8 | I58: =IFERROR('Data Sheet'!H64,0) -> 33073.2 | J58: =IFERROR('Data Sheet'!I64,0) -> 33384.4 | ... L58: =IFERROR('Data Sheet'!K64,0) -> 46785.9
B59: Other Assets | C59: =IFERROR('Data Sheet'!B65-SUM('Data Sheet'!B67:B69),0) -> 12987.6 | D59: =IFERROR('Data Sheet'!C65-SUM('Data Sheet'!C67:C69),0) -> 15161.1 | E59: =IFERROR('Data Sheet'!D65-SUM('Data Sheet'!D67:D69),0) -> 13796.3 | F59: =IFERROR('Data Sheet'!E65-SUM('Data Sheet'!E67:E69),0) -> 11940.6 | G59: =IFERROR('Data Sheet'!F65-SUM('Data Sheet'!F67:F69),0) -> 12382.1 | H59: =IFERROR('Data Sheet'!G65-SUM('Data Sheet'!G67:G69),0) -> 19491.8 | I59: =IFERROR('Data Sheet'!H65-SUM('Data Sheet'!H67:H69),0) -> 16534.8 | J59: =IFERROR('Data Sheet'!I65-SUM('Data Sheet'!I67:I69),0) -> 15539.4 | ... L59: =IFERROR('Data Sheet'!K65-SUM('Data Sheet'!K67:K69),0) -> 17798
...

Sheet Sheet1
B2: ="RATIO ANALYSIS - "&'Data Sheet'!B1 -> RATIO ANALYSIS - WIPRO LTD
B3: YEARS | C3: ='Data Sheet'!B16 -> 42825 | D3: ='Data Sheet'!C16 -> 43190 | E3: ='Data Sheet'!D16 -> 43555 | F3: ='Data Sheet'!E16 -> 43921 | G3: ='Data Sheet'!F16 -> 44286 | H3: ='Data Sheet'!G16 -> 44651 | I3: ='Data Sheet'!H16 -> 45016 | J3: ='Data Sheet'!I16 -> 45382 | ... L3: ='Data Sheet'!K16 -> 46112
B5: SALES GROWTH | D5: =IFERROR(FINANCIALS!D6,0) -> -0.017336839 | E5: =IFERROR(FINANCIALS!E6,0) -> 0.08317198 | F5: =IFERROR(FINANCIALS!F6,0) -> 0.03589867 | G5: =IFERROR(FINANCIALS!G6,0) -> 0.013041075 | H5: =IFERROR(FINANCIALS!H6,0) -> 0.28057041 | I5: =IFERROR(FINANCIALS!I6,0) -> 0.1409068 | J5: =IFERROR(FINANCIALS!J6,0) -> -0.0080375654 | K5: =IFERROR(FINANCIALS!K6,0) -> -0.0074854919 | L5: =IFERROR(FINANCIALS!L6,0) -> 0.039686424
B6: EBITDA GROWTH | D6: =IFERROR(FINANCIALS!D17/FINANCIALS!C17-1,0) -> -0.082484608 | E6: =IFERROR(FINANCIALS!E17/FINANCIALS!D17-1,0) -> 0.11798288 | F6: =IFERROR(FINANCIALS!F17/FINANCIALS!E17-1,0) -> 0.062836919 | G6: =IFERROR(FINANCIALS!G17/FINANCIALS!F17-1,0) -> 0.19681097 | H6: =IFERROR(FINANCIALS!H17/FINANCIALS!G17-1,0) -> 0.12949348 | I6: =IFERROR(FINANCIALS!I17/FINANCIALS!H17-1,0) -> 0.0092782393 | J6: =IFERROR(FINANCIALS!J17/FINANCIALS!I17-1,0) -> -0.0051368846 | K6: =IFERROR(FINANCIALS!K17/FINANCIALS!J17-1,0) -> 0.07573198 | L6: =IFERROR(FINANCIALS!L17/FINANCIALS!K17-1,0) -> -0.011652942
B7: EBIT GROWTH | D7: =IFERROR(FINANCIALS!D26/FINANCIALS!C26-1,0) -> -0.086055105 | E7: =IFERROR(FINANCIALS!E26/FINANCIALS!D26-1,0) -> 0.16067807 | F7: =IFERROR(FINANCIALS!F26/FINANCIALS!E26-1,0) -> 0.066708481 | G7: =IFERROR(FINANCIALS!G26/FINANCIALS!F26-1,0) -> 0.20739185 | H7: =IFERROR(FINANCIALS!H26/FINANCIALS!G26-1,0) -> 0.13693996 | I7: =IFERROR(FINANCIALS!I26/FINANCIALS!H26-1,0) -> -0.044577364 | J7: =IFERROR(FINANCIALS!J26/FINANCIALS!I26-1,0) -> -0.032094852 | K7: =IFERROR(FINANCIALS!K26/FINANCIALS!J26-1,0) -> 0.12374485 | L7: =IFERROR(FINANCIALS!L26/FINANCIALS!K26-1,0) -> -0.01056211
B8: NET PROFIT GROWTH | D8: =IFERROR(FINANCIALS!D32/FINANCIALS!C32-1,0) -> -0.07497498 | E8: =IFERROR(FINANCIALS!E32/FINANCIALS!D32-1,0) -> 0.17435314 | F8: =IFERROR(FINANCIALS!F32/FINANCIALS!E32-1,0) -> 0.099904749 | G8: =IFERROR(FINANCIALS!G32/FINANCIALS!F32-1,0) -> 0.20164965 | H8: =IFERROR(FINANCIALS!H32/FINANCIALS!G32-1,0) -> 0.20228489 | I8: =IFERROR(FINANCIALS!I32/FINANCIALS!H32-1,0) -> -0.10657888 | J8: =IFERROR(FINANCIALS!J32/FINANCIALS!I32-1,0) -> -0.06715868 | K8: =IFERROR(FINANCIALS!K32/FINANCIALS!J32-1,0) -> 0.097544009 | L8: =IFERROR(FINANCIALS!L32/FINANCIALS!K32-1,0) -> 0.0061770836
B9: DIVIDENED GROWTH | D9: =IFERROR(FINANCIALS!D40/FINANCIALS!C40-1,0) -> 0.00020602935 | E9: =IFERROR(FINANCIALS!E40/FINANCIALS!D40-1,0) -> 0.33328912 | F9: =IFERROR(FINANCIALS!F40/FINANCIALS!E40-1,0) -> 1.7967704e-05 | G9: =IFERROR(FINANCIALS!G40/FINANCIALS!F40-1,0) -> -5.36294e-05 | H9: =IFERROR(FINANCIALS!H40/FINANCIALS!G40-1,0) -> 5.0001095 | I9: =IFERROR(FINANCIALS!I40/FINANCIALS!H40-1,0) -> -0.83332878 | J9: =IFERROR(FINANCIALS!J40/FINANCIALS!I40-1,0) -> -4.6928361e-05 | K9: =IFERROR(FINANCIALS!K40/FINANCIALS!J40-1,0) -> 11.00023 | L9: =IFERROR(FINANCIALS!L40/FINANCIALS!K40-1,0) -> 0.83336832
B11: GROSS MARGIN | C11: =IFERROR(FINANCIALS!C12,0) -> 0.46788005 | D11: =IFERROR(FINANCIALS!D12,0) -> 0.46563131 | E11: =IFERROR(FINANCIALS!E12,0) -> 0.46936659 | F11: =IFERROR(FINANCIALS!F12,0) -> 0.4472256 | G11: =IFERROR(FINANCIALS!G12,0) -> 0.4516129 | H11: =IFERROR(FINANCIALS!H12,0) -> 0.40775671 | I11: =IFERROR(FINANCIALS!I12,0) -> 0.37780978 | J11: =IFERROR(FINANCIALS!J12,0) -> 0.3629823 | ... L11: =IFERROR(FINANCIALS!L12,0) -> 0.3700326
B12: EDITDA MARGIN | C12: =IFERROR(FINANCIALS!C18,0) -> 0.20417 | D12: =IFERROR(FINANCIALS!D18,0) -> 0.19063411 | E12: =IFERROR(FINANCIALS!E18,0) -> 0.1967607 | F12: =IFERROR(FINANCIALS!F18,0) -> 0.2018774 | G12: =IFERROR(FINANCIALS!G18,0) -> 0.23849881 | H12: =IFERROR(FINANCIALS!H18,0) -> 0.21036161 | I12: =IFERROR(FINANCIALS!I18,0) -> 0.1860918 | J12: =IFERROR(FINANCIALS!J18,0) -> 0.18663596 | ... L12: =IFERROR(FINANCIALS!L18,0) -> 0.19229573
B13: EBIT MARGIN | C13: =IFERROR((FINANCIALS!C17-FINANCIALS!C23)/FINANCIALS!C5,0) -> 0.16250965 | D13: =IFERROR((FINANCIALS!D17-FINANCIALS!D23)/FINANCIALS!D5,0) -> 0.15187815 | E13: =IFERROR((FINANCIALS!E17-FINANCIALS!E23)/FINANCIALS!E5,0) -> 0.16377635 | F13: =IFERROR((FINANCIALS!F17-FINANCIALS!F23)/FINANCIALS!F5,0) -> 0.16776583 | G13: =IFERROR((FINANCIALS!G17-FINANCIALS!G23)/FINANCIALS!G5,0) -> 0.19388099 | H13: =IFERROR((FINANCIALS!H17-FINANCIALS!H23)/FINANCIALS!H5,0) -> 0.17155538 | I13: =IFERROR((FINANCIALS!I17-FINANCIALS!I23)/FINANCIALS!I5,0) -> 0.14917845 | J13: =IFERROR((FINANCIALS!J17-FINANCIALS!J23)/FINANCIALS!J5,0) -> 0.1486782 | ... L13: =IFERROR((FINANCIALS!L17-FINANCIALS!L23)/FINANCIALS!L5,0) -> 0.16087083
B14: EBT MARGIN | C14: =IFERROR(FINANCIALS!C27,0) -> 0.15179338 | D14: =IFERROR(FINANCIALS!D27,0) -> 0.14117837 | E14: =IFERROR(FINANCIALS!E27,0) -> 0.15128035 | F14: =IFERROR(FINANCIALS!F27,0) -> 0.15577975 | G14: =IFERROR(FINANCIALS!G27,0) -> 0.18566592 | H14: =IFERROR(FINANCIALS!H27,0) -> 0.16484139 | I14: =IFERROR(FINANCIALS!I27,0) -> 0.13804212 | J14: =IFERROR(FINANCIALS!J27,0) -> 0.13469429 | ... L14: =IFERROR(FINANCIALS!L27,0) -> 0.14513301
B15: NET PROFIT MARGIN | C15: =IFERROR(FINANCIALS!C33,0) -> 0.10632047 | D15: =IFERROR(FINANCIALS!D33,0) -> 0.10008424 | E15: =IFERROR(FINANCIALS!E33,0) -> 0.10850931 | F15: =IFERROR(FINANCIALS!F33,0) -> 0.11521388 | G15: =IFERROR(FINANCIALS!G33,0) -> 0.13666447 | H15: =IFERROR(FINANCIALS!H33,0) -> 0.12830971 | I15: =IFERROR(FINANCIALS!I33,0) -> 0.10047675 | J15: =IFERROR(FINANCIALS!J33,0) -> 0.094488321 | ... L15: =IFERROR(FINANCIALS!L33,0) -> 0.10111958
B18: SALESEXPENSES%SALES | C18: =IFERROR(FINANCIALS!C15,0) -> 0.26371004 | D18: =IFERROR(FINANCIALS!D15,0) -> 0.2749972 | E18: =IFERROR(FINANCIALS!E15,0) -> 0.27260589 | F18: =IFERROR(FINANCIALS!F15,0) -> 0.2453482 | G18: =IFERROR(FINANCIALS!G15,0) -> 0.21311409 | H18: =IFERROR(FINANCIALS!H15,0) -> 0.1973951 | I18: =IFERROR(FINANCIALS!I15,0) -> 0.19171798 | J18: =IFERROR(FINANCIALS!J15,0) -> 0.17634634 | ... L18: =IFERROR(FINANCIALS!L15,0) -> 0.17773687
B19: DEPRECIATION%SALES | C19: =IFERROR(FINANCIALS!C24,0) -> 0.078291284 | D19: =IFERROR(FINANCIALS!D24,0) -> 0.072526635 | E19: =IFERROR(FINANCIALS!E24,0) -> 0.062160333 | F19: =IFERROR(FINANCIALS!F24,0) -> 0.061709764 | G19: =IFERROR(FINANCIALS!G24,0) -> 0.081361901 | H19: =IFERROR(FINANCIALS!H24,0) -> 0.065524142 | I19: =IFERROR(FINANCIALS!I24,0) -> 0.05932807 | J19: =IFERROR(FINANCIALS!J24,0) -> 0.059586666 | ... L19: =IFERROR(FINANCIALS!L24,0) -> 0.049883376
B20: OPERATINGINCOME%SALES | C20: =C13 -> 0.16250965 | D20: =D13 -> 0.15187815 | E20: =E13 -> 0.16377635 | F20: =F13 -> 0.16776583 | G20: =G13 -> 0.19388099 | H20: =H13 -> 0.17155538 | I20: =I13 -> 0.14917845 | J20: =J13 -> 0.1486782 | ... L20: =L13 -> 0.16087083
B22: RETURN ON CAPITAL EMPLOYED | C22: =(FINANCIALS!C17-FINANCIALS!C23)/(SUM(FINANCIALS!C50:C52)) -> 0.13671231 | D22: =(FINANCIALS!D17-FINANCIALS!D23)/(SUM(FINANCIALS!D50:D52)) -> 0.13384659 | E22: =(FINANCIALS!E17-FINANCIALS!E23)/(SUM(FINANCIALS!E50:E52)) -> 0.14563812 | F22: =(FINANCIALS!F17-FINANCIALS!F23)/(SUM(FINANCIALS!F50:F52)) -> 0.15768606 | G22: =(FINANCIALS!G17-FINANCIALS!G23)/(SUM(FINANCIALS!G50:G52)) -> 0.1837423 | H22: =(FINANCIALS!H17-FINANCIALS!H23)/(SUM(FINANCIALS!H50:H52)) -> 0.16394063 | I22: =(FINANCIALS!I17-FINANCIALS!I23)/(SUM(FINANCIALS!I50:I52)) -> 0.14189174 | J22: =(FINANCIALS!J17-FINANCIALS!J23)/(SUM(FINANCIALS!J50:J52)) -> 0.14665613 | ... L22: =(FINANCIALS!L17-FINANCIALS!L23)/(SUM(FINANCIALS!L50:L52)) -> 0.1375736
B23: RETAINED EARNING% | C23: =IFERROR(FINANCIALS!C43,0) -> 0.91754448 | D23: =IFERROR(FINANCIALS!D43,0) -> 0.91704106 | E23: =IFERROR(FINANCIALS!E43,0) -> 0.90577911 | F23: =IFERROR(FINANCIALS!F43,0) -> 0.91888726 | G23: =IFERROR(FINANCIALS!G43,0) -> 0.93526931 | H23: =IFERROR(FINANCIALS!H43,0) -> 0.67678475 | I23: =IFERROR(FINANCIALS!I43,0) -> 0.93963858 | J23: =IFERROR(FINANCIALS!J43,0) -> 0.93839388 | ... L23: =IFERROR(FINANCIALS!L43,0) -> 0
B24: RETURN ON EQUITY % | C24: =IFERROR(FINANCIALS!C32/SUM(FINANCIALS!C50:C51),0) -> 0.11409478 | D24: =IFERROR(FINANCIALS!D32/SUM(FINANCIALS!D50:D51),0) -> 0.11378512 | E24: =IFERROR(FINANCIALS!E32/SUM(FINANCIALS!E50:E51),0) -> 0.11350239 | F24: =IFERROR(FINANCIALS!F32/SUM(FINANCIALS!F50:F51),0) -> 0.12732617 | G24: =IFERROR(FINANCIALS!G32/SUM(FINANCIALS!G50:G51),0) -> 0.15417388 | H24: =IFERROR(FINANCIALS!H32/SUM(FINANCIALS!H50:H51),0) -> 0.15559684 | I24: =IFERROR(FINANCIALS!I32/SUM(FINANCIALS!I50:I51),0) -> 0.11706123 | J24: =IFERROR(FINANCIALS!J32/SUM(FINANCIALS!J50:J51),0) -> 0.11379255 | ... L24: =IFERROR(FINANCIALS!L32/SUM(FINANCIALS!L50:L51),0) -> 0.10641083
B25: SELF SUSTAINED GROWTH RATE | C25: =IFERROR(C23*C24,0) -> 0.10468703 | D25: =IFERROR(D23*D24,0) -> 0.10434563 | E25: =IFERROR(E23*E24,0) -> 0.10280809 | F25: =IFERROR(F23*F24,0) -> 0.11699839 | G25: =IFERROR(G23*G24,0) -> 0.14419409 | H25: =IFERROR(H23*H24,0) -> 0.10530557 | I25: =IFERROR(I23*I24,0) -> 0.10999525 | J25: =IFERROR(J23*J24,0) -> 0.10678223 | ... L25: =IFERROR(L23*L24,0) -> 0
B26: INTEREST COVERAGE RATIO | C26: =(FINANCIALS!C17-FINANCIALS!C23)/FINANCIALS!C20 -> 15.164759 | D26: =(FINANCIALS!D17-FINANCIALS!D23)/FINANCIALS!D20 -> 14.194511 | E26: =(FINANCIALS!E17-FINANCIALS!E23)/FINANCIALS!E20 -> 13.106305 | F26: =(FINANCIALS!F17-FINANCIALS!F23)/FINANCIALS!F20 -> 13.996725 | G26: =(FINANCIALS!G17-FINANCIALS!G23)/FINANCIALS!G20 -> 23.600629 | H26: =(FINANCIALS!H17-FINANCIALS!H23)/FINANCIALS!H20 -> 25.551925 | I26: =(FINANCIALS!I17-FINANCIALS!I23)/FINANCIALS!I20 -> 13.395653 | J26: =(FINANCIALS!J17-FINANCIALS!J23)/FINANCIALS!J20 -> 10.632091 | ... L26: =(FINANCIALS!L17-FINANCIALS!L23)/FINANCIALS!L20 -> 10.221925
B28: Debtor Turnover Ratio | C28: =FINANCIALS!C5/FINANCIALS!C62 -> 5.8461506 | D28: =FINANCIALS!D5/FINANCIALS!D62 -> 5.3952966 | E28: =FINANCIALS!E5/FINANCIALS!E62 -> 5.8731702 | F28: =FINANCIALS!F5/FINANCIALS!F62 -> 5.851944 | G28: =FINANCIALS!G5/FINANCIALS!G62 -> 6.5679972 | H28: =FINANCIALS!H5/FINANCIALS!H62 -> 6.8835869 | I28: =FINANCIALS!I5/FINANCIALS!I62 -> 7.161662 | J28: =FINANCIALS!J5/FINANCIALS!J62 -> 7.7730024 | ... L28: =FINANCIALS!L5/FINANCIALS!L62 -> 6.8155496
B29: Credit Turnover Ratio | C29: =IFERROR(FINANCIALS!C5/FINANCIALS!C53,0) -> 4.3452135 | D29: =IFERROR(FINANCIALS!D5/FINANCIALS!D53,0) -> 4.0172451 | E29: =IFERROR(FINANCIALS!E5/FINANCIALS!E53,0) -> 3.6393005 | F29: =IFERROR(FINANCIALS!F5/FINANCIALS!F53,0) -> 3.8321414 | G29: =IFERROR(FINANCIALS!G5/FINANCIALS!G53,0) -> 3.5980631 | H29: =IFERROR(FINANCIALS!H5/FINANCIALS!H53,0) -> 3.2665972 | I29: =IFERROR(FINANCIALS!I5/FINANCIALS!I53,0) -> 4.1528647 | J29: =IFERROR(FINANCIALS!J5/FINANCIALS!J53,0) -> 3.8016306 | ... L29: =IFERROR(FINANCIALS!L5/FINANCIALS!L53,0) -> 2.8434774
B30: Inventory Turnoover ratio | C30: =IFERROR(FINANCIALS!C5/FINANCIALS!C63,0) -> 141.63065 | D30: =IFERROR(FINANCIALS!D5/FINANCIALS!D63,0) -> 161.68279 | E30: =IFERROR(FINANCIALS!E5/FINANCIALS!E63,0) -> 149.37712 | F30: =IFERROR(FINANCIALS!F5/FINANCIALS!F63,0) -> 327.81555 | G30: =IFERROR(FINANCIALS!G5/FINANCIALS!G63,0) -> 582.09492 | H30: =IFERROR(FINANCIALS!H5/FINANCIALS!H63,0) -> 594.54273 | I30: =IFERROR(FINANCIALS!I5/FINANCIALS!I63,0) -> 761.68013 | J30: =IFERROR(FINANCIALS!J5/FINANCIALS!J63,0) -> 989.63947 | ... L30: =IFERROR(FINANCIALS!L5/FINANCIALS!L63,0) -> 1791.5667
B31: Fixed Asset Turnover | C31: =IFERROR(FINANCIALS!C5/FINANCIALS!C52,0) -> 3.8935202 | D31: =IFERROR(FINANCIALS!D5/FINANCIALS!D52,0) -> 3.9195969 | E31: =IFERROR(FINANCIALS!E5/FINANCIALS!E52,0) -> 5.9335156 | F31: =IFERROR(FINANCIALS!F5/FINANCIALS!F52,0) -> 6.2872892 | G31: =IFERROR(FINANCIALS!G5/FINANCIALS!G52,0) -> 5.9259908 | H31: =IFERROR(FINANCIALS!H5/FINANCIALS!H52,0) -> 4.5081823 | I31: =IFERROR(FINANCIALS!I5/FINANCIALS!I52,0) -> 5.1806076 | J31: =IFERROR(FINANCIALS!J5/FINANCIALS!J52,0) -> 5.4516153 | ... L31: =IFERROR(FINANCIALS!L5/FINANCIALS!L52,0) -> 4.5647824
B32: Capital Turnover Ratio | C32: =IFERROR(FINANCIALS!C5/SUM(FINANCIALS!C50:C51),) -> 1.0731215 | D32: =IFERROR(FINANCIALS!D5/SUM(FINANCIALS!D50:D51),) -> 1.1368935 | E32: =IFERROR(FINANCIALS!E5/SUM(FINANCIALS!E50:E51),) -> 1.0460152 | F32: =IFERROR(FINANCIALS!F5/SUM(FINANCIALS!F50:F51),) -> 1.1051287 | G32: =IFERROR(FINANCIALS!G5/SUM(FINANCIALS!G50:G51),) -> 1.1281197 | H32: =IFERROR(FINANCIALS!H5/SUM(FINANCIALS!H50:H51),) -> 1.2126661 | I32: =IFERROR(FINANCIALS!I5/SUM(FINANCIALS!I50:I51),) -> 1.1650579 | J32: =IFERROR(FINANCIALS!J5/SUM(FINANCIALS!J50:J51),) -> 1.2043028 | ... L32: =IFERROR(FINANCIALS!L5/SUM(FINANCIALS!L50:L51),) -> 1.0523266
B34: debtor days | C34: =IFERROR(365/C28,0) -> 62.434245
B35: Payable days | C35: =IFERROR(365/C29,0) -> 84.000476
B36: Inventory Days | C36: =IFERROR(365/C30,0) -> 2.5771258
B37: Cash Conversion cycle

Sheet HISTORICAL FS
N3: 13041
T4: 42064 | U4: 42430 | V4: 42795 | W4: 43160 | X4: 43525 | Y4: 43891 | Z4: 44256 | AA4: 44621 | AB4: 44986 | AC4: 45352 | AD4: 45717 | AE4: 46082
S5: Cash from Operating Activity - | T5: 35531 | U5: 37900 | V5: 30199 | W5: 23857 | X5: 18891 | Y5: 26633 | Z5: 29001 | AA5: 14283 | AB5: 35388 | AC5: 67915 | AD5: 63102 | AE5: 13041
S6: Profit from operations | T6: 43397 | U6: 38626 | V6: 28840 | W6: 33312 | X6: 28771 | Y6: 23352 | Z6: 31198 | AA6: 26943 | AB6: 41694 | AC6: 65106 | AD6: 58937 | AE6: 25393
S7: Receivables | T7: -3179 | U7: -2223 | V7: -4152 | W7: -10688 | X7: -9109 | Y7: 9950 | Z7: -5505 | AA7: 185 | AB7: -2213 | AC7: -1876 | AD7: 3573 | AE7: -1587
S8: Inventory | T8: -3692 | U8: -5743 | V8: -6621 | W8: -3560 | X8: 2069 | Y8: 2326 | Z8: 3814 | AA8: 472 | AB8: -5665 | AC8: -7265 | AD8: 2127 | AE8: -4318
S9: Payables | T9: 3598 | U9: 3947 | V9: 9301 | W9: 7320 | X9: -4692 | Y9: -8085 | Z9: 5748 | AA9: -7012 | AB9: 6945 | AC9: 13706 | AD9: 1303 | AE9: -1973
S10: Loans Advances | T10: 0 | U10: -520 | V10: 0 | W10: 0 | X10: 0 | Y10: 0 | Z10: 0 | AA10: 0 | AB10: 0 | AC10: 0 | AD10: 0 | AE10: -815
S11: Other WC items | T11: -398 | U11: 5852 | V11: 4727 | W11: 494 | X11: 4512 | Y11: 875 | Z11: -4150 | AA11: -4396 | AB11: -2194 | AC11: 2760 | AD11: 1153 | AE11: -345
S12: Working capital changes | T12: -3672 | U12: 1313 | V12: 3254 | W12: -6434 | X12: -7221 | Y12: 5065 | Z12: -93 | AA12: -10750 | AB12: -3127 | AC12: 7325 | AD12: 8156 | AE12: -9038
S13: Direct taxes | T13: -4194 | U13: -2040 | V13: -1895 | W13: -3021 | X13: -2659 | Y13: -1785 | Z13: -2105 | AA13: -1910 | AB13: -3179 | AC13: -4516 | AD13: -3991 | AE13: -3314
S14: Cash from Investing Activity - | T14: -36232 | U14: -36694 | V14: -39571 | W14: -25139 | X14: -20878 | Y14: -33115 | Z14: -25672 | AA14: -4444 | AB14: -15417 | AC14: -22781 | AD14: -49982 | AE14: -24810
S15: Fixed assets purchased | T15: -31962 | U15: -31503 | V15: -16072 | W15: -35079 | X15: -35304 | Y15: -29702 | Z15: -20205 | AA15: -15168 | AB15: -19230 | AC15: -31414 | AD15: -38042 | AE15: -36282
S16: Fixed assets sold | T16: 74 | U16: 59 | V16: 53 | W16: 30 | X16: 67 | Y16: 171 | Z16: 351 | AA16: 230 | AB16: 285 | AC16: 231 | AD16: 974 | AE16: 46
... S19: Interest received | T19: 698 | U19: 731 | V19: 638 | W19: 690 | X19: 761 | Y19: 1104 | Z19: 428 | AA19: 653 | AB19: 973 | AC19: 2493 | AD19: 2420 | AE19: 1940
N20: 0 | S20: Dividends received | T20: 80 | U20: 58 | V20: 620 | W20: 1797 | X20: 232 | Y20: 21 | Z20: 18 | AA20: 32 | AB20: 46 | AC20: 47 | AD20: 64 | AE20: 199
N21: -512 | S21: Investment in group cos | T21: -160 | U21: 0 | V21: -107 | W21: -4 | X21: -9 | Y21: -606 | Z21: -10 | AA21: 0 | AB21: 0 | AC21: -150 | AD21: 0 | AE21: -5
N22: -83 | S22: Redemp n Canc of Shares | T22: 0 | U22: 0 | V22: 0 | W22: 14 | X22: 533 | Y22: 0 | Z22: 0 | AA22: 0 | AB22: 19 | AC22: 107 | AD22: 765 | AE22: 0
N23: -715 | S23: Acquisition of companies | T23: 0 | U23: -111 | V23: 0 | W23: 0 | X23: -8 | Y23: -27 | Z23: 0 | AA23: -98 | AB23: 0 | AC23: 0 | AD23: -688 | AE23: -512
N24: -1344 | S24: Inter corporate deposits | T24: 0 | U24: 0 | V24: 0 | W24: 0 | X24: 0 | Y24: 0 | Z24: 0 | AA24: 0 | AB24: 0 | AC24: -25 | AD24: -20 | AE24: -83
N25: 18 | S25: Other investing items | T25: 456 | U25: -1289 | V25: -26663 | W25: 5360 | X25: 7335 | Y25: -2659 | Z25: 1051 | AA25: 12813 | AB25: -4357 | AC25: -4817 | AD25: -2889 | AE25: -715
N26: 0 | S26: Cash from Financing Activity - | T26: 5201 | U26: -3795 | V26: 6205 | W26: 2012 | X26: 8830 | Y26: 3390 | Z26: 9904 | AA26: -3380 | AB26: -26243 | AC26: -37006 | AD26: -18786 | AE26: -1344
N27: 26425 | S27: Proceeds from shares | T27: 0 | U27: 7433 | V27: 5 | W27: 0 | X27: 0 | Y27: 3889 | Z27: 2603 | AA27: 19 | AB27: 20 | AC27: 82 | AD27: 1108 | AE27: 18
N28: -18110 | S28: Redemption of debentures | T28: -744 | U28: 0 | V28: 0 | W28: 0 | X28: 0 | Y28: 0 | Z28: 0 | AA28: 0 | AB28: 0 | AC28: 0 | AD28: 0 | AE28: 0
N29: -5111 | S29: Proceeds from borrowings | T29: 36363 | U29: 19519 | V29: 33390 | W29: 37482 | X29: 51128 | Y29: 38297 | Z29: 46641 | AA29: 46578 | AB29: 43934 | AC29: 18829 | AD29: 13384 | AE29: 26425
N30: -2203 | S30: Repayment of borrowings | T30: -23332 | U30: -24924 | V30: -21732 | W30: -29964 | X30: -35198 | Y30: -29847 | Z30: -29709 | AA30: -42816 | AB30: -62557 | AC30: -47414 | AD30: -21443 | AE30: -18110
N31: -2145 | S31: Interest paid fin | T31: -6307 | U31: -5716 | V31: -5336 | W31: -5411 | X31: -7005 | Y31: -7518 | Z31: -8123 | AA31: -9251 | AB31: -9336 | AC31: -9332 | AD31: -5814 | AE31: -5111
... N35: 0.87 | S35: Net Cash Flow | T35: 4500 | U35: -2589 | V35: -3167 | W35: 730 | X35: 6843 | Y35: -3092 | Z35: 13232 | AA35: 6459 | AB35: -6272 | AC35: 8128 | AD35: -5666 | AE35: -13113
S36: Free Cash Flow | T36: 3643 | U36: 6455 | V36: 14181 | W36: -11191 | X36: -16346 | Y36: -2898 | Z36: 9146 | AA36: -655 | AB36: 16443 | AC36: 36732 | AD36: 26034 | AE36: -23195
S37: CFO/OP | T37: 1.01 | U37: 1.04 | V37: 1.08 | W37: 0.85 | X37: 0.87 | Y37: 1.58 | Z37: 0.96 | AA37: 0.66 | AB37: 1.21 | AC37: 1.25 | AD37: 1.2 | AE37: 0.87

Sheet DCF
D1: WIPRO LTD
D2: DCF VALUATION
B4: CURRENT ASSETS | C4: 44276 | D4: 44642 | E4: 45008 | F4: 45374 | G4: 45740 | H4: 46106
B5: =DATA!B32 -> Inventories | C5: =DATA!I32 -> 106 | D5: =DATA!J32 -> 133 | E5: =DATA!K32 -> 119 | F5: =DATA!L32 -> 91 | G5: =DATA!M32 -> 69 | H5: =DATA!N32 -> 52
B6: =DATA!B33 -> Trade receivables + | C6: =DATA!I33 -> 9430 | D6: =DATA!J33 -> 11522 | E6: =DATA!K33 -> 12635 | F6: =DATA!L33 -> 11548 | G6: =DATA!M33 -> 11774 | H6: =DATA!N33 -> 13590
B7: =DATA!B35 -> Loans n Advances | C7: =DATA!I35 -> 1830 | D7: =DATA!J35 -> 2294 | E7: =DATA!K35 -> 2830 | F7: =DATA!L35 -> 2826 | G7: =DATA!M35 -> 2668 | H7: =DATA!N35 -> 3340
B8: =DATA!B36 -> Other asset items | C8: =DATA!I36 -> 10552 | D8: =DATA!J36 -> 17198 | E8: =DATA!K36 -> 13705 | F8: =DATA!L36 -> 12713 | G8: =DATA!M36 -> 11910 | H8: =DATA!N36 -> 14458
B9: TOTAL | C9: =SUM(C5:C8) -> 21918 | D9: =SUM(D5:D8) -> 31147 | E9: =SUM(E5:E8) -> 29289 | F9: =SUM(F5:F8) -> 27178 | G9: =SUM(G5:G8) -> 26421 | H9: =SUM(H5:H8) -> 31440
B11: CURRENT LIABILITIES | C11: 44276 | D11: 44642 | E11: 45008 | F11: 45374 | G11: 45740 | H11: 46106
B12: =DATA!B12 -> Trade Payables | C12: =DATA!I12 -> 5182 | D12: =DATA!J12 -> 6252 | E12: =DATA!K12 -> 5972 | F12: =DATA!L12 -> 5766 | G12: =DATA!M12 -> 5867 | H12: =DATA!N12 -> 6289
B13: =DATA!B13 -> Advance from Customers | C13: =DATA!I13 -> 36 | D13: =DATA!J13 -> 63 | E13: =DATA!K13 -> 64 | F13: =DATA!L13 -> 119 | G13: =DATA!M13 -> 79 | H13: =DATA!N13 -> 82
B14: =DATA!B14 -> Other liability items | C14: =DATA!I14 -> 11846 | D14: =DATA!J14 -> 17913 | E14: =DATA!K14 -> 15694 | F14: =DATA!L14 -> 17592 | G14: =DATA!M14 -> 20202 | H14: =DATA!N14 -> 25952
B15: TOTAL | C15: =SUM(C12:C14) -> 17064 | D15: =SUM(D12:D14) -> 24228 | E15: =SUM(E12:E14) -> 21730 | F15: =SUM(F12:F14) -> 23477 | G15: =SUM(G12:G14) -> 26148 | H15: =SUM(H12:H14) -> 32323
B17: TOTAL WORKING CAP | C17: =C9-C15 -> 4854 | D17: =D9-D15 -> 6919 | E17: =E9-E15 -> 7559 | F17: =F9-F15 -> 3701 | G17: =G9-G15 -> 273 | H17: =H9-H15 -> -883
B19: NON CURRENT ASSETS | C19: 44276 | D19: 44642 | E19: 45008 | F19: 45374 | G19: 45740 | H19: 46106
B20: =DATA!B17 -> Land | C20: =DATA!I17 -> 590 | D20: =DATA!J17 -> 609 | E20: =DATA!K17 -> 614 | F20: =DATA!L17 -> 572 | G20: =DATA!M17 -> 550 | H20: =DATA!N17 -> 553
B21: =DATA!B18 -> Building | C21: =DATA!I18 -> 5806 | D21: =DATA!J18 -> 6648 | E21: =DATA!K18 -> 7545 | F21: =DATA!L18 -> 7528 | G21: =DATA!M18 -> 8740 | H21: =DATA!N18 -> 9351
B22: =DATA!B19 -> Plant Machinery | C22: =DATA!I19 -> 9618 | D22: =DATA!J19 -> 10074 | E22: =DATA!K19 -> 12023 | F22: =DATA!L19 -> 10468 | G22: =DATA!M19 -> 10492 | H22: =DATA!N19 -> 10212
B23: =DATA!B20 -> Equipments | C23: =DATA!I20 -> 686 | D23: =DATA!J20 -> 726 | E23: =DATA!K20 -> 782 | F23: =DATA!L20 -> 751 | G23: =DATA!M20 -> 766 | H23: =DATA!N20 -> 793
B24: =DATA!B21 -> Computers | C24: =DATA!I21 -> 1851 | D24: =DATA!J21 -> 2516 | E24: =DATA!K21 -> 0 | F24: =DATA!L21 -> 0 | G24: =DATA!M21 -> 0 | H24: =DATA!N21 -> 0
B25: =DATA!B22 -> Furniture n fittings | C25: =DATA!I22 -> 1373 | D25: =DATA!J22 -> 1529 | E25: =DATA!K22 -> 1799 | F25: =DATA!L22 -> 1814 | G25: =DATA!M22 -> 1948 | H25: =DATA!N22 -> 2012
B26: =DATA!B23 -> Vehicles | C26: =DATA!I23 -> 134 | D26: =DATA!J23 -> 122 | E26: =DATA!K23 -> 103 | F26: =DATA!L23 -> 88 | G26: =DATA!M23 -> 77 | H26: =DATA!N23 -> 94
B27: =DATA!B24 -> Intangible Assets | C27: =DATA!I24 -> 13515 | D27: =DATA!J24 -> 24286 | E27: =DATA!K24 -> 30348 | F27: =DATA!L24 -> 31145 | G27: =DATA!M24 -> 32035 | H27: =DATA!N24 -> 38221
B28: =DATA!B25 -> Other fixed assets | C28: =DATA!I25 -> 2794 | D28: =DATA!J25 -> 5479 | E28: =DATA!K25 -> 6174 | F28: =DATA!L25 -> 5564 | G28: =DATA!M25 -> 5218 | H28: =DATA!N25 -> 6002
B29: =DATA!B26 -> Gross Block | C29: =SUM(C20:C28) -> 36367 | D29: =SUM(D20:D28) -> 51989 | E29: =SUM(E20:E28) -> 59388 | F29: =SUM(F20:F28) -> 57930 | G29: =SUM(G20:G28) -> 59826 | H29: =SUM(H20:H28) -> 67238
B30: =DATA!B27 -> Accumulated Depreciation | C30: =DATA!I27 -> 13327 | D30: =DATA!J27 -> 14000 | E30: =DATA!K27 -> 14631 | F30: =DATA!L27 -> 14302 | G30: =DATA!M27 -> 14639 | H30: =DATA!N27 -> 15547
B31: NET CURRENT ASSETS | C31: =C29-C30 -> 23040 | D31: =D29-D30 -> 37989 | E31: =E29-E30 -> 44757 | F31: =F29-F30 -> 43628 | G31: =G29-G30 -> 45187 | H31: =H29-H30 -> 51691
B33: INVESTED CAP | C33: =C31+C17 -> 27894 | D33: =D31+D17 -> 44908 | E33: =E31+E17 -> 52316 | F33: =F31+F17 -> 47329 | G33: =G31+G17 -> 45460 | H33: =H31+H17 -> 50808
B35: EBIT | C35: =FINANCIALS!G17-FINANCIALS!G23 -> 12008 | D35: =FINANCIALS!H17-FINANCIALS!H23 -> 13606.4 | E35: =FINANCIALS!I17-FINANCIALS!I23 -> 13498.8 | F35: =FINANCIALS!J17-FINANCIALS!J23 -> 13345.4 | G35: =FINANCIALS!K17-FINANCIALS!K23 -> 15063.3 | H35: =FINANCIALS!L17-FINANCIALS!L23 -> 14900.5
B37: ROCE | C37: =C35/C33 -> 0.43048684 | D37: =D35/D33 -> 0.30298388 | E37: =E35/E33 -> 0.25802431 | F37: =F35/F33 -> 0.28197088 | G37: =G35/G33 -> 0.33135284 | H37: =H35/H33 -> 0.29327074
B38: AVERAGE | C38: =AVERAGE(C37:H37) -> 0.31634825
B39: MEDIAN | C39: =MEDIAN(C37:H37) -> 0.29812731
B42: CALCULATION OF REINVESTMENT RATE | C42: 44276 | D42: 44642 | E42: 45008 | F42: 45374 | G42: 45740 | H42: 46106
B44: NET CAP EX | C44: =-SUM(DATA!I50:I51) -> 1883 | D44: =-SUM(DATA!J50:J51) -> 1941 | E44: =-SUM(DATA!K50:K51) -> 1428 | F44: =-SUM(DATA!L50:L51) -> 649 | G44: =-SUM(DATA!M50:M51) -> 1322 | H44: =-SUM(DATA!N50:N51) -> 1484
B45: CHANGES IN WORKING CAP | D45: =D17-C17 -> 2065 | E45: =E17-D17 -> 640 | F45: =F17-E17 -> -3858 | G45: =G17-F17 -> -3428 | H45: =H17-G17 -> -1156
B46: EBIT | D46: =D35 -> 13606.4 | E46: =E35 -> 13498.8 | F46: =F35 -> 13345.4 | G46: =G35 -> 15063.3 | H46: =H35 -> 14900.5
B47: TAX | D47: 0.25 | E47: 0.25 | F47: 0.25 | G47: 0.25 | H47: 0.25
B48: EBIT(1-TAX) | D48: =D46*(1-D47) -> 10204.8 | E48: =E46*(1-E47) -> 10124.1 | F48: =F46*(1-F47) -> 10009.05 | G48: =G46*(1-G47) -> 11297.475 | H48: =H46*(1-H47) -> 11175.375
B50: REINVESTMENT | D50: =D44+D45 -> 4006 | E50: =E44+E45 -> 2068 | F50: =F44+F45 -> -3209 | G50: =G44+G45 -> -2106 | H50: =H44+H45 -> 328
B51: REINVESTMENT RATE | D51: =D50/D46 -> 0.29442027 | E51: =E50/E46 -> 0.1531988 | F51: =F50/F46 -> -0.24045739 | G51: =G50/G46 -> -0.13981 | H51: =H50/H46 -> 0.022012684
...

Sheet DATA
C2: 42064 | D2: 42430 | E2: 42795 | F2: 43160 | G2: 43525 | H2: 43891 | I2: 44256 | J2: 44621 | K2: 44986 | L2: 45352 | M2: 45717 | N2: 46082
B3: Equity Capital | C3: 494 | D3: 494 | E3: 486 | F3: 905 | G3: 1207 | H3: 1143 | I3: 1096 | J3: 1096 | K3: 1098 | L3: 1045 | M3: 2094 | N3: 2098
B4: Reserves | C4: 36598 | D4: 45651 | E4: 51184 | F4: 47022 | G4: 55216 | H4: 54179 | I4: 53805 | J4: 64307 | K4: 76570 | L4: 73488 | M4: 80270 | N4: 85921
B5: Borrowings -
B6: Long term Borrowings | C6: 1271 | D6: 1736 | E6: 1961 | F6: 4527 | G6: 2837 | H6: 484 | I6: 746 | J6: 5646 | K6: 6127 | L6: 6230 | M6: 6395 | N6: 196
B7: Short term Borrowings | C7: 6444 | D7: 10265 | E7: 11674 | F7: 7960 | G7: 6808 | H7: 5402 | I7: 7587 | J7: 9523 | K7: 8882 | L7: 7917 | M7: 9786 | N7: 16591
B8: Lease Liabilities | C8: 0 | D8: 0 | E8: 0 | F8: 0 | G8: 0 | H8: 1920 | I8: 2118 | J8: 2423 | K8: 2457 | L8: 2318 | M8: 3022 | N8: 3504
B9: Other Borrowings | C9: 176 | D9: 521 | E9: 606 | F9: 1415 | G9: 301 | H9: 1918 | I9: 0 | J9: 0 | K9: 0 | L9: 0 | M9: 0 | N9: 0
B10: Other Liabilities -
B11: Non controlling int | C11: 165 | D11: 221 | E11: 239 | F11: 241 | G11: 264 | H11: 188 | I11: 150 | J11: 52 | K11: 59 | L11: 134 | M11: 214 | N11: 251
B12: Trade Payables | C12: 5849 | D12: 4902 | E12: 4867 | F12: 5120 | G12: 6266 | H12: 5840 | I12: 5182 | J12: 6252 | K12: 5972 | L12: 5766 | M12: 5867 | N12: 6289
B13: Advance from Customers | C13: 220 | D13: 238 | E13: 239 | F13: 190 | G13: 136 | H13: 146 | I13: 36 | J13: 63 | K13: 64 | L13: 119 | M13: 79 | N13: 82
B14: Other liability items | C14: 7134 | D14: 7562 | E14: 7415 | F14: 8012 | G14: 9551 | H14: 9780 | I14: 11846 | J14: 17913 | K14: 15694 | L14: 17592 | M14: 20202 | N14: 25952
B15: Total Liabilities | C15: 58350 | D15: 71590 | E15: 78672 | F15: 75391 | G15: 82586 | H15: 81000 | I15: 82566 | J15: 107276 | K15: 116924 | L15: 114609 | M15: 127929 | N15: 140884
B16: Fixed Assets -
B17: Land | C17: 587 | D17: 370 | E17: 381 | F17: 364 | G17: 370 | H17: 576 | I17: 590 | J17: 609 | K17: 614 | L17: 572 | M17: 550 | N17: 553 | O17: =C26-C27 -> 10837
B18: Building | C18: 2437 | D18: 2589 | E18: 2738 | F18: 2495 | G18: 2729 | H18: 5194 | I18: 5806 | J18: 6648 | K18: 7545 | L18: 7528 | M18: 8740 | N18: 9351
B19: Plant Machinery | C19: 7979 | D19: 9950 | E19: 10889 | F19: 6938 | G19: 9229 | H19: 8801 | I19: 9618 | J19: 10074 | K19: 12023 | L19: 10468 | M19: 10492 | N19: 10212 | O19: =C26-SUM(C17:C25) -> 0
B20: Equipments | C20: 422 | D20: 441 | E20: 543 | F20: 582 | G20: 591 | H20: 687 | I20: 686 | J20: 726 | K20: 782 | L20: 751 | M20: 766 | N20: 793
B21: Computers | C21: 0 | D21: 0 | E21: 0 | F21: 1776 | G21: 0 | H21: 1684 | I21: 1851 | J21: 2516 | K21: 0 | L21: 0 | M21: 0 | N21: 0
B22: Furniture n fittings | C22: 857 | D22: 961 | E22: 1022 | F22: 986 | G22: 1050 | H22: 1290 | I22: 1373 | J22: 1529 | K22: 1799 | L22: 1814 | M22: 1948 | N22: 2012
B23: Vehicles | C23: 85 | D23: 59 | E23: 43 | F23: 114 | G23: 95 | H23: 163 | I23: 134 | J23: 122 | K23: 103 | L23: 88 | M23: 77 | N23: 94
B24: Intangible Assets | C24: 5895 | D24: 10098 | E24: 12228 | F24: 11405 | G24: 0 | H24: 0 | I24: 13515 | J24: 24286 | K24: 30348 | L24: 31145 | M24: 32035 | N24: 38221
B25: Other fixed assets | C25: 43 | D25: 1836 | E25: 2681 | F25: 3314 | G25: 14609 | H25: 16608 | I25: 2794 | J25: 5479 | K25: 6174 | L25: 5564 | M25: 5218 | N25: 6002
B26: Gross Block | C26: 18305 | D26: 26304 | E26: 30525 | F26: 27972 | G26: 28672 | H26: 35004 | I26: 36368 | J26: 51990 | K26: 59388 | L26: 57930 | M26: 59826 | N26: 67237
B27: Accumulated Depreciation | C27: 7468 | D27: 9024 | E27: 10639 | F27: 9846 | G27: 11208 | H27: 12942 | I27: 13327 | J27: 14000 | K27: 14631 | L27: 14302 | M27: 14639 | N27: 15547
B28: NET FIXED ASSETS | C28: =C26-C27 -> 10837 | D28: =D26-D27 -> 17280 | E28: =E26-E27 -> 19886 | F28: =F26-F27 -> 18126 | G28: =G26-G27 -> 17464 | H28: =H26-H27 -> 22062 | I28: =I26-I27 -> 23041 | J28: =J26-J27 -> 37990 | ... N28: =N26-N27 -> 51690
B29: CWIP | C29: 395 | D29: 381 | E29: 738 | F29: 1378 | G29: 2142 | H29: 1881 | I29: 1853 | J29: 1602 | K29: 617 | L29: 723 | M29: 196 | N29: 412
B30: Investments | C30: 5532 | D30: 20915 | E30: 29913 | F30: 25797 | G30: 22887 | H30: 20032 | I30: 18775 | J30: 26154 | K30: 33073 | L30: 33384 | M30: 43926 | N30: 46786
B31: Other Assets -
B32: Inventories | C32: 485 | D32: 539 | E32: 392 | F32: 337 | G32: 395 | H32: 186 | I32: 106 | J32: 133 | K32: 119 | L32: 91 | M32: 69 | N32: 52
B33: Trade receivables + | C33: 9155 | D33: 9961 | E33: 9485 | F33: 10099 | G33: 10049 | H33: 10447 | I33: 9430 | J33: 11522 | K33: 12635 | L33: 11548 | M33: 11774 | N33: 13590 | O33: =SUM(C29:C36) -> 47513
B34: Cash Equivalents | C34: 16619 | D34: 9905 | E34: 5271 | F34: 4492 | G34: 15853 | H34: 14450 | I34: 16979 | J34: 10384 | K34: 9188 | L34: 9695 | M34: 12197 | N34: 10556 | O34: =O33+C28 -> 58350
B35: Loans n Advances | C35: 1326 | D35: 2612 | E35: 1613 | F35: 2354 | G35: 2358 | H35: 1625 | I35: 1830 | J35: 2294 | K35: 2830 | L35: 2826 | M35: 2668 | N35: 3340
B36: Other asset items | C36: 14001 | D36: 9998 | E36: 11374 | F36: 12807 | G36: 11438 | H36: 10315 | I36: 10552 | J36: 17198 | K36: 13705 | L36: 12713 | M36: 11910 | N36: 14458
B37: Total Assets | C37: 58350 | D37: 71590 | E37: 78672 | F37: 75391 | G37: 82586 | H37: 81000 | I37: 82566 | J37: 107276 | K37: 116924 | L37: 114609 | M37: 127929 | N37: 140884
C39: 42064 | D39: 42430 | E39: 42795 | F39: 43160 | G39: 43525 | H39: 43891 | I39: 44256 | J39: 44621 | K39: 44986 | L39: 45352 | M39: 45717 | N39: 46082
B40: Cash from Operating Activity - | C40: 7840 | D40: 7887 | E40: 9277 | F40: 8423 | G40: 11632 | H40: 10064 | I40: 14755 | J40: 11080 | K40: 13060 | L40: 17622 | M40: 16943 | N40: 14932
B41: Profit from operations | C41: 10990 | D41: 11180 | E41: 11374 | F41: 11322 | G41: 11430 | H41: 13088 | I41: 14954 | J41: 17297 | K41: 17538 | L41: 17416 | M41: 18533 | N41: 18948
B42: Receivables | C42: -888 | D42: -532 | E42: 335 | F42: -974 | G42: 139 | H42: -333 | I42: 1285 | J42: -4323 | K42: -98 | L42: 782 | M42: 189 | N42: -1144
...

Sheet BETA 
C1: WIPRO | H1: NIFTY 50
B2: Date | C2: Price | D2: RETURNS | G2: Date | H2: Price | I2: =H2/H1-1 -> #VALUE!
B3: 46266 | C3: 166.3 | G3: 46266 | H3: 23431.5 | I3: =H3/H2-1 -> #VALUE!
B4: 46235 | C4: 184.5 | D4: =C4/C3-1 -> 0.10944077 | G4: 46235 | H4: 24080.4 | I4: =H4/H3-1 -> 0.02769349 | K4: =SLOPE(D4:D62,I4:I62) -> 0.91215021
B5: 46204 | C5: 183.65 | D5: =C5/C4-1 -> -0.0046070461 | G5: 46204 | H5: 24383.6 | I5: =H5/H4-1 -> 0.012591153 | K5: =N27 -> 0.91215021
B6: 46174 | C6: 170.39 | D6: =C6/C5-1 -> -0.072202559 | G6: 46174 | H6: 23865.75 | I6: =H6/H5-1 -> -0.021237635
B7: 46143 | C7: 204.25 | D7: =C7/C6-1 -> 0.19872058 | G7: 46143 | H7: 23547.75 | I7: =H7/H6-1 -> -0.013324534 | K7: 0.75
B8: 46113 | C8: 200.65 | D8: =C8/C7-1 -> -0.017625459 | G8: 46113 | H8: 23997.55 | I8: =H8/H7-1 -> 0.019101613 | K8: 0.25
B9: 46082 | C9: 187.64 | D9: =C9/C8-1 -> -0.064839272 | G9: 46082 | H9: 22331.4 | I9: =H9/H8-1 -> -0.069430004 | K9: 1
B10: 46054 | C10: 200.96 | D10: =C10/C9-1 -> 0.070986996 | G10: 46054 | H10: 25178.65 | I10: =H10/H9-1 -> 0.12749984 | K10: =K5 -> 0.91215021 | M10: SUMMARY OUTPUT
B11: 46023 | C11: 236.9 | D11: =C11/C10-1 -> 0.17884156 | G11: 46023 | H11: 25320.65 | I11: =H11/H10-1 -> 0.0056396987 | K11: =(K7*K10)+(K8*K9) -> 0.93411266
B12: 45992 | C12: 263.28 | D12: =C12/C11-1 -> 0.111355 | G12: 45992 | H12: 26129.6 | I12: =H12/H11-1 -> 0.031948232 | M12: Regression Statistics
B13: 45962 | C13: 249.53 | D13: =C13/C12-1 -> -0.052225767 | G13: 45962 | H13: 26202.95 | I13: =H13/H12-1 -> 0.0028071612 | M13: Multiple R | N13: 0.4437517
B14: 45931 | C14: 240.67 | D14: =C14/C13-1 -> -0.035506753 | G14: 45931 | H14: 25722.1 | I14: =H14/H13-1 -> -0.018350987 | M14: R Square | N14: 0.19691557
B15: 45901 | C15: 239.37 | D15: =C15/C14-1 -> -0.0054015872 | G15: 45901 | H15: 24611.1 | I15: =H15/H14-1 -> -0.04319243 | M15: Adjusted R Square | N15: 0.18282637
B16: 45870 | C16: 249.41 | D16: =C16/C15-1 -> 0.041943435 | G16: 45870 | H16: 24426.85 | I16: =H16/H15-1 -> -0.0074864594 | M16: Standard Error | N16: 0.071533826
B17: 45839 | C17: 248.3 | D17: =C17/C16-1 -> -0.0044505032 | G17: 45839 | H17: 24768.35 | I17: =H17/H16-1 -> 0.013980517 | M17: Observations | N17: 59
B18: 45809 | C18: 265.98 | D18: =C18/C17-1 -> 0.071204188 | G18: 45809 | H18: 25517.05 | I18: =H18/H17-1 -> 0.030228094
B19: 45778 | C19: 249.67 | D19: =C19/C18-1 -> -0.0613204 | G19: 45778 | H19: 24750.7 | I19: =H19/H18-1 -> -0.03003286 | M19: ANOVA
B20: 45748 | C20: 241.5 | D20: =C20/C19-1 -> -0.032723195 | G20: 45748 | H20: 24334.2 | I20: =H20/H19-1 -> -0.016827807 | N20: df | O20: SS | P20: MS | Q20: F | R20: Significance F
B21: 45717 | C21: 262.25 | D21: =C21/C20-1 -> 0.085921325 | G21: 45717 | H21: 23519.35 | I21: =H21/H20-1 -> -0.033485794 | M21: Regression | N21: 1 | O21: 0.071518206 | P21: 0.071518206 | Q21: 13.976348 | R21: 0.00043102045
B22: 45689 | C22: 277.65 | D22: =C22/C21-1 -> 0.058722593 | G22: 45689 | H22: 22124.7 | I22: =H22/H21-1 -> -0.059297982 | M22: Residual | N22: 57 | O22: 0.29167403 | P22: 0.0051170883
B23: 45658 | C23: 311.9 | D23: =C23/C22-1 -> 0.12335674 | G23: 45658 | H23: 23508.4 | I23: =H23/H22-1 -> 0.062540961 | M23: Total | N23: 58 | O23: 0.36319224
B24: 45627 | C24: 301.85 | D24: =C24/C23-1 -> -0.032221866 | G24: 45627 | H24: 23644.8 | I24: =H24/H23-1 -> 0.0058021813
B25: 45597 | C25: 288.92 | D25: =C25/C24-1 -> -0.042835846 | G25: 45597 | H25: 24131.1 | I25: =H25/H24-1 -> 0.02056689 | N25: Coefficients | O25: Standard Error | P25: t Stat | Q25: P-value | R25: Lower 95% | S25: Upper 95% | T25: Lower 95.0% | U25: Upper 95.0%
B26: 45566 | C26: 275.9 | D26: =C26/C25-1 -> -0.045064378 | G26: 45566 | H26: 24205.35 | I26: =H26/H25-1 -> 0.0030769422 | M26: Intercept | N26: 0.017979145 | O26: 0.0093651035 | P26: 1.9198021 | Q26: 0.05989259 | R26: -0.0007741513 | S26: 0.036732441 | T26: -0.0007741513 | U26: 0.036732441
B27: 45536 | C27: 270.73 | D27: =C27/C26-1 -> -0.018738673 | G27: 45536 | H27: 25810.85 | I27: =H27/H26-1 -> 0.066328312 | M27: X Variable 1 | N27: 0.91215021 | O27: 0.24398859 | P27: 3.7384954 | Q27: 0.00043102045 | R27: 0.42357149 | S27: 1.4007289 | T27: 0.42357149 | U27: 1.4007289
B28: 45505 | C28: 269.2 | D28: =C28/C27-1 -> -0.005651387 | G28: 45505 | H28: 25235.9 | I28: =H28/H27-1 -> -0.022275516
B29: 45474 | C29: 261 | D29: =C29/C28-1 -> -0.030460624 | G29: 45474 | H29: 24951.15 | I29: =H29/H28-1 -> -0.011283529
B30: 45444 | C30: 257.43 | D30: =C30/C29-1 -> -0.013678161 | G30: 45444 | H30: 24010.6 | I30: =H30/H29-1 -> -0.037695657
B31: 45413 | C31: 219.1 | D31: =C31/C30-1 -> -0.14889485 | G31: 45413 | H31: 22530.7 | I31: =H31/H30-1 -> -0.061635278
B32: 45383 | C32: 231.2 | D32: =C32/C31-1 -> 0.055225924 | G32: 45383 | H32: 22604.85 | I32: =H32/H31-1 -> 0.0032910651
B33: 45352 | C33: 240.05 | D33: =C33/C32-1 -> 0.038278547 | G33: 45352 | H33: 22326.9 | I33: =H33/H32-1 -> -0.012296034
B34: 45323 | C34: 259.3 | D34: =C34/C33-1 -> 0.080191627 | G34: 45323 | H34: 21982.8 | I34: =H34/H33-1 -> -0.015411902
B35: 45292 | C35: 239.07 | D35: =C35/C34-1 -> -0.07801774 | G35: 45292 | H35: 21725.7 | I35: =H35/H34-1 -> -0.011695507
B36: 45261 | C36: 235.65 | D36: =C36/C35-1 -> -0.014305434 | G36: 45261 | H36: 21731.4 | I36: =H36/H35-1 -> 0.00026236209
B37: 45231 | C37: 206.53 | D37: =C37/C36-1 -> -0.1235731 | G37: 45231 | H37: 20133.15 | I37: =H37/H36-1 -> -0.073545653
B38: 45200 | C38: 190.9 | D38: =C38/C37-1 -> -0.075679078 | G38: 45200 | H38: 19079.6 | I38: =H38/H37-1 -> -0.052329119
B39: 45170 | C39: 203.03 | D39: =C39/C38-1 -> 0.063541121 | G39: 45170 | H39: 19638.3 | I39: =H39/H38-1 -> 0.029282585
... B62: 44470 | C62: 323.38 | D62: =C62/C61-1 -> 0.014939426 | G62: 44470 | H62: 17671.65 | I62: =H62/H61-1 -> 0.040537119

Sheet Data Sheet
A1: COMPANY NAME | B1: WIPRO LTD | E1: =IF(B2<>B3, "A NEW VERSION OF THE WORKSHEET IS AVAILABLE", "")
A2: LATEST VERSION | B2: 2.1 | E2: PLEASE DO NOT MAKE ANY CHANGES TO THIS SHEET
A3: CURRENT VERSION | B3: 2.1
A5: META
A6: Number of shares | B6: =IF(B9>0, B9/B8, 0) -> 987.51052
A7: Face Value | B7: 2
A8: Current Price | B8: 166.3
A9: Market Capitalization | B9: 164223
A15: PROFIT & LOSS
A16: Report Date | B16: 42825 | C16: 43190 | D16: 43555 | E16: 43921 | F16: 44286 | G16: 44651 | H16: 45016 | I16: 45382 | J16: 45747 | K16: 46112
A17: Sales | B17: 55448.4 | C17: 54487.1 | D17: 59018.9 | E17: 61137.6 | F17: 61934.9 | G17: 79312 | H17: 90487.6 | I17: 89760.3 | J17: 89088.4 | K17: 92624
A18: Raw Material Cost | B18: 2556 | C18: 1843.4 | D18: 1407.3 | E18: 936 | F18: 695.7 | G18: 673.5 | H18: 649.4 | I18: 383.2 | J18: 296.7 | K18: 575.5
A19: Change in Inventory | B19: -141.1 | C19: -50.5 | D19: 67.3 | E19: -202.2 | F19: -31.5 | G19: 36.9 | H19: -15 | I19: -27.8 | J19: -19.5 | K19: -17.1
A20: Power and Fuel
A21: Other Mfr. Exp | G21: 1327.9 | H21: 1871.7 | I21: 1837.8 | J21: 1933.8 | K21: 2172
A22: Employee Cost | B22: 26808.1 | C22: 27222.3 | D22: 29977.4 | E22: 32657.1 | F22: 33237.1 | G22: 45007.5 | H22: 53764.4 | I22: 54930.1 | J22: 53347.7 | K22: 55585.5
A23: Selling and admin | B23: 13775.7 | C23: 13853.3 | D23: 14796.3 | E23: 14350.4 | F23: 12523.8 | G23: 15524.3 | H23: 17123.9 | I23: 15667.3 | J23: 15481.7 | K23: 16038.7
A24: Other Expenses | B24: 846.6 | C24: 1130.5 | D24: 1292.6 | E24: 649.6 | F24: 675.4 | G24: 131.5 | H24: 224.2 | I24: 161.6 | J24: -12.2 | K24: 424
A25: Other Income | B25: 2622.6 | C25: 2549.8 | D25: 2613.8 | E25: 2727.9 | F25: 2403.7 | G25: 2066.9 | H25: 2274.6 | I25: 2630.8 | J25: 3909.4 | K25: 3899.4
A26: Depreciation | B26: 2310 | C26: 2111.7 | D26: 1946.7 | E26: 2085.5 | F26: 2763.4 | G26: 3077.8 | H26: 3340.2 | I26: 3407.1 | J26: 2957.9 | K26: 2910.7
A27: Interest | B27: 594.2 | C27: 583 | D27: 737.5 | E27: 732.8 | F27: 508.8 | G27: 532.5 | H27: 1007.7 | I27: 1255.2 | J27: 1477 | K27: 1457.7
A28: Profit before tax | B28: 11039.3 | C28: 10242.2 | D28: 11542.2 | E28: 12251.9 | F28: 13902.9 | G28: 15140.8 | H28: 14765.7 | I28: 14721 | J28: 17495.7 | K28: 17342.2
A29: Tax | B29: 2521.4 | C29: 2239.1 | D29: 2524.3 | E29: 2480.1 | F29: 3034.9 | G29: 2897.4 | H29: 3399.2 | I29: 3608.9 | J29: 4277.7 | K29: 4076.7
A30: Net profit | B30: 8493.1 | C30: 8002.8 | D30: 9003.7 | E30: 9722.3 | F30: 10796.4 | G30: 12229.6 | H30: 11350 | I30: 11045.2 | J30: 13135.4 | K30: 13197.4
A31: Dividend Amount | B31: 486.1 | C31: 452.4 | D31: 603.4 | E31: 571.35 | F31: 547.9 | G31: 3289.2 | H31: 548.8 | I31: 522.5 | J31: 6283.2 | K31: 11537.35
A40: Quarters
A41: Report Date | B41: 45382 | C41: 45473 | D41: 45565 | E41: 45657 | F41: 45747 | G41: 45838 | H41: 45930 | I41: 46022 | J41: 46112 | K41: 46203
A42: Sales | B42: 22208.3 | C42: 21963.8 | D42: 22301.6 | E42: 22318.8 | F42: 22504.2 | G42: 22134.6 | H42: 22697.3 | I42: 23555.8 | J42: 24236.3 | K42: 24478.6
A43: Expenses | B43: 17827.7 | C43: 17614.2 | D43: 17798.3 | E43: 17779 | F43: 17880.2 | G43: 17901.5 | H43: 18324.9 | I43: 19259.4 | J43: 19327 | K43: 19845.9
A44: Other Income | B44: 652.9 | C44: 729.7 | D44: 962.2 | E44: 1004.6 | F44: 1217.4 | G44: 1071.5 | H44: 962.9 | I44: 1008.1 | J44: 856.9 | K44: 979
A45: Depreciation | B45: 840.5 | C45: 728.9 | D45: 830.8 | E45: 676.5 | F45: 721.7 | G45: 685.5 | H45: 691.7 | I45: 805 | J45: 728.5 | K45: 804.4
A46: Interest | B46: 330.8 | C46: 328.8 | D46: 356.9 | E46: 414.6 | F46: 376.7 | G46: 360.8 | H46: 361.2 | I46: 365.6 | J46: 370.1 | K46: 472.8
A47: Profit before tax | B47: 3862.2 | C47: 4021.6 | D47: 4277.8 | E47: 4453.3 | F47: 4743 | G47: 4258.3 | H47: 4282.4 | I47: 4133.9 | J47: 4667.6 | K47: 4334.5
A48: Tax | B48: 1004 | C48: 985 | D48: 1051.2 | E48: 1086.6 | F48: 1154.9 | G48: 921.8 | H48: 1020 | I48: 988.9 | J48: 1146 | K48: 978.2
A49: Net profit | B49: 2834.6 | C49: 3003.2 | D49: 3208.8 | E49: 3353.8 | F49: 3569.6 | G49: 3330.4 | H49: 3246.2 | I49: 3119 | J49: 3501.8 | K49: 3352
A50: Operating Profit | B50: 4380.6 | C50: 4349.6 | D50: 4503.3 | E50: 4539.8 | F50: 4624 | G50: 4233.1 | H50: 4372.4 | I50: 4296.4 | J50: 4909.3 | K50: 4632.7
A55: BALANCE SHEET
A56: Report Date | B56: 42825 | C56: 43190 | D56: 43555 | E56: 43921 | F56: 44286 | G56: 44651 | H56: 45016 | I56: 45382 | J56: 45747 | K56: 46112
A57: Equity Share Capital | B57: 486.1 | C57: 904.8 | D57: 1206.8 | E57: 1142.7 | F57: 1095.8 | G57: 1096.4 | H57: 1097.6 | I57: 1045 | J57: 2094.4 | K57: 2097.7
A58: Reserves | B58: 51184.1 | C58: 47021.5 | D58: 55215.8 | E58: 54179 | F58: 53805.2 | G58: 64306.6 | H58: 76570.3 | I58: 73488 | J58: 80269.7 | K58: 85920.6
...

Sheet Profit & Loss
A1: ='Data Sheet'!B1 -> WIPRO LTD | H1: =UPDATE | M1: SCREENER.IN
A3: Narration | B3: ='Data Sheet'!B16 -> 42825 | C3: ='Data Sheet'!C16 -> 43190 | D3: ='Data Sheet'!D16 -> 43555 | E3: ='Data Sheet'!E16 -> 43921 | F3: ='Data Sheet'!F16 -> 44286 | G3: ='Data Sheet'!G16 -> 44651 | H3: ='Data Sheet'!H16 -> 45016 | I3: ='Data Sheet'!I16 -> 45382 | ... K3: ='Data Sheet'!K16 -> 46112 | L3: Trailing | M3: Best Case | N3: Worst Case
A4: Sales | B4: ='Data Sheet'!B17 -> 55448.4 | C4: ='Data Sheet'!C17 -> 54487.1 | D4: ='Data Sheet'!D17 -> 59018.9 | E4: ='Data Sheet'!E17 -> 61137.6 | F4: ='Data Sheet'!F17 -> 61934.9 | G4: ='Data Sheet'!G17 -> 79312 | H4: ='Data Sheet'!H17 -> 90487.6 | I4: ='Data Sheet'!I17 -> 89760.3 | ... K4: ='Data Sheet'!K17 -> 92624 | L4: =SUM(Quarters!H4:K4) -> 94968 | M4: =$K4+M23*K4 -> 96299.915 | N4: =$K4+N23*L4 -> 93365.588
A5: Expenses | B5: =SUM('Data Sheet'!B18,'Data Sheet'!B20:B24, -1*'Data Sheet'!B19) -> 44127.5 | C5: =SUM('Data Sheet'!C18,'Data Sheet'!C20:C24, -1*'Data Sheet'!C19) -> 44100 | D5: =SUM('Data Sheet'!D18,'Data Sheet'!D20:D24, -1*'Data Sheet'!D19) -> 47406.3 | E5: =SUM('Data Sheet'!E18,'Data Sheet'!E20:E24, -1*'Data Sheet'!E19) -> 48795.3 | F5: =SUM('Data Sheet'!F18,'Data Sheet'!F20:F24, -1*'Data Sheet'!F19) -> 47163.5 | G5: =SUM('Data Sheet'!G18,'Data Sheet'!G20:G24, -1*'Data Sheet'!G19) -> 62627.8 | H5: =SUM('Data Sheet'!H18,'Data Sheet'!H20:H24, -1*'Data Sheet'!H19) -> 73648.6 | I5: =SUM('Data Sheet'!I18,'Data Sheet'!I20:I24, -1*'Data Sheet'!I19) -> 73007.8 | ... K5: =SUM('Data Sheet'!K18,'Data Sheet'!K20:K24, -1*'Data Sheet'!K19) -> 74812.8 | L5: =SUM(Quarters!H5:K5) -> 76757.2 | M5: =M4-M6 -> 77646.395 | N5: =N4-N6 -> 75462.062
A6: Operating Profit | B6: =B4-B5 -> 11320.9 | C6: =C4-C5 -> 10387.1 | D6: =D4-D5 -> 11612.6 | E6: =E4-E5 -> 12342.3 | F6: =F4-F5 -> 14771.4 | G6: =G4-G5 -> 16684.2 | H6: =H4-H5 -> 16839 | I6: =I4-I5 -> 16752.5 | ... K6: =K4-K5 -> 17811.2 | L6: =SUM(Quarters!H6:K6) -> 18210.8 | M6: =M4*M24 -> 18653.52 | N6: =N4*N24 -> 17903.526
A7: Other Income | B7: ='Data Sheet'!B25 -> 2622.6 | C7: ='Data Sheet'!C25 -> 2549.8 | D7: ='Data Sheet'!D25 -> 2613.8 | E7: ='Data Sheet'!E25 -> 2727.9 | F7: ='Data Sheet'!F25 -> 2403.7 | G7: ='Data Sheet'!G25 -> 2066.9 | H7: ='Data Sheet'!H25 -> 2274.6 | I7: ='Data Sheet'!I25 -> 2630.8 | ... K7: ='Data Sheet'!K25 -> 3899.4 | L7: =SUM(Quarters!H7:K7) -> 3806.9 | M7: 0 | N7: 0
A8: Depreciation | B8: ='Data Sheet'!B26 -> 2310 | C8: ='Data Sheet'!C26 -> 2111.7 | D8: ='Data Sheet'!D26 -> 1946.7 | E8: ='Data Sheet'!E26 -> 2085.5 | F8: ='Data Sheet'!F26 -> 2763.4 | G8: ='Data Sheet'!G26 -> 3077.8 | H8: ='Data Sheet'!H26 -> 3340.2 | I8: ='Data Sheet'!I26 -> 3407.1 | ... K8: ='Data Sheet'!K26 -> 2910.7 | L8: =SUM(Quarters!H8:K8) -> 3029.6 | M8: =+$L8 -> 3029.6 | N8: =+$L8 -> 3029.6
A9: Interest | B9: ='Data Sheet'!B27 -> 594.2 | C9: ='Data Sheet'!C27 -> 583 | D9: ='Data Sheet'!D27 -> 737.5 | E9: ='Data Sheet'!E27 -> 732.8 | F9: ='Data Sheet'!F27 -> 508.8 | G9: ='Data Sheet'!G27 -> 532.5 | H9: ='Data Sheet'!H27 -> 1007.7 | I9: ='Data Sheet'!I27 -> 1255.2 | ... K9: ='Data Sheet'!K27 -> 1457.7 | L9: =SUM(Quarters!H9:K9) -> 1569.7 | M9: =+$L9 -> 1569.7 | N9: =+$L9 -> 1569.7
